CRITICAL - 2023-03-01 07:11:26 --> Undefined array key "echafactura_forma_pago"
#0 C:\xampp\htdocs\dfpyme\app\Views\caja_general\total_ingresos.php(14): CodeIgniter\Debug\Exceptions->errorHandler(2, 'Undefined array...', 'C:\\xampp\\htdocs...', 14)
#1 C:\xampp\htdocs\dfpyme\system\View\View.php(210): include('C:\\xampp\\htdocs...')
#2 C:\xampp\htdocs\dfpyme\system\View\View.php(213): CodeIgniter\View\View->CodeIgniter\View\{closure}()
#3 C:\xampp\htdocs\dfpyme\system\Common.php(1089): CodeIgniter\View\View->render('caja_general/to...', Array, true)
#4 C:\xampp\htdocs\dfpyme\app\Controllers\caja_general\cajaGeneralController.php(262): view('caja_general/to...', Array)
#5 C:\xampp\htdocs\dfpyme\system\CodeIgniter.php(832): App\Controllers\caja_general\cajaGeneralController->total_ingresos()
#6 C:\xampp\htdocs\dfpyme\system\CodeIgniter.php(419): CodeIgniter\CodeIgniter->runController(Object(App\Controllers\caja_general\cajaGeneralController))
#7 C:\xampp\htdocs\dfpyme\system\CodeIgniter.php(326): CodeIgniter\CodeIgniter->handleRequest(NULL, Object(Config\Cache), false)
#8 C:\xampp\htdocs\dfpyme\index.php(37): CodeIgniter\CodeIgniter->run()
#9 {main}
CRITICAL - 2023-03-01 07:11:40 --> Undefined array key "factura_forma_pago"
#0 C:\xampp\htdocs\dfpyme\app\Views\caja_general\total_ingresos.php(14): CodeIgniter\Debug\Exceptions->errorHandler(2, 'Undefined array...', 'C:\\xampp\\htdocs...', 14)
#1 C:\xampp\htdocs\dfpyme\system\View\View.php(210): include('C:\\xampp\\htdocs...')
#2 C:\xampp\htdocs\dfpyme\system\View\View.php(213): CodeIgniter\View\View->CodeIgniter\View\{closure}()
#3 C:\xampp\htdocs\dfpyme\system\Common.php(1089): CodeIgniter\View\View->render('caja_general/to...', Array, true)
#4 C:\xampp\htdocs\dfpyme\app\Controllers\caja_general\cajaGeneralController.php(262): view('caja_general/to...', Array)
#5 C:\xampp\htdocs\dfpyme\system\CodeIgniter.php(832): App\Controllers\caja_general\cajaGeneralController->total_ingresos()
#6 C:\xampp\htdocs\dfpyme\system\CodeIgniter.php(419): CodeIgniter\CodeIgniter->runController(Object(App\Controllers\caja_general\cajaGeneralController))
#7 C:\xampp\htdocs\dfpyme\system\CodeIgniter.php(326): CodeIgniter\CodeIgniter->handleRequest(NULL, Object(Config\Cache), false)
#8 C:\xampp\htdocs\dfpyme\index.php(37): CodeIgniter\CodeIgniter->run()
#9 {main}
CRITICAL - 2023-03-01 07:25:08 --> number_format(): Argument #1 ($num) must be of type float, string given
#0 C:\xampp\htdocs\dfpyme\app\Views\caja_general\total_ingresos.php(15): number_format('0-56201', 0, ',', '.')
#1 C:\xampp\htdocs\dfpyme\system\View\View.php(210): include('C:\\xampp\\htdocs...')
#2 C:\xampp\htdocs\dfpyme\system\View\View.php(213): CodeIgniter\View\View->CodeIgniter\View\{closure}()
#3 C:\xampp\htdocs\dfpyme\system\Common.php(1089): CodeIgniter\View\View->render('caja_general/to...', Array, true)
#4 C:\xampp\htdocs\dfpyme\app\Controllers\caja_general\cajaGeneralController.php(262): view('caja_general/to...', Array)
#5 C:\xampp\htdocs\dfpyme\system\CodeIgniter.php(832): App\Controllers\caja_general\cajaGeneralController->total_ingresos()
#6 C:\xampp\htdocs\dfpyme\system\CodeIgniter.php(419): CodeIgniter\CodeIgniter->runController(Object(App\Controllers\caja_general\cajaGeneralController))
#7 C:\xampp\htdocs\dfpyme\system\CodeIgniter.php(326): CodeIgniter\CodeIgniter->handleRequest(NULL, Object(Config\Cache), false)
#8 C:\xampp\htdocs\dfpyme\index.php(37): CodeIgniter\CodeIgniter->run()
#9 {main}
CRITICAL - 2023-03-01 07:25:11 --> number_format(): Argument #1 ($num) must be of type float, string given
#0 C:\xampp\htdocs\dfpyme\app\Views\caja_general\total_ingresos.php(15): number_format('0-56201', 0, ',', '.')
#1 C:\xampp\htdocs\dfpyme\system\View\View.php(210): include('C:\\xampp\\htdocs...')
#2 C:\xampp\htdocs\dfpyme\system\View\View.php(213): CodeIgniter\View\View->CodeIgniter\View\{closure}()
#3 C:\xampp\htdocs\dfpyme\system\Common.php(1089): CodeIgniter\View\View->render('caja_general/to...', Array, true)
#4 C:\xampp\htdocs\dfpyme\app\Controllers\caja_general\cajaGeneralController.php(262): view('caja_general/to...', Array)
#5 C:\xampp\htdocs\dfpyme\system\CodeIgniter.php(832): App\Controllers\caja_general\cajaGeneralController->total_ingresos()
#6 C:\xampp\htdocs\dfpyme\system\CodeIgniter.php(419): CodeIgniter\CodeIgniter->runController(Object(App\Controllers\caja_general\cajaGeneralController))
#7 C:\xampp\htdocs\dfpyme\system\CodeIgniter.php(326): CodeIgniter\CodeIgniter->handleRequest(NULL, Object(Config\Cache), false)
#8 C:\xampp\htdocs\dfpyme\index.php(37): CodeIgniter\CodeIgniter->run()
#9 {main}
CRITICAL - 2023-03-01 07:25:13 --> number_format(): Argument #1 ($num) must be of type float, string given
#0 C:\xampp\htdocs\dfpyme\app\Views\caja_general\total_ingresos.php(15): number_format('0-56201', 0, ',', '.')
#1 C:\xampp\htdocs\dfpyme\system\View\View.php(210): include('C:\\xampp\\htdocs...')
#2 C:\xampp\htdocs\dfpyme\system\View\View.php(213): CodeIgniter\View\View->CodeIgniter\View\{closure}()
#3 C:\xampp\htdocs\dfpyme\system\Common.php(1089): CodeIgniter\View\View->render('caja_general/to...', Array, true)
#4 C:\xampp\htdocs\dfpyme\app\Controllers\caja_general\cajaGeneralController.php(262): view('caja_general/to...', Array)
#5 C:\xampp\htdocs\dfpyme\system\CodeIgniter.php(832): App\Controllers\caja_general\cajaGeneralController->total_ingresos()
#6 C:\xampp\htdocs\dfpyme\system\CodeIgniter.php(419): CodeIgniter\CodeIgniter->runController(Object(App\Controllers\caja_general\cajaGeneralController))
#7 C:\xampp\htdocs\dfpyme\system\CodeIgniter.php(326): CodeIgniter\CodeIgniter->handleRequest(NULL, Object(Config\Cache), false)
#8 C:\xampp\htdocs\dfpyme\index.php(37): CodeIgniter\CodeIgniter->run()
#9 {main}
CRITICAL - 2023-03-01 07:25:18 --> number_format(): Argument #1 ($num) must be of type float, string given
#0 C:\xampp\htdocs\dfpyme\app\Views\caja_general\total_ingresos.php(15): number_format('0-56201', 0, ',', '.')
#1 C:\xampp\htdocs\dfpyme\system\View\View.php(210): include('C:\\xampp\\htdocs...')
#2 C:\xampp\htdocs\dfpyme\system\View\View.php(213): CodeIgniter\View\View->CodeIgniter\View\{closure}()
#3 C:\xampp\htdocs\dfpyme\system\Common.php(1089): CodeIgniter\View\View->render('caja_general/to...', Array, true)
#4 C:\xampp\htdocs\dfpyme\app\Controllers\caja_general\cajaGeneralController.php(262): view('caja_general/to...', Array)
#5 C:\xampp\htdocs\dfpyme\system\CodeIgniter.php(832): App\Controllers\caja_general\cajaGeneralController->total_ingresos()
#6 C:\xampp\htdocs\dfpyme\system\CodeIgniter.php(419): CodeIgniter\CodeIgniter->runController(Object(App\Controllers\caja_general\cajaGeneralController))
#7 C:\xampp\htdocs\dfpyme\system\CodeIgniter.php(326): CodeIgniter\CodeIgniter->handleRequest(NULL, Object(Config\Cache), false)
#8 C:\xampp\htdocs\dfpyme\index.php(37): CodeIgniter\CodeIgniter->run()
#9 {main}
CRITICAL - 2023-03-01 07:39:11 --> Undefined array key "fechafactura_forma_pago"
#0 C:\xampp\htdocs\dfpyme\app\Views\caja_general\total_ingresos.php(14): CodeIgniter\Debug\Exceptions->errorHandler(2, 'Undefined array...', 'C:\\xampp\\htdocs...', 14)
#1 C:\xampp\htdocs\dfpyme\system\View\View.php(210): include('C:\\xampp\\htdocs...')
#2 C:\xampp\htdocs\dfpyme\system\View\View.php(213): CodeIgniter\View\View->CodeIgniter\View\{closure}()
#3 C:\xampp\htdocs\dfpyme\system\Common.php(1089): CodeIgniter\View\View->render('caja_general/to...', Array, true)
#4 C:\xampp\htdocs\dfpyme\app\Controllers\caja_general\cajaGeneralController.php(263): view('caja_general/to...', Array)
#5 C:\xampp\htdocs\dfpyme\system\CodeIgniter.php(832): App\Controllers\caja_general\cajaGeneralController->total_ingresos()
#6 C:\xampp\htdocs\dfpyme\system\CodeIgniter.php(419): CodeIgniter\CodeIgniter->runController(Object(App\Controllers\caja_general\cajaGeneralController))
#7 C:\xampp\htdocs\dfpyme\system\CodeIgniter.php(326): CodeIgniter\CodeIgniter->handleRequest(NULL, Object(Config\Cache), false)
#8 C:\xampp\htdocs\dfpyme\index.php(37): CodeIgniter\CodeIgniter->run()
#9 {main}
CRITICAL - 2023-03-01 07:39:14 --> Undefined array key "fechafactura_forma_pago"
#0 C:\xampp\htdocs\dfpyme\app\Views\caja_general\total_ingresos.php(14): CodeIgniter\Debug\Exceptions->errorHandler(2, 'Undefined array...', 'C:\\xampp\\htdocs...', 14)
#1 C:\xampp\htdocs\dfpyme\system\View\View.php(210): include('C:\\xampp\\htdocs...')
#2 C:\xampp\htdocs\dfpyme\system\View\View.php(213): CodeIgniter\View\View->CodeIgniter\View\{closure}()
#3 C:\xampp\htdocs\dfpyme\system\Common.php(1089): CodeIgniter\View\View->render('caja_general/to...', Array, true)
#4 C:\xampp\htdocs\dfpyme\app\Controllers\caja_general\cajaGeneralController.php(263): view('caja_general/to...', Array)
#5 C:\xampp\htdocs\dfpyme\system\CodeIgniter.php(832): App\Controllers\caja_general\cajaGeneralController->total_ingresos()
#6 C:\xampp\htdocs\dfpyme\system\CodeIgniter.php(419): CodeIgniter\CodeIgniter->runController(Object(App\Controllers\caja_general\cajaGeneralController))
#7 C:\xampp\htdocs\dfpyme\system\CodeIgniter.php(326): CodeIgniter\CodeIgniter->handleRequest(NULL, Object(Config\Cache), false)
#8 C:\xampp\htdocs\dfpyme\index.php(37): CodeIgniter\CodeIgniter->run()
#9 {main}
CRITICAL - 2023-03-01 07:39:20 --> Undefined array key "fechafactura_forma_pago"
#0 C:\xampp\htdocs\dfpyme\app\Views\caja_general\total_ingresos.php(14): CodeIgniter\Debug\Exceptions->errorHandler(2, 'Undefined array...', 'C:\\xampp\\htdocs...', 14)
#1 C:\xampp\htdocs\dfpyme\system\View\View.php(210): include('C:\\xampp\\htdocs...')
#2 C:\xampp\htdocs\dfpyme\system\View\View.php(213): CodeIgniter\View\View->CodeIgniter\View\{closure}()
#3 C:\xampp\htdocs\dfpyme\system\Common.php(1089): CodeIgniter\View\View->render('caja_general/to...', Array, true)
#4 C:\xampp\htdocs\dfpyme\app\Controllers\caja_general\cajaGeneralController.php(263): view('caja_general/to...', Array)
#5 C:\xampp\htdocs\dfpyme\system\CodeIgniter.php(832): App\Controllers\caja_general\cajaGeneralController->total_ingresos()
#6 C:\xampp\htdocs\dfpyme\system\CodeIgniter.php(419): CodeIgniter\CodeIgniter->runController(Object(App\Controllers\caja_general\cajaGeneralController))
#7 C:\xampp\htdocs\dfpyme\system\CodeIgniter.php(326): CodeIgniter\CodeIgniter->handleRequest(NULL, Object(Config\Cache), false)
#8 C:\xampp\htdocs\dfpyme\index.php(37): CodeIgniter\CodeIgniter->run()
#9 {main}
ERROR - 2023-03-01 08:08:51 --> ErrorException: pg_query(): Query failed: ERROR:  la sintaxis de entrada no es válida para tipo date: «»
LINE 9: ...   WHERE fechafactura_forma_pago BETWEEN '2023-02-01' AND ''
                                                                     ^ in C:\xampp\htdocs\dfpyme\system\Database\Postgre\Connection.php:135
Stack trace:
#0 [internal function]: CodeIgniter\Debug\Exceptions->errorHandler(2, 'pg_query(): Que...', 'C:\\xampp\\htdocs...', 135)
#1 C:\xampp\htdocs\dfpyme\system\Database\Postgre\Connection.php(135): pg_query(Resource id #157, '\r\n        SELEC...')
#2 C:\xampp\htdocs\dfpyme\system\Database\BaseConnection.php(670): CodeIgniter\Database\Postgre\Connection->execute('\r\n        SELEC...')
#3 C:\xampp\htdocs\dfpyme\system\Database\BaseConnection.php(598): CodeIgniter\Database\BaseConnection->simpleQuery('\r\n        SELEC...')
#4 C:\xampp\htdocs\dfpyme\app\Models\movimientosCajaGeneralModel.php(81): CodeIgniter\Database\BaseConnection->query('\r\n        SELEC...')
#5 C:\xampp\htdocs\dfpyme\app\Controllers\caja_general\cajaGeneralController.php(261): App\Models\movimientosCajaGeneralModel->consultar_total_ingresos_cierre('2023-02-01', '')
#6 C:\xampp\htdocs\dfpyme\system\CodeIgniter.php(832): App\Controllers\caja_general\cajaGeneralController->total_ingresos()
#7 C:\xampp\htdocs\dfpyme\system\CodeIgniter.php(419): CodeIgniter\CodeIgniter->runController(Object(App\Controllers\caja_general\cajaGeneralController))
#8 C:\xampp\htdocs\dfpyme\system\CodeIgniter.php(326): CodeIgniter\CodeIgniter->handleRequest(NULL, Object(Config\Cache), false)
#9 C:\xampp\htdocs\dfpyme\index.php(37): CodeIgniter\CodeIgniter->run()
#10 {main}
CRITICAL - 2023-03-01 08:08:51 --> pg_query(): Query failed: ERROR:  la sintaxis de entrada no es válida para tipo date: «»
LINE 9: ...   WHERE fechafactura_forma_pago BETWEEN '2023-02-01' AND ''
                                                                     ^
#0 [internal function]: CodeIgniter\Debug\Exceptions->errorHandler(2, 'pg_query(): Que...', 'C:\\xampp\\htdocs...', 135)
#1 C:\xampp\htdocs\dfpyme\system\Database\Postgre\Connection.php(135): pg_query(Resource id #157, '\r\n        SELEC...')
#2 C:\xampp\htdocs\dfpyme\system\Database\BaseConnection.php(670): CodeIgniter\Database\Postgre\Connection->execute('\r\n        SELEC...')
#3 C:\xampp\htdocs\dfpyme\system\Database\BaseConnection.php(598): CodeIgniter\Database\BaseConnection->simpleQuery('\r\n        SELEC...')
#4 C:\xampp\htdocs\dfpyme\app\Models\movimientosCajaGeneralModel.php(81): CodeIgniter\Database\BaseConnection->query('\r\n        SELEC...')
#5 C:\xampp\htdocs\dfpyme\app\Controllers\caja_general\cajaGeneralController.php(261): App\Models\movimientosCajaGeneralModel->consultar_total_ingresos_cierre('2023-02-01', '')
#6 C:\xampp\htdocs\dfpyme\system\CodeIgniter.php(832): App\Controllers\caja_general\cajaGeneralController->total_ingresos()
#7 C:\xampp\htdocs\dfpyme\system\CodeIgniter.php(419): CodeIgniter\CodeIgniter->runController(Object(App\Controllers\caja_general\cajaGeneralController))
#8 C:\xampp\htdocs\dfpyme\system\CodeIgniter.php(326): CodeIgniter\CodeIgniter->handleRequest(NULL, Object(Config\Cache), false)
#9 C:\xampp\htdocs\dfpyme\index.php(37): CodeIgniter\CodeIgniter->run()
#10 {main}
CRITICAL - 2023-03-01 08:08:51 --> Uncaught CodeIgniter\Format\Exceptions\FormatException: Failed to parse json string, error: "Type is not supported". in C:\xampp\htdocs\dfpyme\system\Format\JSONFormatter.php:41
Stack trace:
#0 C:\xampp\htdocs\dfpyme\system\Format\JSONFormatter.php(41): CodeIgniter\Format\Exceptions\FormatException::forInvalidJSON('Type is not sup...')
#1 C:\xampp\htdocs\dfpyme\system\API\ResponseTrait.php(341): CodeIgniter\Format\JSONFormatter->format(Array)
#2 C:\xampp\htdocs\dfpyme\system\API\ResponseTrait.php(99): CodeIgniter\Debug\Exceptions->format(Array)
#3 C:\xampp\htdocs\dfpyme\system\Debug\Exceptions.php(115): CodeIgniter\Debug\Exceptions->respond(Array, 500)
#4 [internal function]: CodeIgniter\Debug\Exceptions->exceptionHandler(Object(ErrorException))
#5 {main}
  thrown
#0 [internal function]: CodeIgniter\Debug\Exceptions->shutdownHandler()
#1 {main}
ERROR - 2023-03-01 08:08:55 --> ErrorException: pg_query(): Query failed: ERROR:  la sintaxis de entrada no es válida para tipo date: «»
LINE 9: ...   WHERE fechafactura_forma_pago BETWEEN '2023-02-01' AND ''
                                                                     ^ in C:\xampp\htdocs\dfpyme\system\Database\Postgre\Connection.php:135
Stack trace:
#0 [internal function]: CodeIgniter\Debug\Exceptions->errorHandler(2, 'pg_query(): Que...', 'C:\\xampp\\htdocs...', 135)
#1 C:\xampp\htdocs\dfpyme\system\Database\Postgre\Connection.php(135): pg_query(Resource id #157, '\r\n        SELEC...')
#2 C:\xampp\htdocs\dfpyme\system\Database\BaseConnection.php(670): CodeIgniter\Database\Postgre\Connection->execute('\r\n        SELEC...')
#3 C:\xampp\htdocs\dfpyme\system\Database\BaseConnection.php(598): CodeIgniter\Database\BaseConnection->simpleQuery('\r\n        SELEC...')
#4 C:\xampp\htdocs\dfpyme\app\Models\movimientosCajaGeneralModel.php(81): CodeIgniter\Database\BaseConnection->query('\r\n        SELEC...')
#5 C:\xampp\htdocs\dfpyme\app\Controllers\caja_general\cajaGeneralController.php(261): App\Models\movimientosCajaGeneralModel->consultar_total_ingresos_cierre('2023-02-01', '')
#6 C:\xampp\htdocs\dfpyme\system\CodeIgniter.php(832): App\Controllers\caja_general\cajaGeneralController->total_ingresos()
#7 C:\xampp\htdocs\dfpyme\system\CodeIgniter.php(419): CodeIgniter\CodeIgniter->runController(Object(App\Controllers\caja_general\cajaGeneralController))
#8 C:\xampp\htdocs\dfpyme\system\CodeIgniter.php(326): CodeIgniter\CodeIgniter->handleRequest(NULL, Object(Config\Cache), false)
#9 C:\xampp\htdocs\dfpyme\index.php(37): CodeIgniter\CodeIgniter->run()
#10 {main}
CRITICAL - 2023-03-01 08:08:55 --> pg_query(): Query failed: ERROR:  la sintaxis de entrada no es válida para tipo date: «»
LINE 9: ...   WHERE fechafactura_forma_pago BETWEEN '2023-02-01' AND ''
                                                                     ^
#0 [internal function]: CodeIgniter\Debug\Exceptions->errorHandler(2, 'pg_query(): Que...', 'C:\\xampp\\htdocs...', 135)
#1 C:\xampp\htdocs\dfpyme\system\Database\Postgre\Connection.php(135): pg_query(Resource id #157, '\r\n        SELEC...')
#2 C:\xampp\htdocs\dfpyme\system\Database\BaseConnection.php(670): CodeIgniter\Database\Postgre\Connection->execute('\r\n        SELEC...')
#3 C:\xampp\htdocs\dfpyme\system\Database\BaseConnection.php(598): CodeIgniter\Database\BaseConnection->simpleQuery('\r\n        SELEC...')
#4 C:\xampp\htdocs\dfpyme\app\Models\movimientosCajaGeneralModel.php(81): CodeIgniter\Database\BaseConnection->query('\r\n        SELEC...')
#5 C:\xampp\htdocs\dfpyme\app\Controllers\caja_general\cajaGeneralController.php(261): App\Models\movimientosCajaGeneralModel->consultar_total_ingresos_cierre('2023-02-01', '')
#6 C:\xampp\htdocs\dfpyme\system\CodeIgniter.php(832): App\Controllers\caja_general\cajaGeneralController->total_ingresos()
#7 C:\xampp\htdocs\dfpyme\system\CodeIgniter.php(419): CodeIgniter\CodeIgniter->runController(Object(App\Controllers\caja_general\cajaGeneralController))
#8 C:\xampp\htdocs\dfpyme\system\CodeIgniter.php(326): CodeIgniter\CodeIgniter->handleRequest(NULL, Object(Config\Cache), false)
#9 C:\xampp\htdocs\dfpyme\index.php(37): CodeIgniter\CodeIgniter->run()
#10 {main}
CRITICAL - 2023-03-01 08:08:55 --> Uncaught CodeIgniter\Format\Exceptions\FormatException: Failed to parse json string, error: "Type is not supported". in C:\xampp\htdocs\dfpyme\system\Format\JSONFormatter.php:41
Stack trace:
#0 C:\xampp\htdocs\dfpyme\system\Format\JSONFormatter.php(41): CodeIgniter\Format\Exceptions\FormatException::forInvalidJSON('Type is not sup...')
#1 C:\xampp\htdocs\dfpyme\system\API\ResponseTrait.php(341): CodeIgniter\Format\JSONFormatter->format(Array)
#2 C:\xampp\htdocs\dfpyme\system\API\ResponseTrait.php(99): CodeIgniter\Debug\Exceptions->format(Array)
#3 C:\xampp\htdocs\dfpyme\system\Debug\Exceptions.php(115): CodeIgniter\Debug\Exceptions->respond(Array, 500)
#4 [internal function]: CodeIgniter\Debug\Exceptions->exceptionHandler(Object(ErrorException))
#5 {main}
  thrown
#0 [internal function]: CodeIgniter\Debug\Exceptions->shutdownHandler()
#1 {main}
ERROR - 2023-03-01 08:10:19 --> ErrorException: pg_query(): Query failed: ERROR:  la sintaxis de entrada no es válida para tipo date: «»
LINE 9: ...   WHERE fechafactura_forma_pago BETWEEN '2023-02-01' AND ''
                                                                     ^ in C:\xampp\htdocs\dfpyme\system\Database\Postgre\Connection.php:135
Stack trace:
#0 [internal function]: CodeIgniter\Debug\Exceptions->errorHandler(2, 'pg_query(): Que...', 'C:\\xampp\\htdocs...', 135)
#1 C:\xampp\htdocs\dfpyme\system\Database\Postgre\Connection.php(135): pg_query(Resource id #157, '\r\n        SELEC...')
#2 C:\xampp\htdocs\dfpyme\system\Database\BaseConnection.php(670): CodeIgniter\Database\Postgre\Connection->execute('\r\n        SELEC...')
#3 C:\xampp\htdocs\dfpyme\system\Database\BaseConnection.php(598): CodeIgniter\Database\BaseConnection->simpleQuery('\r\n        SELEC...')
#4 C:\xampp\htdocs\dfpyme\app\Models\movimientosCajaGeneralModel.php(81): CodeIgniter\Database\BaseConnection->query('\r\n        SELEC...')
#5 C:\xampp\htdocs\dfpyme\app\Controllers\caja_general\cajaGeneralController.php(262): App\Models\movimientosCajaGeneralModel->consultar_total_ingresos_cierre('2023-02-01', '')
#6 C:\xampp\htdocs\dfpyme\system\CodeIgniter.php(832): App\Controllers\caja_general\cajaGeneralController->total_ingresos()
#7 C:\xampp\htdocs\dfpyme\system\CodeIgniter.php(419): CodeIgniter\CodeIgniter->runController(Object(App\Controllers\caja_general\cajaGeneralController))
#8 C:\xampp\htdocs\dfpyme\system\CodeIgniter.php(326): CodeIgniter\CodeIgniter->handleRequest(NULL, Object(Config\Cache), false)
#9 C:\xampp\htdocs\dfpyme\index.php(37): CodeIgniter\CodeIgniter->run()
#10 {main}
CRITICAL - 2023-03-01 08:10:19 --> pg_query(): Query failed: ERROR:  la sintaxis de entrada no es válida para tipo date: «»
LINE 9: ...   WHERE fechafactura_forma_pago BETWEEN '2023-02-01' AND ''
                                                                     ^
#0 [internal function]: CodeIgniter\Debug\Exceptions->errorHandler(2, 'pg_query(): Que...', 'C:\\xampp\\htdocs...', 135)
#1 C:\xampp\htdocs\dfpyme\system\Database\Postgre\Connection.php(135): pg_query(Resource id #157, '\r\n        SELEC...')
#2 C:\xampp\htdocs\dfpyme\system\Database\BaseConnection.php(670): CodeIgniter\Database\Postgre\Connection->execute('\r\n        SELEC...')
#3 C:\xampp\htdocs\dfpyme\system\Database\BaseConnection.php(598): CodeIgniter\Database\BaseConnection->simpleQuery('\r\n        SELEC...')
#4 C:\xampp\htdocs\dfpyme\app\Models\movimientosCajaGeneralModel.php(81): CodeIgniter\Database\BaseConnection->query('\r\n        SELEC...')
#5 C:\xampp\htdocs\dfpyme\app\Controllers\caja_general\cajaGeneralController.php(262): App\Models\movimientosCajaGeneralModel->consultar_total_ingresos_cierre('2023-02-01', '')
#6 C:\xampp\htdocs\dfpyme\system\CodeIgniter.php(832): App\Controllers\caja_general\cajaGeneralController->total_ingresos()
#7 C:\xampp\htdocs\dfpyme\system\CodeIgniter.php(419): CodeIgniter\CodeIgniter->runController(Object(App\Controllers\caja_general\cajaGeneralController))
#8 C:\xampp\htdocs\dfpyme\system\CodeIgniter.php(326): CodeIgniter\CodeIgniter->handleRequest(NULL, Object(Config\Cache), false)
#9 C:\xampp\htdocs\dfpyme\index.php(37): CodeIgniter\CodeIgniter->run()
#10 {main}
CRITICAL - 2023-03-01 08:15:08 --> Array to string conversion
#0 C:\xampp\htdocs\dfpyme\app\Controllers\caja_general\cajaGeneralController.php(265): CodeIgniter\Debug\Exceptions->errorHandler(2, 'Array to string...', 'C:\\xampp\\htdocs...', 265)
#1 C:\xampp\htdocs\dfpyme\system\CodeIgniter.php(832): App\Controllers\caja_general\cajaGeneralController->total_ingresos()
#2 C:\xampp\htdocs\dfpyme\system\CodeIgniter.php(419): CodeIgniter\CodeIgniter->runController(Object(App\Controllers\caja_general\cajaGeneralController))
#3 C:\xampp\htdocs\dfpyme\system\CodeIgniter.php(326): CodeIgniter\CodeIgniter->handleRequest(NULL, Object(Config\Cache), false)
#4 C:\xampp\htdocs\dfpyme\index.php(37): CodeIgniter\CodeIgniter->run()
#5 {main}
CRITICAL - 2023-03-01 09:04:55 --> Too few arguments to function App\Models\productoFacturaVentaModel::getProductosFacturaVentaModel(), 0 passed in C:\xampp\htdocs\dfpyme\app\Controllers\caja_general\cajaGeneralController.php on line 314 and exactly 1 expected
#0 C:\xampp\htdocs\dfpyme\app\Controllers\caja_general\cajaGeneralController.php(314): App\Models\productoFacturaVentaModel->getProductosFacturaVentaModel()
#1 C:\xampp\htdocs\dfpyme\system\CodeIgniter.php(832): App\Controllers\caja_general\cajaGeneralController->imprimir_movimiento_caja_general()
#2 C:\xampp\htdocs\dfpyme\system\CodeIgniter.php(419): CodeIgniter\CodeIgniter->runController(Object(App\Controllers\caja_general\cajaGeneralController))
#3 C:\xampp\htdocs\dfpyme\system\CodeIgniter.php(326): CodeIgniter\CodeIgniter->handleRequest(NULL, Object(Config\Cache), false)
#4 C:\xampp\htdocs\dfpyme\index.php(37): CodeIgniter\CodeIgniter->run()
#5 {main}
CRITICAL - 2023-03-01 09:06:06 --> Too few arguments to function App\Models\productoFacturaVentaModel::getProductosFacturaVentaModel(), 0 passed in C:\xampp\htdocs\dfpyme\app\Controllers\caja_general\cajaGeneralController.php on line 314 and exactly 1 expected
#0 C:\xampp\htdocs\dfpyme\app\Controllers\caja_general\cajaGeneralController.php(314): App\Models\productoFacturaVentaModel->getProductosFacturaVentaModel()
#1 C:\xampp\htdocs\dfpyme\system\CodeIgniter.php(832): App\Controllers\caja_general\cajaGeneralController->imprimir_movimiento_caja_general()
#2 C:\xampp\htdocs\dfpyme\system\CodeIgniter.php(419): CodeIgniter\CodeIgniter->runController(Object(App\Controllers\caja_general\cajaGeneralController))
#3 C:\xampp\htdocs\dfpyme\system\CodeIgniter.php(326): CodeIgniter\CodeIgniter->handleRequest(NULL, Object(Config\Cache), false)
#4 C:\xampp\htdocs\dfpyme\index.php(37): CodeIgniter\CodeIgniter->run()
#5 {main}
CRITICAL - 2023-03-01 09:39:34 --> Array to string conversion
#0 C:\xampp\htdocs\dfpyme\app\Models\movimientosCajaGeneralModel.php(19): CodeIgniter\Debug\Exceptions->errorHandler(2, 'Array to string...', 'C:\\xampp\\htdocs...', 19)
#1 C:\xampp\htdocs\dfpyme\app\Controllers\caja_general\cajaGeneralController.php(324): App\Models\movimientosCajaGeneralModel->efectivo('2023-02-01', Array)
#2 C:\xampp\htdocs\dfpyme\system\CodeIgniter.php(832): App\Controllers\caja_general\cajaGeneralController->imprimir_movimiento_caja_general()
#3 C:\xampp\htdocs\dfpyme\system\CodeIgniter.php(419): CodeIgniter\CodeIgniter->runController(Object(App\Controllers\caja_general\cajaGeneralController))
#4 C:\xampp\htdocs\dfpyme\system\CodeIgniter.php(326): CodeIgniter\CodeIgniter->handleRequest(NULL, Object(Config\Cache), false)
#5 C:\xampp\htdocs\dfpyme\index.php(37): CodeIgniter\CodeIgniter->run()
#6 {main}
CRITICAL - 2023-03-01 09:42:09 --> Array to string conversion
#0 C:\xampp\htdocs\dfpyme\app\Models\movimientosCajaGeneralModel.php(102): CodeIgniter\Debug\Exceptions->errorHandler(2, 'Array to string...', 'C:\\xampp\\htdocs...', 102)
#1 C:\xampp\htdocs\dfpyme\app\Controllers\caja_general\cajaGeneralController.php(324): App\Models\movimientosCajaGeneralModel->imprimir_mov_efectivo('2023-02-01', Array)
#2 C:\xampp\htdocs\dfpyme\system\CodeIgniter.php(832): App\Controllers\caja_general\cajaGeneralController->imprimir_movimiento_caja_general()
#3 C:\xampp\htdocs\dfpyme\system\CodeIgniter.php(419): CodeIgniter\CodeIgniter->runController(Object(App\Controllers\caja_general\cajaGeneralController))
#4 C:\xampp\htdocs\dfpyme\system\CodeIgniter.php(326): CodeIgniter\CodeIgniter->handleRequest(NULL, Object(Config\Cache), false)
#5 C:\xampp\htdocs\dfpyme\index.php(37): CodeIgniter\CodeIgniter->run()
#6 {main}
CRITICAL - 2023-03-01 09:43:19 --> Array to string conversion
#0 C:\xampp\htdocs\dfpyme\app\Controllers\caja_general\cajaGeneralController.php(323): CodeIgniter\Debug\Exceptions->errorHandler(2, 'Array to string...', 'C:\\xampp\\htdocs...', 323)
#1 C:\xampp\htdocs\dfpyme\system\CodeIgniter.php(832): App\Controllers\caja_general\cajaGeneralController->imprimir_movimiento_caja_general()
#2 C:\xampp\htdocs\dfpyme\system\CodeIgniter.php(419): CodeIgniter\CodeIgniter->runController(Object(App\Controllers\caja_general\cajaGeneralController))
#3 C:\xampp\htdocs\dfpyme\system\CodeIgniter.php(326): CodeIgniter\CodeIgniter->handleRequest(NULL, Object(Config\Cache), false)
#4 C:\xampp\htdocs\dfpyme\index.php(37): CodeIgniter\CodeIgniter->run()
#5 {main}
ERROR - 2023-03-01 09:53:49 --> ErrorException: pg_query(): Query failed: ERROR:  no existe la columna «2023-02-01»
LINE 3: WHERE &quot;2023-02-01&quot; = '2023-03-01'
              ^ in C:\xampp\htdocs\dfpyme\system\Database\Postgre\Connection.php:135
Stack trace:
#0 [internal function]: CodeIgniter\Debug\Exceptions->errorHandler(2, 'pg_query(): Que...', 'C:\\xampp\\htdocs...', 135)
#1 C:\xampp\htdocs\dfpyme\system\Database\Postgre\Connection.php(135): pg_query(Resource id #156, 'SELECT "valor_c...')
#2 C:\xampp\htdocs\dfpyme\system\Database\BaseConnection.php(670): CodeIgniter\Database\Postgre\Connection->execute('SELECT "valor_c...')
#3 C:\xampp\htdocs\dfpyme\system\Database\BaseConnection.php(598): CodeIgniter\Database\BaseConnection->simpleQuery('SELECT "valor_c...')
#4 C:\xampp\htdocs\dfpyme\system\Database\BaseBuilder.php(1455): CodeIgniter\Database\BaseConnection->query('SELECT "valor_c...', Array, false)
#5 C:\xampp\htdocs\dfpyme\system\Model.php(210): CodeIgniter\Database\BaseBuilder->get()
#6 C:\xampp\htdocs\dfpyme\system\BaseModel.php(622): CodeIgniter\Model->doFirst()
#7 C:\xampp\htdocs\dfpyme\app\Controllers\caja_general\cajaGeneralController.php(326): CodeIgniter\BaseModel->first()
#8 C:\xampp\htdocs\dfpyme\system\CodeIgniter.php(832): App\Controllers\caja_general\cajaGeneralController->imprimir_movimiento_caja_general()
#9 C:\xampp\htdocs\dfpyme\system\CodeIgniter.php(419): CodeIgniter\CodeIgniter->runController(Object(App\Controllers\caja_general\cajaGeneralController))
#10 C:\xampp\htdocs\dfpyme\system\CodeIgniter.php(326): CodeIgniter\CodeIgniter->handleRequest(NULL, Object(Config\Cache), false)
#11 C:\xampp\htdocs\dfpyme\index.php(37): CodeIgniter\CodeIgniter->run()
#12 {main}
CRITICAL - 2023-03-01 09:53:49 --> pg_query(): Query failed: ERROR:  no existe la columna «2023-02-01»
LINE 3: WHERE &quot;2023-02-01&quot; = '2023-03-01'
              ^
#0 [internal function]: CodeIgniter\Debug\Exceptions->errorHandler(2, 'pg_query(): Que...', 'C:\\xampp\\htdocs...', 135)
#1 C:\xampp\htdocs\dfpyme\system\Database\Postgre\Connection.php(135): pg_query(Resource id #156, 'SELECT "valor_c...')
#2 C:\xampp\htdocs\dfpyme\system\Database\BaseConnection.php(670): CodeIgniter\Database\Postgre\Connection->execute('SELECT "valor_c...')
#3 C:\xampp\htdocs\dfpyme\system\Database\BaseConnection.php(598): CodeIgniter\Database\BaseConnection->simpleQuery('SELECT "valor_c...')
#4 C:\xampp\htdocs\dfpyme\system\Database\BaseBuilder.php(1455): CodeIgniter\Database\BaseConnection->query('SELECT "valor_c...', Array, false)
#5 C:\xampp\htdocs\dfpyme\system\Model.php(210): CodeIgniter\Database\BaseBuilder->get()
#6 C:\xampp\htdocs\dfpyme\system\BaseModel.php(622): CodeIgniter\Model->doFirst()
#7 C:\xampp\htdocs\dfpyme\app\Controllers\caja_general\cajaGeneralController.php(326): CodeIgniter\BaseModel->first()
#8 C:\xampp\htdocs\dfpyme\system\CodeIgniter.php(832): App\Controllers\caja_general\cajaGeneralController->imprimir_movimiento_caja_general()
#9 C:\xampp\htdocs\dfpyme\system\CodeIgniter.php(419): CodeIgniter\CodeIgniter->runController(Object(App\Controllers\caja_general\cajaGeneralController))
#10 C:\xampp\htdocs\dfpyme\system\CodeIgniter.php(326): CodeIgniter\CodeIgniter->handleRequest(NULL, Object(Config\Cache), false)
#11 C:\xampp\htdocs\dfpyme\index.php(37): CodeIgniter\CodeIgniter->run()
#12 {main}
CRITICAL - 2023-03-01 09:54:31 --> Undefined array key "valor"
#0 C:\xampp\htdocs\dfpyme\app\Controllers\caja_general\cajaGeneralController.php(331): CodeIgniter\Debug\Exceptions->errorHandler(2, 'Undefined array...', 'C:\\xampp\\htdocs...', 331)
#1 C:\xampp\htdocs\dfpyme\system\CodeIgniter.php(832): App\Controllers\caja_general\cajaGeneralController->imprimir_movimiento_caja_general()
#2 C:\xampp\htdocs\dfpyme\system\CodeIgniter.php(419): CodeIgniter\CodeIgniter->runController(Object(App\Controllers\caja_general\cajaGeneralController))
#3 C:\xampp\htdocs\dfpyme\system\CodeIgniter.php(326): CodeIgniter\CodeIgniter->handleRequest(NULL, Object(Config\Cache), false)
#4 C:\xampp\htdocs\dfpyme\index.php(37): CodeIgniter\CodeIgniter->run()
#5 {main}
CRITICAL - 2023-03-01 09:57:26 --> Undefined array key "total"
#0 C:\xampp\htdocs\dfpyme\app\Controllers\caja_general\cajaGeneralController.php(333): CodeIgniter\Debug\Exceptions->errorHandler(2, 'Undefined array...', 'C:\\xampp\\htdocs...', 333)
#1 C:\xampp\htdocs\dfpyme\system\CodeIgniter.php(832): App\Controllers\caja_general\cajaGeneralController->imprimir_movimiento_caja_general()
#2 C:\xampp\htdocs\dfpyme\system\CodeIgniter.php(419): CodeIgniter\CodeIgniter->runController(Object(App\Controllers\caja_general\cajaGeneralController))
#3 C:\xampp\htdocs\dfpyme\system\CodeIgniter.php(326): CodeIgniter\CodeIgniter->handleRequest(NULL, Object(Config\Cache), false)
#4 C:\xampp\htdocs\dfpyme\index.php(37): CodeIgniter\CodeIgniter->run()
#5 {main}
CRITICAL - 2023-03-01 09:59:21 --> Undefined array key "total"
#0 C:\xampp\htdocs\dfpyme\app\Controllers\caja_general\cajaGeneralController.php(336): CodeIgniter\Debug\Exceptions->errorHandler(2, 'Undefined array...', 'C:\\xampp\\htdocs...', 336)
#1 C:\xampp\htdocs\dfpyme\system\CodeIgniter.php(832): App\Controllers\caja_general\cajaGeneralController->imprimir_movimiento_caja_general()
#2 C:\xampp\htdocs\dfpyme\system\CodeIgniter.php(419): CodeIgniter\CodeIgniter->runController(Object(App\Controllers\caja_general\cajaGeneralController))
#3 C:\xampp\htdocs\dfpyme\system\CodeIgniter.php(326): CodeIgniter\CodeIgniter->handleRequest(NULL, Object(Config\Cache), false)
#4 C:\xampp\htdocs\dfpyme\index.php(37): CodeIgniter\CodeIgniter->run()
#5 {main}
CRITICAL - 2023-03-01 10:55:23 --> Undefined array key "fechafactura_forma_pago"
#0 C:\xampp\htdocs\dfpyme\app\Views\caja_general\retiros.php(14): CodeIgniter\Debug\Exceptions->errorHandler(2, 'Undefined array...', 'C:\\xampp\\htdocs...', 14)
#1 C:\xampp\htdocs\dfpyme\system\View\View.php(210): include('C:\\xampp\\htdocs...')
#2 C:\xampp\htdocs\dfpyme\system\View\View.php(213): CodeIgniter\View\View->CodeIgniter\View\{closure}()
#3 C:\xampp\htdocs\dfpyme\system\Common.php(1089): CodeIgniter\View\View->render('caja_general/re...', Array, true)
#4 C:\xampp\htdocs\dfpyme\app\Controllers\caja_general\cajaGeneralController.php(393): view('caja_general/re...', Array)
#5 C:\xampp\htdocs\dfpyme\system\CodeIgniter.php(832): App\Controllers\caja_general\cajaGeneralController->ver_retiros()
#6 C:\xampp\htdocs\dfpyme\system\CodeIgniter.php(419): CodeIgniter\CodeIgniter->runController(Object(App\Controllers\caja_general\cajaGeneralController))
#7 C:\xampp\htdocs\dfpyme\system\CodeIgniter.php(326): CodeIgniter\CodeIgniter->handleRequest(NULL, Object(Config\Cache), false)
#8 C:\xampp\htdocs\dfpyme\index.php(37): CodeIgniter\CodeIgniter->run()
#9 {main}
ERROR - 2023-03-01 11:00:19 --> ErrorException: pg_query(): Query failed: ERROR:  no existe la columna «valor»
LINE 1: SELECT &quot;valor&quot;
               ^ in C:\xampp\htdocs\dfpyme\system\Database\Postgre\Connection.php:135
Stack trace:
#0 [internal function]: CodeIgniter\Debug\Exceptions->errorHandler(2, 'pg_query(): Que...', 'C:\\xampp\\htdocs...', 135)
#1 C:\xampp\htdocs\dfpyme\system\Database\Postgre\Connection.php(135): pg_query(Resource id #158, 'SELECT "valor"\n...')
#2 C:\xampp\htdocs\dfpyme\system\Database\BaseConnection.php(670): CodeIgniter\Database\Postgre\Connection->execute('SELECT "valor"\n...')
#3 C:\xampp\htdocs\dfpyme\system\Database\BaseConnection.php(598): CodeIgniter\Database\BaseConnection->simpleQuery('SELECT "valor"\n...')
#4 C:\xampp\htdocs\dfpyme\system\Database\BaseBuilder.php(1455): CodeIgniter\Database\BaseConnection->query('SELECT "valor"\n...', Array, false)
#5 C:\xampp\htdocs\dfpyme\system\Model.php(210): CodeIgniter\Database\BaseBuilder->get()
#6 C:\xampp\htdocs\dfpyme\system\BaseModel.php(622): CodeIgniter\Model->doFirst()
#7 C:\xampp\htdocs\dfpyme\app\Views\caja_general\retiros.php(14): CodeIgniter\BaseModel->first()
#8 C:\xampp\htdocs\dfpyme\system\View\View.php(210): include('C:\\xampp\\htdocs...')
#9 C:\xampp\htdocs\dfpyme\system\View\View.php(213): CodeIgniter\View\View->CodeIgniter\View\{closure}()
#10 C:\xampp\htdocs\dfpyme\system\Common.php(1089): CodeIgniter\View\View->render('caja_general/re...', Array, true)
#11 C:\xampp\htdocs\dfpyme\app\Controllers\caja_general\cajaGeneralController.php(393): view('caja_general/re...', Array)
#12 C:\xampp\htdocs\dfpyme\system\CodeIgniter.php(832): App\Controllers\caja_general\cajaGeneralController->ver_retiros()
#13 C:\xampp\htdocs\dfpyme\system\CodeIgniter.php(419): CodeIgniter\CodeIgniter->runController(Object(App\Controllers\caja_general\cajaGeneralController))
#14 C:\xampp\htdocs\dfpyme\system\CodeIgniter.php(326): CodeIgniter\CodeIgniter->handleRequest(NULL, Object(Config\Cache), false)
#15 C:\xampp\htdocs\dfpyme\index.php(37): CodeIgniter\CodeIgniter->run()
#16 {main}
CRITICAL - 2023-03-01 11:00:19 --> pg_query(): Query failed: ERROR:  no existe la columna «valor»
LINE 1: SELECT &quot;valor&quot;
               ^
#0 [internal function]: CodeIgniter\Debug\Exceptions->errorHandler(2, 'pg_query(): Que...', 'C:\\xampp\\htdocs...', 135)
#1 C:\xampp\htdocs\dfpyme\system\Database\Postgre\Connection.php(135): pg_query(Resource id #158, 'SELECT "valor"\n...')
#2 C:\xampp\htdocs\dfpyme\system\Database\BaseConnection.php(670): CodeIgniter\Database\Postgre\Connection->execute('SELECT "valor"\n...')
#3 C:\xampp\htdocs\dfpyme\system\Database\BaseConnection.php(598): CodeIgniter\Database\BaseConnection->simpleQuery('SELECT "valor"\n...')
#4 C:\xampp\htdocs\dfpyme\system\Database\BaseBuilder.php(1455): CodeIgniter\Database\BaseConnection->query('SELECT "valor"\n...', Array, false)
#5 C:\xampp\htdocs\dfpyme\system\Model.php(210): CodeIgniter\Database\BaseBuilder->get()
#6 C:\xampp\htdocs\dfpyme\system\BaseModel.php(622): CodeIgniter\Model->doFirst()
#7 C:\xampp\htdocs\dfpyme\app\Views\caja_general\retiros.php(14): CodeIgniter\BaseModel->first()
#8 C:\xampp\htdocs\dfpyme\system\View\View.php(210): include('C:\\xampp\\htdocs...')
#9 C:\xampp\htdocs\dfpyme\system\View\View.php(213): CodeIgniter\View\View->CodeIgniter\View\{closure}()
#10 C:\xampp\htdocs\dfpyme\system\Common.php(1089): CodeIgniter\View\View->render('caja_general/re...', Array, true)
#11 C:\xampp\htdocs\dfpyme\app\Controllers\caja_general\cajaGeneralController.php(393): view('caja_general/re...', Array)
#12 C:\xampp\htdocs\dfpyme\system\CodeIgniter.php(832): App\Controllers\caja_general\cajaGeneralController->ver_retiros()
#13 C:\xampp\htdocs\dfpyme\system\CodeIgniter.php(419): CodeIgniter\CodeIgniter->runController(Object(App\Controllers\caja_general\cajaGeneralController))
#14 C:\xampp\htdocs\dfpyme\system\CodeIgniter.php(326): CodeIgniter\CodeIgniter->handleRequest(NULL, Object(Config\Cache), false)
#15 C:\xampp\htdocs\dfpyme\index.php(37): CodeIgniter\CodeIgniter->run()
#16 {main}
CRITICAL - 2023-03-01 11:00:57 --> Undefined array key "valorfactura_forma_pago"
#0 C:\xampp\htdocs\dfpyme\app\Views\caja_general\retiros.php(15): CodeIgniter\Debug\Exceptions->errorHandler(2, 'Undefined array...', 'C:\\xampp\\htdocs...', 15)
#1 C:\xampp\htdocs\dfpyme\system\View\View.php(210): include('C:\\xampp\\htdocs...')
#2 C:\xampp\htdocs\dfpyme\system\View\View.php(213): CodeIgniter\View\View->CodeIgniter\View\{closure}()
#3 C:\xampp\htdocs\dfpyme\system\Common.php(1089): CodeIgniter\View\View->render('caja_general/re...', Array, true)
#4 C:\xampp\htdocs\dfpyme\app\Controllers\caja_general\cajaGeneralController.php(393): view('caja_general/re...', Array)
#5 C:\xampp\htdocs\dfpyme\system\CodeIgniter.php(832): App\Controllers\caja_general\cajaGeneralController->ver_retiros()
#6 C:\xampp\htdocs\dfpyme\system\CodeIgniter.php(419): CodeIgniter\CodeIgniter->runController(Object(App\Controllers\caja_general\cajaGeneralController))
#7 C:\xampp\htdocs\dfpyme\system\CodeIgniter.php(326): CodeIgniter\CodeIgniter->handleRequest(NULL, Object(Config\Cache), false)
#8 C:\xampp\htdocs\dfpyme\index.php(37): CodeIgniter\CodeIgniter->run()
#9 {main}
CRITICAL - 2023-03-01 11:03:35 --> Undefined array key "concepto"
#0 C:\xampp\htdocs\dfpyme\app\Views\caja_general\retiros.php(18): CodeIgniter\Debug\Exceptions->errorHandler(2, 'Undefined array...', 'C:\\xampp\\htdocs...', 18)
#1 C:\xampp\htdocs\dfpyme\system\View\View.php(210): include('C:\\xampp\\htdocs...')
#2 C:\xampp\htdocs\dfpyme\system\View\View.php(213): CodeIgniter\View\View->CodeIgniter\View\{closure}()
#3 C:\xampp\htdocs\dfpyme\system\Common.php(1089): CodeIgniter\View\View->render('caja_general/re...', Array, true)
#4 C:\xampp\htdocs\dfpyme\app\Controllers\caja_general\cajaGeneralController.php(393): view('caja_general/re...', Array)
#5 C:\xampp\htdocs\dfpyme\system\CodeIgniter.php(832): App\Controllers\caja_general\cajaGeneralController->ver_retiros()
#6 C:\xampp\htdocs\dfpyme\system\CodeIgniter.php(419): CodeIgniter\CodeIgniter->runController(Object(App\Controllers\caja_general\cajaGeneralController))
#7 C:\xampp\htdocs\dfpyme\system\CodeIgniter.php(326): CodeIgniter\CodeIgniter->handleRequest(NULL, Object(Config\Cache), false)
#8 C:\xampp\htdocs\dfpyme\index.php(37): CodeIgniter\CodeIgniter->run()
#9 {main}
CRITICAL - 2023-03-01 11:08:26 --> Undefined array key "total"
#0 C:\xampp\htdocs\dfpyme\app\Controllers\caja_general\cajaGeneralController.php(396): CodeIgniter\Debug\Exceptions->errorHandler(2, 'Undefined array...', 'C:\\xampp\\htdocs...', 396)
#1 C:\xampp\htdocs\dfpyme\system\CodeIgniter.php(832): App\Controllers\caja_general\cajaGeneralController->ver_retiros()
#2 C:\xampp\htdocs\dfpyme\system\CodeIgniter.php(419): CodeIgniter\CodeIgniter->runController(Object(App\Controllers\caja_general\cajaGeneralController))
#3 C:\xampp\htdocs\dfpyme\system\CodeIgniter.php(326): CodeIgniter\CodeIgniter->handleRequest(NULL, Object(Config\Cache), false)
#4 C:\xampp\htdocs\dfpyme\index.php(37): CodeIgniter\CodeIgniter->run()
#5 {main}
CRITICAL - 2023-03-01 11:08:33 --> Undefined array key "total"
#0 C:\xampp\htdocs\dfpyme\app\Controllers\caja_general\cajaGeneralController.php(396): CodeIgniter\Debug\Exceptions->errorHandler(2, 'Undefined array...', 'C:\\xampp\\htdocs...', 396)
#1 C:\xampp\htdocs\dfpyme\system\CodeIgniter.php(832): App\Controllers\caja_general\cajaGeneralController->ver_retiros()
#2 C:\xampp\htdocs\dfpyme\system\CodeIgniter.php(419): CodeIgniter\CodeIgniter->runController(Object(App\Controllers\caja_general\cajaGeneralController))
#3 C:\xampp\htdocs\dfpyme\system\CodeIgniter.php(326): CodeIgniter\CodeIgniter->handleRequest(NULL, Object(Config\Cache), false)
#4 C:\xampp\htdocs\dfpyme\index.php(37): CodeIgniter\CodeIgniter->run()
#5 {main}
CRITICAL - 2023-03-01 11:08:48 --> Trying to access array offset on value of type null
#0 C:\xampp\htdocs\dfpyme\app\Controllers\caja_general\cajaGeneralController.php(387): CodeIgniter\Debug\Exceptions->errorHandler(2, 'Trying to acces...', 'C:\\xampp\\htdocs...', 387)
#1 C:\xampp\htdocs\dfpyme\system\CodeIgniter.php(832): App\Controllers\caja_general\cajaGeneralController->ver_retiros()
#2 C:\xampp\htdocs\dfpyme\system\CodeIgniter.php(419): CodeIgniter\CodeIgniter->runController(Object(App\Controllers\caja_general\cajaGeneralController))
#3 C:\xampp\htdocs\dfpyme\system\CodeIgniter.php(326): CodeIgniter\CodeIgniter->handleRequest(NULL, Object(Config\Cache), false)
#4 C:\xampp\htdocs\dfpyme\index.php(37): CodeIgniter\CodeIgniter->run()
#5 {main}
CRITICAL - 2023-03-01 11:09:29 --> Trying to access array offset on value of type null
#0 C:\xampp\htdocs\dfpyme\app\Controllers\caja_general\cajaGeneralController.php(387): CodeIgniter\Debug\Exceptions->errorHandler(2, 'Trying to acces...', 'C:\\xampp\\htdocs...', 387)
#1 C:\xampp\htdocs\dfpyme\system\CodeIgniter.php(832): App\Controllers\caja_general\cajaGeneralController->ver_retiros()
#2 C:\xampp\htdocs\dfpyme\system\CodeIgniter.php(419): CodeIgniter\CodeIgniter->runController(Object(App\Controllers\caja_general\cajaGeneralController))
#3 C:\xampp\htdocs\dfpyme\system\CodeIgniter.php(326): CodeIgniter\CodeIgniter->handleRequest(NULL, Object(Config\Cache), false)
#4 C:\xampp\htdocs\dfpyme\index.php(37): CodeIgniter\CodeIgniter->run()
#5 {main}
CRITICAL - 2023-03-01 11:10:06 --> Undefined array key "total"
#0 C:\xampp\htdocs\dfpyme\app\Controllers\caja_general\cajaGeneralController.php(396): CodeIgniter\Debug\Exceptions->errorHandler(2, 'Undefined array...', 'C:\\xampp\\htdocs...', 396)
#1 C:\xampp\htdocs\dfpyme\system\CodeIgniter.php(832): App\Controllers\caja_general\cajaGeneralController->ver_retiros()
#2 C:\xampp\htdocs\dfpyme\system\CodeIgniter.php(419): CodeIgniter\CodeIgniter->runController(Object(App\Controllers\caja_general\cajaGeneralController))
#3 C:\xampp\htdocs\dfpyme\system\CodeIgniter.php(326): CodeIgniter\CodeIgniter->handleRequest(NULL, Object(Config\Cache), false)
#4 C:\xampp\htdocs\dfpyme\index.php(37): CodeIgniter\CodeIgniter->run()
#5 {main}
ERROR - 2023-03-01 11:34:23 --> ErrorException: pg_query(): Query failed: ERROR:  no existe la columna «id_iva» en la relación «producto_factura_venta»
LINE 1: ...otal&quot;, &quot;valor_ico&quot;, &quot;impuesto_al_consumo&quot;, &quot;iva&quot;, &quot;id_iva&quot;, ...
                                                             ^ in C:\xampp\htdocs\dfpyme\system\Database\Postgre\Connection.php:135
Stack trace:
#0 [internal function]: CodeIgniter\Debug\Exceptions->errorHandler(2, 'pg_query(): Que...', 'C:\\xampp\\htdocs...', 135)
#1 C:\xampp\htdocs\dfpyme\system\Database\Postgre\Connection.php(135): pg_query(Resource id #158, 'INSERT INTO "pr...')
#2 C:\xampp\htdocs\dfpyme\system\Database\BaseConnection.php(670): CodeIgniter\Database\Postgre\Connection->execute('INSERT INTO "pr...')
#3 C:\xampp\htdocs\dfpyme\system\Database\BaseConnection.php(598): CodeIgniter\Database\BaseConnection->simpleQuery('INSERT INTO "pr...')
#4 C:\xampp\htdocs\dfpyme\system\Database\BaseBuilder.php(1771): CodeIgniter\Database\BaseConnection->query('INSERT INTO "pr...', Array, false)
#5 C:\xampp\htdocs\dfpyme\system\Model.php(239): CodeIgniter\Database\BaseBuilder->insert()
#6 C:\xampp\htdocs\dfpyme\system\BaseModel.php(738): CodeIgniter\Model->doInsert(Array)
#7 C:\xampp\htdocs\dfpyme\system\Model.php(625): CodeIgniter\BaseModel->insert(Array, true)
#8 C:\xampp\htdocs\dfpyme\app\Controllers\pedido\pedidoController.php(338): CodeIgniter\Model->insert(Array)
#9 C:\xampp\htdocs\dfpyme\app\Controllers\pedido\pedidoController.php(195): App\Controllers\pedido\pedidoController->facturacion_sin_impuestos('2023-03-01 11:3...', '30360', '40000', '0', '3200', '22222222', '8', '1', 40000)
#10 C:\xampp\htdocs\dfpyme\system\CodeIgniter.php(832): App\Controllers\pedido\pedidoController->cerrar_venta()
#11 C:\xampp\htdocs\dfpyme\system\CodeIgniter.php(419): CodeIgniter\CodeIgniter->runController(Object(App\Controllers\pedido\pedidoController))
#12 C:\xampp\htdocs\dfpyme\system\CodeIgniter.php(326): CodeIgniter\CodeIgniter->handleRequest(NULL, Object(Config\Cache), false)
#13 C:\xampp\htdocs\dfpyme\index.php(37): CodeIgniter\CodeIgniter->run()
#14 {main}
CRITICAL - 2023-03-01 11:34:23 --> pg_query(): Query failed: ERROR:  no existe la columna «id_iva» en la relación «producto_factura_venta»
LINE 1: ...otal&quot;, &quot;valor_ico&quot;, &quot;impuesto_al_consumo&quot;, &quot;iva&quot;, &quot;id_iva&quot;, ...
                                                             ^
#0 [internal function]: CodeIgniter\Debug\Exceptions->errorHandler(2, 'pg_query(): Que...', 'C:\\xampp\\htdocs...', 135)
#1 C:\xampp\htdocs\dfpyme\system\Database\Postgre\Connection.php(135): pg_query(Resource id #158, 'INSERT INTO "pr...')
#2 C:\xampp\htdocs\dfpyme\system\Database\BaseConnection.php(670): CodeIgniter\Database\Postgre\Connection->execute('INSERT INTO "pr...')
#3 C:\xampp\htdocs\dfpyme\system\Database\BaseConnection.php(598): CodeIgniter\Database\BaseConnection->simpleQuery('INSERT INTO "pr...')
#4 C:\xampp\htdocs\dfpyme\system\Database\BaseBuilder.php(1771): CodeIgniter\Database\BaseConnection->query('INSERT INTO "pr...', Array, false)
#5 C:\xampp\htdocs\dfpyme\system\Model.php(239): CodeIgniter\Database\BaseBuilder->insert()
#6 C:\xampp\htdocs\dfpyme\system\BaseModel.php(738): CodeIgniter\Model->doInsert(Array)
#7 C:\xampp\htdocs\dfpyme\system\Model.php(625): CodeIgniter\BaseModel->insert(Array, true)
#8 C:\xampp\htdocs\dfpyme\app\Controllers\pedido\pedidoController.php(338): CodeIgniter\Model->insert(Array)
#9 C:\xampp\htdocs\dfpyme\app\Controllers\pedido\pedidoController.php(195): App\Controllers\pedido\pedidoController->facturacion_sin_impuestos('2023-03-01 11:3...', '30360', '40000', '0', '3200', '22222222', '8', '1', 40000)
#10 C:\xampp\htdocs\dfpyme\system\CodeIgniter.php(832): App\Controllers\pedido\pedidoController->cerrar_venta()
#11 C:\xampp\htdocs\dfpyme\system\CodeIgniter.php(419): CodeIgniter\CodeIgniter->runController(Object(App\Controllers\pedido\pedidoController))
#12 C:\xampp\htdocs\dfpyme\system\CodeIgniter.php(326): CodeIgniter\CodeIgniter->handleRequest(NULL, Object(Config\Cache), false)
#13 C:\xampp\htdocs\dfpyme\index.php(37): CodeIgniter\CodeIgniter->run()
#14 {main}
CRITICAL - 2023-03-01 11:34:23 --> Uncaught CodeIgniter\Format\Exceptions\FormatException: Failed to parse json string, error: "Type is not supported". in C:\xampp\htdocs\dfpyme\system\Format\JSONFormatter.php:41
Stack trace:
#0 C:\xampp\htdocs\dfpyme\system\Format\JSONFormatter.php(41): CodeIgniter\Format\Exceptions\FormatException::forInvalidJSON('Type is not sup...')
#1 C:\xampp\htdocs\dfpyme\system\API\ResponseTrait.php(341): CodeIgniter\Format\JSONFormatter->format(Array)
#2 C:\xampp\htdocs\dfpyme\system\API\ResponseTrait.php(99): CodeIgniter\Debug\Exceptions->format(Array)
#3 C:\xampp\htdocs\dfpyme\system\Debug\Exceptions.php(115): CodeIgniter\Debug\Exceptions->respond(Array, 500)
#4 [internal function]: CodeIgniter\Debug\Exceptions->exceptionHandler(Object(ErrorException))
#5 {main}
  thrown
#0 [internal function]: CodeIgniter\Debug\Exceptions->shutdownHandler()
#1 {main}
ERROR - 2023-03-01 11:40:06 --> ErrorException: pg_query(): Query failed: ERROR:  la sintaxis de entrada no es válida para integer: «»
LINE 3: WHERE &quot;id&quot; = ''
                     ^ in C:\xampp\htdocs\dfpyme\system\Database\Postgre\Connection.php:135
Stack trace:
#0 [internal function]: CodeIgniter\Debug\Exceptions->errorHandler(2, 'pg_query(): Que...', 'C:\\xampp\\htdocs...', 135)
#1 C:\xampp\htdocs\dfpyme\system\Database\Postgre\Connection.php(135): pg_query(Resource id #158, 'SELECT "fk_usua...')
#2 C:\xampp\htdocs\dfpyme\system\Database\BaseConnection.php(670): CodeIgniter\Database\Postgre\Connection->execute('SELECT "fk_usua...')
#3 C:\xampp\htdocs\dfpyme\system\Database\BaseConnection.php(598): CodeIgniter\Database\BaseConnection->simpleQuery('SELECT "fk_usua...')
#4 C:\xampp\htdocs\dfpyme\system\Database\BaseBuilder.php(1455): CodeIgniter\Database\BaseConnection->query('SELECT "fk_usua...', Array, false)
#5 C:\xampp\htdocs\dfpyme\system\Model.php(210): CodeIgniter\Database\BaseBuilder->get()
#6 C:\xampp\htdocs\dfpyme\system\BaseModel.php(622): CodeIgniter\Model->doFirst()
#7 C:\xampp\htdocs\dfpyme\app\Controllers\pre_factura\prefacturaController.php(137): CodeIgniter\BaseModel->first()
#8 C:\xampp\htdocs\dfpyme\system\CodeIgniter.php(832): App\Controllers\pre_factura\prefacturaController->imprimir_desde_pedido()
#9 C:\xampp\htdocs\dfpyme\system\CodeIgniter.php(419): CodeIgniter\CodeIgniter->runController(Object(App\Controllers\pre_factura\prefacturaController))
#10 C:\xampp\htdocs\dfpyme\system\CodeIgniter.php(326): CodeIgniter\CodeIgniter->handleRequest(NULL, Object(Config\Cache), false)
#11 C:\xampp\htdocs\dfpyme\index.php(37): CodeIgniter\CodeIgniter->run()
#12 {main}
CRITICAL - 2023-03-01 11:40:06 --> pg_query(): Query failed: ERROR:  la sintaxis de entrada no es válida para integer: «»
LINE 3: WHERE &quot;id&quot; = ''
                     ^
#0 [internal function]: CodeIgniter\Debug\Exceptions->errorHandler(2, 'pg_query(): Que...', 'C:\\xampp\\htdocs...', 135)
#1 C:\xampp\htdocs\dfpyme\system\Database\Postgre\Connection.php(135): pg_query(Resource id #158, 'SELECT "fk_usua...')
#2 C:\xampp\htdocs\dfpyme\system\Database\BaseConnection.php(670): CodeIgniter\Database\Postgre\Connection->execute('SELECT "fk_usua...')
#3 C:\xampp\htdocs\dfpyme\system\Database\BaseConnection.php(598): CodeIgniter\Database\BaseConnection->simpleQuery('SELECT "fk_usua...')
#4 C:\xampp\htdocs\dfpyme\system\Database\BaseBuilder.php(1455): CodeIgniter\Database\BaseConnection->query('SELECT "fk_usua...', Array, false)
#5 C:\xampp\htdocs\dfpyme\system\Model.php(210): CodeIgniter\Database\BaseBuilder->get()
#6 C:\xampp\htdocs\dfpyme\system\BaseModel.php(622): CodeIgniter\Model->doFirst()
#7 C:\xampp\htdocs\dfpyme\app\Controllers\pre_factura\prefacturaController.php(137): CodeIgniter\BaseModel->first()
#8 C:\xampp\htdocs\dfpyme\system\CodeIgniter.php(832): App\Controllers\pre_factura\prefacturaController->imprimir_desde_pedido()
#9 C:\xampp\htdocs\dfpyme\system\CodeIgniter.php(419): CodeIgniter\CodeIgniter->runController(Object(App\Controllers\pre_factura\prefacturaController))
#10 C:\xampp\htdocs\dfpyme\system\CodeIgniter.php(326): CodeIgniter\CodeIgniter->handleRequest(NULL, Object(Config\Cache), false)
#11 C:\xampp\htdocs\dfpyme\index.php(37): CodeIgniter\CodeIgniter->run()
#12 {main}
CRITICAL - 2023-03-01 11:40:06 --> Uncaught CodeIgniter\Format\Exceptions\FormatException: Failed to parse json string, error: "Type is not supported". in C:\xampp\htdocs\dfpyme\system\Format\JSONFormatter.php:41
Stack trace:
#0 C:\xampp\htdocs\dfpyme\system\Format\JSONFormatter.php(41): CodeIgniter\Format\Exceptions\FormatException::forInvalidJSON('Type is not sup...')
#1 C:\xampp\htdocs\dfpyme\system\API\ResponseTrait.php(341): CodeIgniter\Format\JSONFormatter->format(Array)
#2 C:\xampp\htdocs\dfpyme\system\API\ResponseTrait.php(99): CodeIgniter\Debug\Exceptions->format(Array)
#3 C:\xampp\htdocs\dfpyme\system\Debug\Exceptions.php(115): CodeIgniter\Debug\Exceptions->respond(Array, 500)
#4 [internal function]: CodeIgniter\Debug\Exceptions->exceptionHandler(Object(ErrorException))
#5 {main}
  thrown
#0 [internal function]: CodeIgniter\Debug\Exceptions->shutdownHandler()
#1 {main}
ERROR - 2023-03-01 11:48:07 --> ErrorException: pg_query(): Query failed: ERROR:  no existe la columna «id_iva» en la relación «producto_factura_venta»
LINE 1: ...otal&quot;, &quot;valor_ico&quot;, &quot;impuesto_al_consumo&quot;, &quot;iva&quot;, &quot;id_iva&quot;, ...
                                                             ^ in C:\xampp\htdocs\dfpyme\system\Database\Postgre\Connection.php:135
Stack trace:
#0 [internal function]: CodeIgniter\Debug\Exceptions->errorHandler(2, 'pg_query(): Que...', 'C:\\xampp\\htdocs...', 135)
#1 C:\xampp\htdocs\dfpyme\system\Database\Postgre\Connection.php(135): pg_query(Resource id #158, 'INSERT INTO "pr...')
#2 C:\xampp\htdocs\dfpyme\system\Database\BaseConnection.php(670): CodeIgniter\Database\Postgre\Connection->execute('INSERT INTO "pr...')
#3 C:\xampp\htdocs\dfpyme\system\Database\BaseConnection.php(598): CodeIgniter\Database\BaseConnection->simpleQuery('INSERT INTO "pr...')
#4 C:\xampp\htdocs\dfpyme\system\Database\BaseBuilder.php(1771): CodeIgniter\Database\BaseConnection->query('INSERT INTO "pr...', Array, false)
#5 C:\xampp\htdocs\dfpyme\system\Model.php(239): CodeIgniter\Database\BaseBuilder->insert()
#6 C:\xampp\htdocs\dfpyme\system\BaseModel.php(738): CodeIgniter\Model->doInsert(Array)
#7 C:\xampp\htdocs\dfpyme\system\Model.php(625): CodeIgniter\BaseModel->insert(Array, true)
#8 C:\xampp\htdocs\dfpyme\app\Controllers\pedido\pedidoController.php(338): CodeIgniter\Model->insert(Array)
#9 C:\xampp\htdocs\dfpyme\app\Controllers\pedido\pedidoController.php(195): App\Controllers\pedido\pedidoController->facturacion_sin_impuestos('2023-03-01 11:4...', '30360', '40000', '0', '3200', '22222222', '8', '1', 40000)
#10 C:\xampp\htdocs\dfpyme\system\CodeIgniter.php(832): App\Controllers\pedido\pedidoController->cerrar_venta()
#11 C:\xampp\htdocs\dfpyme\system\CodeIgniter.php(419): CodeIgniter\CodeIgniter->runController(Object(App\Controllers\pedido\pedidoController))
#12 C:\xampp\htdocs\dfpyme\system\CodeIgniter.php(326): CodeIgniter\CodeIgniter->handleRequest(NULL, Object(Config\Cache), false)
#13 C:\xampp\htdocs\dfpyme\index.php(37): CodeIgniter\CodeIgniter->run()
#14 {main}
CRITICAL - 2023-03-01 11:48:07 --> pg_query(): Query failed: ERROR:  no existe la columna «id_iva» en la relación «producto_factura_venta»
LINE 1: ...otal&quot;, &quot;valor_ico&quot;, &quot;impuesto_al_consumo&quot;, &quot;iva&quot;, &quot;id_iva&quot;, ...
                                                             ^
#0 [internal function]: CodeIgniter\Debug\Exceptions->errorHandler(2, 'pg_query(): Que...', 'C:\\xampp\\htdocs...', 135)
#1 C:\xampp\htdocs\dfpyme\system\Database\Postgre\Connection.php(135): pg_query(Resource id #158, 'INSERT INTO "pr...')
#2 C:\xampp\htdocs\dfpyme\system\Database\BaseConnection.php(670): CodeIgniter\Database\Postgre\Connection->execute('INSERT INTO "pr...')
#3 C:\xampp\htdocs\dfpyme\system\Database\BaseConnection.php(598): CodeIgniter\Database\BaseConnection->simpleQuery('INSERT INTO "pr...')
#4 C:\xampp\htdocs\dfpyme\system\Database\BaseBuilder.php(1771): CodeIgniter\Database\BaseConnection->query('INSERT INTO "pr...', Array, false)
#5 C:\xampp\htdocs\dfpyme\system\Model.php(239): CodeIgniter\Database\BaseBuilder->insert()
#6 C:\xampp\htdocs\dfpyme\system\BaseModel.php(738): CodeIgniter\Model->doInsert(Array)
#7 C:\xampp\htdocs\dfpyme\system\Model.php(625): CodeIgniter\BaseModel->insert(Array, true)
#8 C:\xampp\htdocs\dfpyme\app\Controllers\pedido\pedidoController.php(338): CodeIgniter\Model->insert(Array)
#9 C:\xampp\htdocs\dfpyme\app\Controllers\pedido\pedidoController.php(195): App\Controllers\pedido\pedidoController->facturacion_sin_impuestos('2023-03-01 11:4...', '30360', '40000', '0', '3200', '22222222', '8', '1', 40000)
#10 C:\xampp\htdocs\dfpyme\system\CodeIgniter.php(832): App\Controllers\pedido\pedidoController->cerrar_venta()
#11 C:\xampp\htdocs\dfpyme\system\CodeIgniter.php(419): CodeIgniter\CodeIgniter->runController(Object(App\Controllers\pedido\pedidoController))
#12 C:\xampp\htdocs\dfpyme\system\CodeIgniter.php(326): CodeIgniter\CodeIgniter->handleRequest(NULL, Object(Config\Cache), false)
#13 C:\xampp\htdocs\dfpyme\index.php(37): CodeIgniter\CodeIgniter->run()
#14 {main}
CRITICAL - 2023-03-01 11:48:07 --> Uncaught CodeIgniter\Format\Exceptions\FormatException: Failed to parse json string, error: "Type is not supported". in C:\xampp\htdocs\dfpyme\system\Format\JSONFormatter.php:41
Stack trace:
#0 C:\xampp\htdocs\dfpyme\system\Format\JSONFormatter.php(41): CodeIgniter\Format\Exceptions\FormatException::forInvalidJSON('Type is not sup...')
#1 C:\xampp\htdocs\dfpyme\system\API\ResponseTrait.php(341): CodeIgniter\Format\JSONFormatter->format(Array)
#2 C:\xampp\htdocs\dfpyme\system\API\ResponseTrait.php(99): CodeIgniter\Debug\Exceptions->format(Array)
#3 C:\xampp\htdocs\dfpyme\system\Debug\Exceptions.php(115): CodeIgniter\Debug\Exceptions->respond(Array, 500)
#4 [internal function]: CodeIgniter\Debug\Exceptions->exceptionHandler(Object(ErrorException))
#5 {main}
  thrown
#0 [internal function]: CodeIgniter\Debug\Exceptions->shutdownHandler()
#1 {main}
ERROR - 2023-03-01 11:50:23 --> ErrorException: pg_query(): Query failed: ERROR:  no existe la columna «id_iva» en la relación «producto_factura_venta»
LINE 1: ...otal&quot;, &quot;valor_ico&quot;, &quot;impuesto_al_consumo&quot;, &quot;iva&quot;, &quot;id_iva&quot;, ...
                                                             ^ in C:\xampp\htdocs\dfpyme\system\Database\Postgre\Connection.php:135
Stack trace:
#0 [internal function]: CodeIgniter\Debug\Exceptions->errorHandler(2, 'pg_query(): Que...', 'C:\\xampp\\htdocs...', 135)
#1 C:\xampp\htdocs\dfpyme\system\Database\Postgre\Connection.php(135): pg_query(Resource id #158, 'INSERT INTO "pr...')
#2 C:\xampp\htdocs\dfpyme\system\Database\BaseConnection.php(670): CodeIgniter\Database\Postgre\Connection->execute('INSERT INTO "pr...')
#3 C:\xampp\htdocs\dfpyme\system\Database\BaseConnection.php(598): CodeIgniter\Database\BaseConnection->simpleQuery('INSERT INTO "pr...')
#4 C:\xampp\htdocs\dfpyme\system\Database\BaseBuilder.php(1771): CodeIgniter\Database\BaseConnection->query('INSERT INTO "pr...', Array, false)
#5 C:\xampp\htdocs\dfpyme\system\Model.php(239): CodeIgniter\Database\BaseBuilder->insert()
#6 C:\xampp\htdocs\dfpyme\system\BaseModel.php(738): CodeIgniter\Model->doInsert(Array)
#7 C:\xampp\htdocs\dfpyme\system\Model.php(625): CodeIgniter\BaseModel->insert(Array, true)
#8 C:\xampp\htdocs\dfpyme\app\Controllers\pedido\pedidoController.php(338): CodeIgniter\Model->insert(Array)
#9 C:\xampp\htdocs\dfpyme\app\Controllers\pedido\pedidoController.php(195): App\Controllers\pedido\pedidoController->facturacion_sin_impuestos('2023-03-01 11:5...', 30360, 200000, 200000, 400000, 22222222, 8, 1, 400000)
#10 C:\xampp\htdocs\dfpyme\system\CodeIgniter.php(832): App\Controllers\pedido\pedidoController->cerrar_venta()
#11 C:\xampp\htdocs\dfpyme\system\CodeIgniter.php(419): CodeIgniter\CodeIgniter->runController(Object(App\Controllers\pedido\pedidoController))
#12 C:\xampp\htdocs\dfpyme\system\CodeIgniter.php(326): CodeIgniter\CodeIgniter->handleRequest(NULL, Object(Config\Cache), false)
#13 C:\xampp\htdocs\dfpyme\index.php(37): CodeIgniter\CodeIgniter->run()
#14 {main}
CRITICAL - 2023-03-01 11:50:23 --> pg_query(): Query failed: ERROR:  no existe la columna «id_iva» en la relación «producto_factura_venta»
LINE 1: ...otal&quot;, &quot;valor_ico&quot;, &quot;impuesto_al_consumo&quot;, &quot;iva&quot;, &quot;id_iva&quot;, ...
                                                             ^
#0 [internal function]: CodeIgniter\Debug\Exceptions->errorHandler(2, 'pg_query(): Que...', 'C:\\xampp\\htdocs...', 135)
#1 C:\xampp\htdocs\dfpyme\system\Database\Postgre\Connection.php(135): pg_query(Resource id #158, 'INSERT INTO "pr...')
#2 C:\xampp\htdocs\dfpyme\system\Database\BaseConnection.php(670): CodeIgniter\Database\Postgre\Connection->execute('INSERT INTO "pr...')
#3 C:\xampp\htdocs\dfpyme\system\Database\BaseConnection.php(598): CodeIgniter\Database\BaseConnection->simpleQuery('INSERT INTO "pr...')
#4 C:\xampp\htdocs\dfpyme\system\Database\BaseBuilder.php(1771): CodeIgniter\Database\BaseConnection->query('INSERT INTO "pr...', Array, false)
#5 C:\xampp\htdocs\dfpyme\system\Model.php(239): CodeIgniter\Database\BaseBuilder->insert()
#6 C:\xampp\htdocs\dfpyme\system\BaseModel.php(738): CodeIgniter\Model->doInsert(Array)
#7 C:\xampp\htdocs\dfpyme\system\Model.php(625): CodeIgniter\BaseModel->insert(Array, true)
#8 C:\xampp\htdocs\dfpyme\app\Controllers\pedido\pedidoController.php(338): CodeIgniter\Model->insert(Array)
#9 C:\xampp\htdocs\dfpyme\app\Controllers\pedido\pedidoController.php(195): App\Controllers\pedido\pedidoController->facturacion_sin_impuestos('2023-03-01 11:5...', 30360, 200000, 200000, 400000, 22222222, 8, 1, 400000)
#10 C:\xampp\htdocs\dfpyme\system\CodeIgniter.php(832): App\Controllers\pedido\pedidoController->cerrar_venta()
#11 C:\xampp\htdocs\dfpyme\system\CodeIgniter.php(419): CodeIgniter\CodeIgniter->runController(Object(App\Controllers\pedido\pedidoController))
#12 C:\xampp\htdocs\dfpyme\system\CodeIgniter.php(326): CodeIgniter\CodeIgniter->handleRequest(NULL, Object(Config\Cache), false)
#13 C:\xampp\htdocs\dfpyme\index.php(37): CodeIgniter\CodeIgniter->run()
#14 {main}
ERROR - 2023-03-01 11:58:27 --> ErrorException: pg_query(): Query failed: ERROR:  no existe la columna «id_iva» en la relación «producto_factura_venta»
LINE 1: ...l_producto&quot;, &quot;fecha_y_hora_venta&quot;, &quot;fecha_venta&quot;, &quot;id_iva&quot;, ...
                                                             ^ in C:\xampp\htdocs\dfpyme\system\Database\Postgre\Connection.php:135
Stack trace:
#0 [internal function]: CodeIgniter\Debug\Exceptions->errorHandler(2, 'pg_query(): Que...', 'C:\\xampp\\htdocs...', 135)
#1 C:\xampp\htdocs\dfpyme\system\Database\Postgre\Connection.php(135): pg_query(Resource id #158, 'INSERT INTO "pr...')
#2 C:\xampp\htdocs\dfpyme\system\Database\BaseConnection.php(670): CodeIgniter\Database\Postgre\Connection->execute('INSERT INTO "pr...')
#3 C:\xampp\htdocs\dfpyme\system\Database\BaseConnection.php(598): CodeIgniter\Database\BaseConnection->simpleQuery('INSERT INTO "pr...')
#4 C:\xampp\htdocs\dfpyme\system\Database\BaseBuilder.php(1771): CodeIgniter\Database\BaseConnection->query('INSERT INTO "pr...', Array, false)
#5 C:\xampp\htdocs\dfpyme\system\Model.php(239): CodeIgniter\Database\BaseBuilder->insert()
#6 C:\xampp\htdocs\dfpyme\system\BaseModel.php(738): CodeIgniter\Model->doInsert(Array)
#7 C:\xampp\htdocs\dfpyme\system\Model.php(625): CodeIgniter\BaseModel->insert(Array, true)
#8 C:\xampp\htdocs\dfpyme\app\Controllers\factura_pos\facturaDirectaController.php(244): CodeIgniter\Model->insert(Array)
#9 C:\xampp\htdocs\dfpyme\app\Controllers\factura_pos\facturaDirectaController.php(83): App\Controllers\factura_pos\facturaDirectaController->facturacion_sin_impuestos('2023-03-01 11:5...', 0, '5000', '0', '2500', '22222222', '8', '1', '50000')
#10 C:\xampp\htdocs\dfpyme\system\CodeIgniter.php(832): App\Controllers\factura_pos\facturaDirectaController->facturacion()
#11 C:\xampp\htdocs\dfpyme\system\CodeIgniter.php(419): CodeIgniter\CodeIgniter->runController(Object(App\Controllers\factura_pos\facturaDirectaController))
#12 C:\xampp\htdocs\dfpyme\system\CodeIgniter.php(326): CodeIgniter\CodeIgniter->handleRequest(NULL, Object(Config\Cache), false)
#13 C:\xampp\htdocs\dfpyme\index.php(37): CodeIgniter\CodeIgniter->run()
#14 {main}
CRITICAL - 2023-03-01 11:58:27 --> pg_query(): Query failed: ERROR:  no existe la columna «id_iva» en la relación «producto_factura_venta»
LINE 1: ...l_producto&quot;, &quot;fecha_y_hora_venta&quot;, &quot;fecha_venta&quot;, &quot;id_iva&quot;, ...
                                                             ^
#0 [internal function]: CodeIgniter\Debug\Exceptions->errorHandler(2, 'pg_query(): Que...', 'C:\\xampp\\htdocs...', 135)
#1 C:\xampp\htdocs\dfpyme\system\Database\Postgre\Connection.php(135): pg_query(Resource id #158, 'INSERT INTO "pr...')
#2 C:\xampp\htdocs\dfpyme\system\Database\BaseConnection.php(670): CodeIgniter\Database\Postgre\Connection->execute('INSERT INTO "pr...')
#3 C:\xampp\htdocs\dfpyme\system\Database\BaseConnection.php(598): CodeIgniter\Database\BaseConnection->simpleQuery('INSERT INTO "pr...')
#4 C:\xampp\htdocs\dfpyme\system\Database\BaseBuilder.php(1771): CodeIgniter\Database\BaseConnection->query('INSERT INTO "pr...', Array, false)
#5 C:\xampp\htdocs\dfpyme\system\Model.php(239): CodeIgniter\Database\BaseBuilder->insert()
#6 C:\xampp\htdocs\dfpyme\system\BaseModel.php(738): CodeIgniter\Model->doInsert(Array)
#7 C:\xampp\htdocs\dfpyme\system\Model.php(625): CodeIgniter\BaseModel->insert(Array, true)
#8 C:\xampp\htdocs\dfpyme\app\Controllers\factura_pos\facturaDirectaController.php(244): CodeIgniter\Model->insert(Array)
#9 C:\xampp\htdocs\dfpyme\app\Controllers\factura_pos\facturaDirectaController.php(83): App\Controllers\factura_pos\facturaDirectaController->facturacion_sin_impuestos('2023-03-01 11:5...', 0, '5000', '0', '2500', '22222222', '8', '1', '50000')
#10 C:\xampp\htdocs\dfpyme\system\CodeIgniter.php(832): App\Controllers\factura_pos\facturaDirectaController->facturacion()
#11 C:\xampp\htdocs\dfpyme\system\CodeIgniter.php(419): CodeIgniter\CodeIgniter->runController(Object(App\Controllers\factura_pos\facturaDirectaController))
#12 C:\xampp\htdocs\dfpyme\system\CodeIgniter.php(326): CodeIgniter\CodeIgniter->handleRequest(NULL, Object(Config\Cache), false)
#13 C:\xampp\htdocs\dfpyme\index.php(37): CodeIgniter\CodeIgniter->run()
#14 {main}
CRITICAL - 2023-03-01 11:58:27 --> Uncaught CodeIgniter\Format\Exceptions\FormatException: Failed to parse json string, error: "Type is not supported". in C:\xampp\htdocs\dfpyme\system\Format\JSONFormatter.php:41
Stack trace:
#0 C:\xampp\htdocs\dfpyme\system\Format\JSONFormatter.php(41): CodeIgniter\Format\Exceptions\FormatException::forInvalidJSON('Type is not sup...')
#1 C:\xampp\htdocs\dfpyme\system\API\ResponseTrait.php(341): CodeIgniter\Format\JSONFormatter->format(Array)
#2 C:\xampp\htdocs\dfpyme\system\API\ResponseTrait.php(99): CodeIgniter\Debug\Exceptions->format(Array)
#3 C:\xampp\htdocs\dfpyme\system\Debug\Exceptions.php(115): CodeIgniter\Debug\Exceptions->respond(Array, 500)
#4 [internal function]: CodeIgniter\Debug\Exceptions->exceptionHandler(Object(ErrorException))
#5 {main}
  thrown
#0 [internal function]: CodeIgniter\Debug\Exceptions->shutdownHandler()
#1 {main}
ERROR - 2023-03-01 11:58:39 --> ErrorException: pg_query(): Query failed: ERROR:  no existe la columna «id_iva» en la relación «producto_factura_venta»
LINE 1: ...l_producto&quot;, &quot;fecha_y_hora_venta&quot;, &quot;fecha_venta&quot;, &quot;id_iva&quot;, ...
                                                             ^ in C:\xampp\htdocs\dfpyme\system\Database\Postgre\Connection.php:135
Stack trace:
#0 [internal function]: CodeIgniter\Debug\Exceptions->errorHandler(2, 'pg_query(): Que...', 'C:\\xampp\\htdocs...', 135)
#1 C:\xampp\htdocs\dfpyme\system\Database\Postgre\Connection.php(135): pg_query(Resource id #158, 'INSERT INTO "pr...')
#2 C:\xampp\htdocs\dfpyme\system\Database\BaseConnection.php(670): CodeIgniter\Database\Postgre\Connection->execute('INSERT INTO "pr...')
#3 C:\xampp\htdocs\dfpyme\system\Database\BaseConnection.php(598): CodeIgniter\Database\BaseConnection->simpleQuery('INSERT INTO "pr...')
#4 C:\xampp\htdocs\dfpyme\system\Database\BaseBuilder.php(1771): CodeIgniter\Database\BaseConnection->query('INSERT INTO "pr...', Array, false)
#5 C:\xampp\htdocs\dfpyme\system\Model.php(239): CodeIgniter\Database\BaseBuilder->insert()
#6 C:\xampp\htdocs\dfpyme\system\BaseModel.php(738): CodeIgniter\Model->doInsert(Array)
#7 C:\xampp\htdocs\dfpyme\system\Model.php(625): CodeIgniter\BaseModel->insert(Array, true)
#8 C:\xampp\htdocs\dfpyme\app\Controllers\factura_pos\facturaDirectaController.php(244): CodeIgniter\Model->insert(Array)
#9 C:\xampp\htdocs\dfpyme\app\Controllers\factura_pos\facturaDirectaController.php(83): App\Controllers\factura_pos\facturaDirectaController->facturacion_sin_impuestos('2023-03-01 11:5...', 0, '5000', '0', '2500', '22222222', '8', '1', '50000')
#10 C:\xampp\htdocs\dfpyme\system\CodeIgniter.php(832): App\Controllers\factura_pos\facturaDirectaController->facturacion()
#11 C:\xampp\htdocs\dfpyme\system\CodeIgniter.php(419): CodeIgniter\CodeIgniter->runController(Object(App\Controllers\factura_pos\facturaDirectaController))
#12 C:\xampp\htdocs\dfpyme\system\CodeIgniter.php(326): CodeIgniter\CodeIgniter->handleRequest(NULL, Object(Config\Cache), false)
#13 C:\xampp\htdocs\dfpyme\index.php(37): CodeIgniter\CodeIgniter->run()
#14 {main}
CRITICAL - 2023-03-01 11:58:39 --> pg_query(): Query failed: ERROR:  no existe la columna «id_iva» en la relación «producto_factura_venta»
LINE 1: ...l_producto&quot;, &quot;fecha_y_hora_venta&quot;, &quot;fecha_venta&quot;, &quot;id_iva&quot;, ...
                                                             ^
#0 [internal function]: CodeIgniter\Debug\Exceptions->errorHandler(2, 'pg_query(): Que...', 'C:\\xampp\\htdocs...', 135)
#1 C:\xampp\htdocs\dfpyme\system\Database\Postgre\Connection.php(135): pg_query(Resource id #158, 'INSERT INTO "pr...')
#2 C:\xampp\htdocs\dfpyme\system\Database\BaseConnection.php(670): CodeIgniter\Database\Postgre\Connection->execute('INSERT INTO "pr...')
#3 C:\xampp\htdocs\dfpyme\system\Database\BaseConnection.php(598): CodeIgniter\Database\BaseConnection->simpleQuery('INSERT INTO "pr...')
#4 C:\xampp\htdocs\dfpyme\system\Database\BaseBuilder.php(1771): CodeIgniter\Database\BaseConnection->query('INSERT INTO "pr...', Array, false)
#5 C:\xampp\htdocs\dfpyme\system\Model.php(239): CodeIgniter\Database\BaseBuilder->insert()
#6 C:\xampp\htdocs\dfpyme\system\BaseModel.php(738): CodeIgniter\Model->doInsert(Array)
#7 C:\xampp\htdocs\dfpyme\system\Model.php(625): CodeIgniter\BaseModel->insert(Array, true)
#8 C:\xampp\htdocs\dfpyme\app\Controllers\factura_pos\facturaDirectaController.php(244): CodeIgniter\Model->insert(Array)
#9 C:\xampp\htdocs\dfpyme\app\Controllers\factura_pos\facturaDirectaController.php(83): App\Controllers\factura_pos\facturaDirectaController->facturacion_sin_impuestos('2023-03-01 11:5...', 0, '5000', '0', '2500', '22222222', '8', '1', '50000')
#10 C:\xampp\htdocs\dfpyme\system\CodeIgniter.php(832): App\Controllers\factura_pos\facturaDirectaController->facturacion()
#11 C:\xampp\htdocs\dfpyme\system\CodeIgniter.php(419): CodeIgniter\CodeIgniter->runController(Object(App\Controllers\factura_pos\facturaDirectaController))
#12 C:\xampp\htdocs\dfpyme\system\CodeIgniter.php(326): CodeIgniter\CodeIgniter->handleRequest(NULL, Object(Config\Cache), false)
#13 C:\xampp\htdocs\dfpyme\index.php(37): CodeIgniter\CodeIgniter->run()
#14 {main}
CRITICAL - 2023-03-01 11:58:39 --> Uncaught CodeIgniter\Format\Exceptions\FormatException: Failed to parse json string, error: "Type is not supported". in C:\xampp\htdocs\dfpyme\system\Format\JSONFormatter.php:41
Stack trace:
#0 C:\xampp\htdocs\dfpyme\system\Format\JSONFormatter.php(41): CodeIgniter\Format\Exceptions\FormatException::forInvalidJSON('Type is not sup...')
#1 C:\xampp\htdocs\dfpyme\system\API\ResponseTrait.php(341): CodeIgniter\Format\JSONFormatter->format(Array)
#2 C:\xampp\htdocs\dfpyme\system\API\ResponseTrait.php(99): CodeIgniter\Debug\Exceptions->format(Array)
#3 C:\xampp\htdocs\dfpyme\system\Debug\Exceptions.php(115): CodeIgniter\Debug\Exceptions->respond(Array, 500)
#4 [internal function]: CodeIgniter\Debug\Exceptions->exceptionHandler(Object(ErrorException))
#5 {main}
  thrown
#0 [internal function]: CodeIgniter\Debug\Exceptions->shutdownHandler()
#1 {main}
ERROR - 2023-03-01 12:01:01 --> ErrorException: pg_query(): Query failed: ERROR:  no existe la columna «id_iva» en la relación «producto_factura_venta»
LINE 1: ...l_producto&quot;, &quot;fecha_y_hora_venta&quot;, &quot;fecha_venta&quot;, &quot;id_iva&quot;, ...
                                                             ^ in C:\xampp\htdocs\dfpyme\system\Database\Postgre\Connection.php:135
Stack trace:
#0 [internal function]: CodeIgniter\Debug\Exceptions->errorHandler(2, 'pg_query(): Que...', 'C:\\xampp\\htdocs...', 135)
#1 C:\xampp\htdocs\dfpyme\system\Database\Postgre\Connection.php(135): pg_query(Resource id #159, 'INSERT INTO "pr...')
#2 C:\xampp\htdocs\dfpyme\system\Database\BaseConnection.php(670): CodeIgniter\Database\Postgre\Connection->execute('INSERT INTO "pr...')
#3 C:\xampp\htdocs\dfpyme\system\Database\BaseConnection.php(598): CodeIgniter\Database\BaseConnection->simpleQuery('INSERT INTO "pr...')
#4 C:\xampp\htdocs\dfpyme\system\Database\BaseBuilder.php(1771): CodeIgniter\Database\BaseConnection->query('INSERT INTO "pr...', Array, false)
#5 C:\xampp\htdocs\dfpyme\system\Model.php(239): CodeIgniter\Database\BaseBuilder->insert()
#6 C:\xampp\htdocs\dfpyme\system\BaseModel.php(738): CodeIgniter\Model->doInsert(Array)
#7 C:\xampp\htdocs\dfpyme\system\Model.php(625): CodeIgniter\BaseModel->insert(Array, true)
#8 C:\xampp\htdocs\dfpyme\app\Controllers\factura_pos\facturaDirectaController.php(244): CodeIgniter\Model->insert(Array)
#9 C:\xampp\htdocs\dfpyme\app\Controllers\factura_pos\facturaDirectaController.php(83): App\Controllers\factura_pos\facturaDirectaController->facturacion_sin_impuestos('2023-03-01 12:0...', 0, '0', '200', '60', 22222222, 8, 1, '70')
#10 C:\xampp\htdocs\dfpyme\system\CodeIgniter.php(832): App\Controllers\factura_pos\facturaDirectaController->facturacion()
#11 C:\xampp\htdocs\dfpyme\system\CodeIgniter.php(419): CodeIgniter\CodeIgniter->runController(Object(App\Controllers\factura_pos\facturaDirectaController))
#12 C:\xampp\htdocs\dfpyme\system\CodeIgniter.php(326): CodeIgniter\CodeIgniter->handleRequest(NULL, Object(Config\Cache), false)
#13 C:\xampp\htdocs\dfpyme\index.php(37): CodeIgniter\CodeIgniter->run()
#14 {main}
CRITICAL - 2023-03-01 12:01:01 --> pg_query(): Query failed: ERROR:  no existe la columna «id_iva» en la relación «producto_factura_venta»
LINE 1: ...l_producto&quot;, &quot;fecha_y_hora_venta&quot;, &quot;fecha_venta&quot;, &quot;id_iva&quot;, ...
                                                             ^
#0 [internal function]: CodeIgniter\Debug\Exceptions->errorHandler(2, 'pg_query(): Que...', 'C:\\xampp\\htdocs...', 135)
#1 C:\xampp\htdocs\dfpyme\system\Database\Postgre\Connection.php(135): pg_query(Resource id #159, 'INSERT INTO "pr...')
#2 C:\xampp\htdocs\dfpyme\system\Database\BaseConnection.php(670): CodeIgniter\Database\Postgre\Connection->execute('INSERT INTO "pr...')
#3 C:\xampp\htdocs\dfpyme\system\Database\BaseConnection.php(598): CodeIgniter\Database\BaseConnection->simpleQuery('INSERT INTO "pr...')
#4 C:\xampp\htdocs\dfpyme\system\Database\BaseBuilder.php(1771): CodeIgniter\Database\BaseConnection->query('INSERT INTO "pr...', Array, false)
#5 C:\xampp\htdocs\dfpyme\system\Model.php(239): CodeIgniter\Database\BaseBuilder->insert()
#6 C:\xampp\htdocs\dfpyme\system\BaseModel.php(738): CodeIgniter\Model->doInsert(Array)
#7 C:\xampp\htdocs\dfpyme\system\Model.php(625): CodeIgniter\BaseModel->insert(Array, true)
#8 C:\xampp\htdocs\dfpyme\app\Controllers\factura_pos\facturaDirectaController.php(244): CodeIgniter\Model->insert(Array)
#9 C:\xampp\htdocs\dfpyme\app\Controllers\factura_pos\facturaDirectaController.php(83): App\Controllers\factura_pos\facturaDirectaController->facturacion_sin_impuestos('2023-03-01 12:0...', 0, '0', '200', '60', 22222222, 8, 1, '70')
#10 C:\xampp\htdocs\dfpyme\system\CodeIgniter.php(832): App\Controllers\factura_pos\facturaDirectaController->facturacion()
#11 C:\xampp\htdocs\dfpyme\system\CodeIgniter.php(419): CodeIgniter\CodeIgniter->runController(Object(App\Controllers\factura_pos\facturaDirectaController))
#12 C:\xampp\htdocs\dfpyme\system\CodeIgniter.php(326): CodeIgniter\CodeIgniter->handleRequest(NULL, Object(Config\Cache), false)
#13 C:\xampp\htdocs\dfpyme\index.php(37): CodeIgniter\CodeIgniter->run()
#14 {main}
CRITICAL - 2023-03-01 12:04:51 --> Undefined array key "id_de_factura"
#0 C:\xampp\htdocs\dfpyme\app\Controllers\consultas_y_reportes\duplicadoFacturaController.php(107): CodeIgniter\Debug\Exceptions->errorHandler(2, 'Undefined array...', 'C:\\xampp\\htdocs...', 107)
#1 C:\xampp\htdocs\dfpyme\system\CodeIgniter.php(832): App\Controllers\consultas_y_reportes\duplicadoFacturaController->imprimir_duplicado_factura()
#2 C:\xampp\htdocs\dfpyme\system\CodeIgniter.php(419): CodeIgniter\CodeIgniter->runController(Object(App\Controllers\consultas_y_reportes\duplicadoFacturaController))
#3 C:\xampp\htdocs\dfpyme\system\CodeIgniter.php(326): CodeIgniter\CodeIgniter->handleRequest(NULL, Object(Config\Cache), false)
#4 C:\xampp\htdocs\dfpyme\index.php(37): CodeIgniter\CodeIgniter->run()
#5 {main}
ERROR - 2023-03-01 13:43:28 --> Error connecting to the database: pg_connect(): Unable to connect to PostgreSQL server: FATAL:  el sistema de base de datos est� en modo de recuperaci�n
CRITICAL - 2023-03-01 13:43:28 --> Unable to connect to the database.
Main connection [Postgre]: pg_connect(): Unable to connect to PostgreSQL server: FATAL:  el sistema de base de datos est� en modo de recuperaci�n
#0 C:\xampp\htdocs\dfpyme\system\Database\BaseConnection.php(577): CodeIgniter\Database\BaseConnection->initialize()
#1 C:\xampp\htdocs\dfpyme\app\Models\productoFacturaVentaModel.php(53): CodeIgniter\Database\BaseConnection->query('\r\n        SELEC...')
#2 C:\xampp\htdocs\dfpyme\app\Controllers\consultas_y_reportes\duplicadoFacturaController.php(110): App\Models\productoFacturaVentaModel->getProductosFacturaVentaModel('61476')
#3 C:\xampp\htdocs\dfpyme\system\CodeIgniter.php(832): App\Controllers\consultas_y_reportes\duplicadoFacturaController->imprimir_duplicado_factura()
#4 C:\xampp\htdocs\dfpyme\system\CodeIgniter.php(419): CodeIgniter\CodeIgniter->runController(Object(App\Controllers\consultas_y_reportes\duplicadoFacturaController))
#5 C:\xampp\htdocs\dfpyme\system\CodeIgniter.php(326): CodeIgniter\CodeIgniter->handleRequest(NULL, Object(Config\Cache), false)
#6 C:\xampp\htdocs\dfpyme\index.php(37): CodeIgniter\CodeIgniter->run()
#7 {main}
ERROR - 2023-03-01 13:43:35 --> Error connecting to the database: pg_connect(): Unable to connect to PostgreSQL server: FATAL:  el sistema de base de datos est� en modo de recuperaci�n
CRITICAL - 2023-03-01 13:43:35 --> Unable to connect to the database.
Main connection [Postgre]: pg_connect(): Unable to connect to PostgreSQL server: FATAL:  el sistema de base de datos est� en modo de recuperaci�n
#0 C:\xampp\htdocs\dfpyme\system\Database\BaseConnection.php(577): CodeIgniter\Database\BaseConnection->initialize()
#1 C:\xampp\htdocs\dfpyme\app\Models\productoFacturaVentaModel.php(53): CodeIgniter\Database\BaseConnection->query('\r\n        SELEC...')
#2 C:\xampp\htdocs\dfpyme\app\Controllers\consultas_y_reportes\duplicadoFacturaController.php(110): App\Models\productoFacturaVentaModel->getProductosFacturaVentaModel('61476')
#3 C:\xampp\htdocs\dfpyme\system\CodeIgniter.php(832): App\Controllers\consultas_y_reportes\duplicadoFacturaController->imprimir_duplicado_factura()
#4 C:\xampp\htdocs\dfpyme\system\CodeIgniter.php(419): CodeIgniter\CodeIgniter->runController(Object(App\Controllers\consultas_y_reportes\duplicadoFacturaController))
#5 C:\xampp\htdocs\dfpyme\system\CodeIgniter.php(326): CodeIgniter\CodeIgniter->handleRequest(NULL, Object(Config\Cache), false)
#6 C:\xampp\htdocs\dfpyme\index.php(37): CodeIgniter\CodeIgniter->run()
#7 {main}
CRITICAL - 2023-03-01 13:52:51 --> Trying to access array offset on value of type null
#0 C:\xampp\htdocs\dfpyme\app\Views\producto\datos_consultar_agrupado.php(134): CodeIgniter\Debug\Exceptions->errorHandler(2, 'Trying to acces...', 'C:\\xampp\\htdocs...', 134)
#1 C:\xampp\htdocs\dfpyme\system\View\View.php(210): include('C:\\xampp\\htdocs...')
#2 C:\xampp\htdocs\dfpyme\system\View\View.php(213): CodeIgniter\View\View->CodeIgniter\View\{closure}()
#3 C:\xampp\htdocs\dfpyme\system\Common.php(1089): CodeIgniter\View\View->render('producto/datos_...', Array, true)
#4 C:\xampp\htdocs\dfpyme\app\Controllers\consultas_y_reportes\reporteDeVentasController.php(809): view('producto/datos_...', Array)
#5 C:\xampp\htdocs\dfpyme\system\CodeIgniter.php(832): App\Controllers\consultas_y_reportes\reporteDeVentasController->datos_consultar_producto_agrupado()
#6 C:\xampp\htdocs\dfpyme\system\CodeIgniter.php(419): CodeIgniter\CodeIgniter->runController(Object(App\Controllers\consultas_y_reportes\reporteDeVentasController))
#7 C:\xampp\htdocs\dfpyme\system\CodeIgniter.php(326): CodeIgniter\CodeIgniter->handleRequest(NULL, Object(Config\Cache), false)
#8 C:\xampp\htdocs\dfpyme\index.php(37): CodeIgniter\CodeIgniter->run()
#9 {main}
CRITICAL - 2023-03-01 13:53:39 --> Undefined array key "id_producto"
#0 C:\xampp\htdocs\dfpyme\app\Controllers\producto\productoController.php(427): CodeIgniter\Debug\Exceptions->errorHandler(2, 'Undefined array...', 'C:\\xampp\\htdocs...', 427)
#1 C:\xampp\htdocs\dfpyme\system\CodeIgniter.php(832): App\Controllers\producto\productoController->agregar_productos_x_categoria()
#2 C:\xampp\htdocs\dfpyme\system\CodeIgniter.php(419): CodeIgniter\CodeIgniter->runController(Object(App\Controllers\producto\productoController))
#3 C:\xampp\htdocs\dfpyme\system\CodeIgniter.php(326): CodeIgniter\CodeIgniter->handleRequest(NULL, Object(Config\Cache), false)
#4 C:\xampp\htdocs\dfpyme\index.php(37): CodeIgniter\CodeIgniter->run()
#5 {main}
ERROR - 2023-03-01 13:54:51 --> ErrorException: pg_query(): Query failed: ERROR:  la sintaxis de entrada no es válida para integer: «»
LINE 3: WHERE &quot;fk_mesa&quot; = ''
                          ^ in C:\xampp\htdocs\dfpyme\system\Database\Postgre\Connection.php:135
Stack trace:
#0 [internal function]: CodeIgniter\Debug\Exceptions->errorHandler(2, 'pg_query(): Que...', 'C:\\xampp\\htdocs...', 135)
#1 C:\xampp\htdocs\dfpyme\system\Database\Postgre\Connection.php(135): pg_query(Resource id #157, 'SELECT "id"\nFRO...')
#2 C:\xampp\htdocs\dfpyme\system\Database\BaseConnection.php(670): CodeIgniter\Database\Postgre\Connection->execute('SELECT "id"\nFRO...')
#3 C:\xampp\htdocs\dfpyme\system\Database\BaseConnection.php(598): CodeIgniter\Database\BaseConnection->simpleQuery('SELECT "id"\nFRO...')
#4 C:\xampp\htdocs\dfpyme\system\Database\BaseBuilder.php(1455): CodeIgniter\Database\BaseConnection->query('SELECT "id"\nFRO...', Array, false)
#5 C:\xampp\htdocs\dfpyme\system\Model.php(210): CodeIgniter\Database\BaseBuilder->get()
#6 C:\xampp\htdocs\dfpyme\system\BaseModel.php(622): CodeIgniter\Model->doFirst()
#7 C:\xampp\htdocs\dfpyme\app\Controllers\producto\productoController.php(202): CodeIgniter\BaseModel->first()
#8 C:\xampp\htdocs\dfpyme\system\CodeIgniter.php(832): App\Controllers\producto\productoController->insertar_productos_tabla_pedido()
#9 C:\xampp\htdocs\dfpyme\system\CodeIgniter.php(419): CodeIgniter\CodeIgniter->runController(Object(App\Controllers\producto\productoController))
#10 C:\xampp\htdocs\dfpyme\system\CodeIgniter.php(326): CodeIgniter\CodeIgniter->handleRequest(NULL, Object(Config\Cache), false)
#11 C:\xampp\htdocs\dfpyme\index.php(37): CodeIgniter\CodeIgniter->run()
#12 {main}
CRITICAL - 2023-03-01 13:54:51 --> pg_query(): Query failed: ERROR:  la sintaxis de entrada no es válida para integer: «»
LINE 3: WHERE &quot;fk_mesa&quot; = ''
                          ^
#0 [internal function]: CodeIgniter\Debug\Exceptions->errorHandler(2, 'pg_query(): Que...', 'C:\\xampp\\htdocs...', 135)
#1 C:\xampp\htdocs\dfpyme\system\Database\Postgre\Connection.php(135): pg_query(Resource id #157, 'SELECT "id"\nFRO...')
#2 C:\xampp\htdocs\dfpyme\system\Database\BaseConnection.php(670): CodeIgniter\Database\Postgre\Connection->execute('SELECT "id"\nFRO...')
#3 C:\xampp\htdocs\dfpyme\system\Database\BaseConnection.php(598): CodeIgniter\Database\BaseConnection->simpleQuery('SELECT "id"\nFRO...')
#4 C:\xampp\htdocs\dfpyme\system\Database\BaseBuilder.php(1455): CodeIgniter\Database\BaseConnection->query('SELECT "id"\nFRO...', Array, false)
#5 C:\xampp\htdocs\dfpyme\system\Model.php(210): CodeIgniter\Database\BaseBuilder->get()
#6 C:\xampp\htdocs\dfpyme\system\BaseModel.php(622): CodeIgniter\Model->doFirst()
#7 C:\xampp\htdocs\dfpyme\app\Controllers\producto\productoController.php(202): CodeIgniter\BaseModel->first()
#8 C:\xampp\htdocs\dfpyme\system\CodeIgniter.php(832): App\Controllers\producto\productoController->insertar_productos_tabla_pedido()
#9 C:\xampp\htdocs\dfpyme\system\CodeIgniter.php(419): CodeIgniter\CodeIgniter->runController(Object(App\Controllers\producto\productoController))
#10 C:\xampp\htdocs\dfpyme\system\CodeIgniter.php(326): CodeIgniter\CodeIgniter->handleRequest(NULL, Object(Config\Cache), false)
#11 C:\xampp\htdocs\dfpyme\index.php(37): CodeIgniter\CodeIgniter->run()
#12 {main}
CRITICAL - 2023-03-01 13:54:51 --> Uncaught CodeIgniter\Format\Exceptions\FormatException: Failed to parse json string, error: "Type is not supported". in C:\xampp\htdocs\dfpyme\system\Format\JSONFormatter.php:41
Stack trace:
#0 C:\xampp\htdocs\dfpyme\system\Format\JSONFormatter.php(41): CodeIgniter\Format\Exceptions\FormatException::forInvalidJSON('Type is not sup...')
#1 C:\xampp\htdocs\dfpyme\system\API\ResponseTrait.php(341): CodeIgniter\Format\JSONFormatter->format(Array)
#2 C:\xampp\htdocs\dfpyme\system\API\ResponseTrait.php(99): CodeIgniter\Debug\Exceptions->format(Array)
#3 C:\xampp\htdocs\dfpyme\system\Debug\Exceptions.php(115): CodeIgniter\Debug\Exceptions->respond(Array, 500)
#4 [internal function]: CodeIgniter\Debug\Exceptions->exceptionHandler(Object(ErrorException))
#5 {main}
  thrown
#0 [internal function]: CodeIgniter\Debug\Exceptions->shutdownHandler()
#1 {main}
ERROR - 2023-03-01 14:38:30 --> ErrorException: pg_query(): Query failed: ERROR:  no existe la columna «id_iva» en la relación «producto_factura_venta»
LINE 1: ...otal&quot;, &quot;valor_ico&quot;, &quot;impuesto_al_consumo&quot;, &quot;iva&quot;, &quot;id_iva&quot;, ...
                                                             ^ in C:\xampp\htdocs\dfpyme\system\Database\Postgre\Connection.php:135
Stack trace:
#0 [internal function]: CodeIgniter\Debug\Exceptions->errorHandler(2, 'pg_query(): Que...', 'C:\\xampp\\htdocs...', 135)
#1 C:\xampp\htdocs\dfpyme\system\Database\Postgre\Connection.php(135): pg_query(Resource id #157, 'INSERT INTO "pr...')
#2 C:\xampp\htdocs\dfpyme\system\Database\BaseConnection.php(670): CodeIgniter\Database\Postgre\Connection->execute('INSERT INTO "pr...')
#3 C:\xampp\htdocs\dfpyme\system\Database\BaseConnection.php(598): CodeIgniter\Database\BaseConnection->simpleQuery('INSERT INTO "pr...')
#4 C:\xampp\htdocs\dfpyme\system\Database\BaseBuilder.php(1771): CodeIgniter\Database\BaseConnection->query('INSERT INTO "pr...', Array, false)
#5 C:\xampp\htdocs\dfpyme\system\Model.php(239): CodeIgniter\Database\BaseBuilder->insert()
#6 C:\xampp\htdocs\dfpyme\system\BaseModel.php(738): CodeIgniter\Model->doInsert(Array)
#7 C:\xampp\htdocs\dfpyme\system\Model.php(625): CodeIgniter\BaseModel->insert(Array, true)
#8 C:\xampp\htdocs\dfpyme\app\Controllers\pedido\partirFacturaController.php(251): CodeIgniter\Model->insert(Array)
#9 C:\xampp\htdocs\dfpyme\app\Controllers\pedido\partirFacturaController.php(117): App\Controllers\pedido\partirFacturaController->facturacion_sin_impuestos('2023-03-01 14:3...', '30363', '10000', '0', '5500', '22222222', '8', '1', 10000)
#10 C:\xampp\htdocs\dfpyme\system\CodeIgniter.php(832): App\Controllers\pedido\partirFacturaController->facturar()
#11 C:\xampp\htdocs\dfpyme\system\CodeIgniter.php(419): CodeIgniter\CodeIgniter->runController(Object(App\Controllers\pedido\partirFacturaController))
#12 C:\xampp\htdocs\dfpyme\system\CodeIgniter.php(326): CodeIgniter\CodeIgniter->handleRequest(NULL, Object(Config\Cache), false)
#13 C:\xampp\htdocs\dfpyme\index.php(37): CodeIgniter\CodeIgniter->run()
#14 {main}
CRITICAL - 2023-03-01 14:38:30 --> pg_query(): Query failed: ERROR:  no existe la columna «id_iva» en la relación «producto_factura_venta»
LINE 1: ...otal&quot;, &quot;valor_ico&quot;, &quot;impuesto_al_consumo&quot;, &quot;iva&quot;, &quot;id_iva&quot;, ...
                                                             ^
#0 [internal function]: CodeIgniter\Debug\Exceptions->errorHandler(2, 'pg_query(): Que...', 'C:\\xampp\\htdocs...', 135)
#1 C:\xampp\htdocs\dfpyme\system\Database\Postgre\Connection.php(135): pg_query(Resource id #157, 'INSERT INTO "pr...')
#2 C:\xampp\htdocs\dfpyme\system\Database\BaseConnection.php(670): CodeIgniter\Database\Postgre\Connection->execute('INSERT INTO "pr...')
#3 C:\xampp\htdocs\dfpyme\system\Database\BaseConnection.php(598): CodeIgniter\Database\BaseConnection->simpleQuery('INSERT INTO "pr...')
#4 C:\xampp\htdocs\dfpyme\system\Database\BaseBuilder.php(1771): CodeIgniter\Database\BaseConnection->query('INSERT INTO "pr...', Array, false)
#5 C:\xampp\htdocs\dfpyme\system\Model.php(239): CodeIgniter\Database\BaseBuilder->insert()
#6 C:\xampp\htdocs\dfpyme\system\BaseModel.php(738): CodeIgniter\Model->doInsert(Array)
#7 C:\xampp\htdocs\dfpyme\system\Model.php(625): CodeIgniter\BaseModel->insert(Array, true)
#8 C:\xampp\htdocs\dfpyme\app\Controllers\pedido\partirFacturaController.php(251): CodeIgniter\Model->insert(Array)
#9 C:\xampp\htdocs\dfpyme\app\Controllers\pedido\partirFacturaController.php(117): App\Controllers\pedido\partirFacturaController->facturacion_sin_impuestos('2023-03-01 14:3...', '30363', '10000', '0', '5500', '22222222', '8', '1', 10000)
#10 C:\xampp\htdocs\dfpyme\system\CodeIgniter.php(832): App\Controllers\pedido\partirFacturaController->facturar()
#11 C:\xampp\htdocs\dfpyme\system\CodeIgniter.php(419): CodeIgniter\CodeIgniter->runController(Object(App\Controllers\pedido\partirFacturaController))
#12 C:\xampp\htdocs\dfpyme\system\CodeIgniter.php(326): CodeIgniter\CodeIgniter->handleRequest(NULL, Object(Config\Cache), false)
#13 C:\xampp\htdocs\dfpyme\index.php(37): CodeIgniter\CodeIgniter->run()
#14 {main}
CRITICAL - 2023-03-01 14:38:30 --> Uncaught CodeIgniter\Format\Exceptions\FormatException: Failed to parse json string, error: "Type is not supported". in C:\xampp\htdocs\dfpyme\system\Format\JSONFormatter.php:41
Stack trace:
#0 C:\xampp\htdocs\dfpyme\system\Format\JSONFormatter.php(41): CodeIgniter\Format\Exceptions\FormatException::forInvalidJSON('Type is not sup...')
#1 C:\xampp\htdocs\dfpyme\system\API\ResponseTrait.php(341): CodeIgniter\Format\JSONFormatter->format(Array)
#2 C:\xampp\htdocs\dfpyme\system\API\ResponseTrait.php(99): CodeIgniter\Debug\Exceptions->format(Array)
#3 C:\xampp\htdocs\dfpyme\system\Debug\Exceptions.php(115): CodeIgniter\Debug\Exceptions->respond(Array, 500)
#4 [internal function]: CodeIgniter\Debug\Exceptions->exceptionHandler(Object(ErrorException))
#5 {main}
  thrown
#0 [internal function]: CodeIgniter\Debug\Exceptions->shutdownHandler()
#1 {main}
CRITICAL - 2023-03-01 15:08:27 --> Undefined variable $pedido
#0 C:\xampp\htdocs\dfpyme\app\Views\productos_pedido\productos_pedido.php(106): CodeIgniter\Debug\Exceptions->errorHandler(2, 'Undefined varia...', 'C:\\xampp\\htdocs...', 106)
#1 C:\xampp\htdocs\dfpyme\system\View\View.php(210): include('C:\\xampp\\htdocs...')
#2 C:\xampp\htdocs\dfpyme\system\View\View.php(213): CodeIgniter\View\View->CodeIgniter\View\{closure}()
#3 C:\xampp\htdocs\dfpyme\system\Common.php(1089): CodeIgniter\View\View->render('productos_pedid...', Array, true)
#4 C:\xampp\htdocs\dfpyme\app\Controllers\producto\productoController.php(836): view('productos_pedid...', Array)
#5 C:\xampp\htdocs\dfpyme\system\CodeIgniter.php(832): App\Controllers\producto\productoController->actualizar_entregar_producto()
#6 C:\xampp\htdocs\dfpyme\system\CodeIgniter.php(419): CodeIgniter\CodeIgniter->runController(Object(App\Controllers\producto\productoController))
#7 C:\xampp\htdocs\dfpyme\system\CodeIgniter.php(326): CodeIgniter\CodeIgniter->handleRequest(NULL, Object(Config\Cache), false)
#8 C:\xampp\htdocs\dfpyme\index.php(37): CodeIgniter\CodeIgniter->run()
#9 {main}
CRITICAL - 2023-03-01 15:08:27 --> Uncaught CodeIgniter\Format\Exceptions\FormatException: Failed to parse json string, error: "Type is not supported". in C:\xampp\htdocs\dfpyme\system\Format\JSONFormatter.php:41
Stack trace:
#0 C:\xampp\htdocs\dfpyme\system\Format\JSONFormatter.php(41): CodeIgniter\Format\Exceptions\FormatException::forInvalidJSON('Type is not sup...')
#1 C:\xampp\htdocs\dfpyme\system\API\ResponseTrait.php(341): CodeIgniter\Format\JSONFormatter->format(Array)
#2 C:\xampp\htdocs\dfpyme\system\API\ResponseTrait.php(99): CodeIgniter\Debug\Exceptions->format(Array)
#3 C:\xampp\htdocs\dfpyme\system\Debug\Exceptions.php(115): CodeIgniter\Debug\Exceptions->respond(Array, 500)
#4 [internal function]: CodeIgniter\Debug\Exceptions->exceptionHandler(Object(ErrorException))
#5 {main}
  thrown
#0 [internal function]: CodeIgniter\Debug\Exceptions->shutdownHandler()
#1 {main}
ERROR - 2023-03-01 15:18:48 --> ErrorException: pg_query(): Query failed: ERROR:  no existe la columna «id_iva» en la relación «producto_factura_venta»
LINE 1: ...otal&quot;, &quot;valor_ico&quot;, &quot;impuesto_al_consumo&quot;, &quot;iva&quot;, &quot;id_iva&quot;, ...
                                                             ^ in C:\xampp\htdocs\dfpyme\system\Database\Postgre\Connection.php:135
Stack trace:
#0 [internal function]: CodeIgniter\Debug\Exceptions->errorHandler(2, 'pg_query(): Que...', 'C:\\xampp\\htdocs...', 135)
#1 C:\xampp\htdocs\dfpyme\system\Database\Postgre\Connection.php(135): pg_query(Resource id #158, 'INSERT INTO "pr...')
#2 C:\xampp\htdocs\dfpyme\system\Database\BaseConnection.php(670): CodeIgniter\Database\Postgre\Connection->execute('INSERT INTO "pr...')
#3 C:\xampp\htdocs\dfpyme\system\Database\BaseConnection.php(598): CodeIgniter\Database\BaseConnection->simpleQuery('INSERT INTO "pr...')
#4 C:\xampp\htdocs\dfpyme\system\Database\BaseBuilder.php(1771): CodeIgniter\Database\BaseConnection->query('INSERT INTO "pr...', Array, false)
#5 C:\xampp\htdocs\dfpyme\system\Model.php(239): CodeIgniter\Database\BaseBuilder->insert()
#6 C:\xampp\htdocs\dfpyme\system\BaseModel.php(738): CodeIgniter\Model->doInsert(Array)
#7 C:\xampp\htdocs\dfpyme\system\Model.php(625): CodeIgniter\BaseModel->insert(Array, true)
#8 C:\xampp\htdocs\dfpyme\app\Controllers\pedido\pedidoController.php(1593): CodeIgniter\Model->insert(Array)
#9 C:\xampp\htdocs\dfpyme\app\Controllers\pedido\pedidoController.php(1464): App\Controllers\pedido\pedidoController->facturacion_sin_impuestos_credito('2023-03-01 15:1...', '7600', 0, 0, 0, '98713702', '8', '2', 0)
#10 C:\xampp\htdocs\dfpyme\system\CodeIgniter.php(832): App\Controllers\pedido\pedidoController->facturar_credito()
#11 C:\xampp\htdocs\dfpyme\system\CodeIgniter.php(419): CodeIgniter\CodeIgniter->runController(Object(App\Controllers\pedido\pedidoController))
#12 C:\xampp\htdocs\dfpyme\system\CodeIgniter.php(326): CodeIgniter\CodeIgniter->handleRequest(NULL, Object(Config\Cache), false)
#13 C:\xampp\htdocs\dfpyme\index.php(37): CodeIgniter\CodeIgniter->run()
#14 {main}
CRITICAL - 2023-03-01 15:18:48 --> pg_query(): Query failed: ERROR:  no existe la columna «id_iva» en la relación «producto_factura_venta»
LINE 1: ...otal&quot;, &quot;valor_ico&quot;, &quot;impuesto_al_consumo&quot;, &quot;iva&quot;, &quot;id_iva&quot;, ...
                                                             ^
#0 [internal function]: CodeIgniter\Debug\Exceptions->errorHandler(2, 'pg_query(): Que...', 'C:\\xampp\\htdocs...', 135)
#1 C:\xampp\htdocs\dfpyme\system\Database\Postgre\Connection.php(135): pg_query(Resource id #158, 'INSERT INTO "pr...')
#2 C:\xampp\htdocs\dfpyme\system\Database\BaseConnection.php(670): CodeIgniter\Database\Postgre\Connection->execute('INSERT INTO "pr...')
#3 C:\xampp\htdocs\dfpyme\system\Database\BaseConnection.php(598): CodeIgniter\Database\BaseConnection->simpleQuery('INSERT INTO "pr...')
#4 C:\xampp\htdocs\dfpyme\system\Database\BaseBuilder.php(1771): CodeIgniter\Database\BaseConnection->query('INSERT INTO "pr...', Array, false)
#5 C:\xampp\htdocs\dfpyme\system\Model.php(239): CodeIgniter\Database\BaseBuilder->insert()
#6 C:\xampp\htdocs\dfpyme\system\BaseModel.php(738): CodeIgniter\Model->doInsert(Array)
#7 C:\xampp\htdocs\dfpyme\system\Model.php(625): CodeIgniter\BaseModel->insert(Array, true)
#8 C:\xampp\htdocs\dfpyme\app\Controllers\pedido\pedidoController.php(1593): CodeIgniter\Model->insert(Array)
#9 C:\xampp\htdocs\dfpyme\app\Controllers\pedido\pedidoController.php(1464): App\Controllers\pedido\pedidoController->facturacion_sin_impuestos_credito('2023-03-01 15:1...', '7600', 0, 0, 0, '98713702', '8', '2', 0)
#10 C:\xampp\htdocs\dfpyme\system\CodeIgniter.php(832): App\Controllers\pedido\pedidoController->facturar_credito()
#11 C:\xampp\htdocs\dfpyme\system\CodeIgniter.php(419): CodeIgniter\CodeIgniter->runController(Object(App\Controllers\pedido\pedidoController))
#12 C:\xampp\htdocs\dfpyme\system\CodeIgniter.php(326): CodeIgniter\CodeIgniter->handleRequest(NULL, Object(Config\Cache), false)
#13 C:\xampp\htdocs\dfpyme\index.php(37): CodeIgniter\CodeIgniter->run()
#14 {main}
CRITICAL - 2023-03-01 15:18:48 --> Uncaught CodeIgniter\Format\Exceptions\FormatException: Failed to parse json string, error: "Type is not supported". in C:\xampp\htdocs\dfpyme\system\Format\JSONFormatter.php:41
Stack trace:
#0 C:\xampp\htdocs\dfpyme\system\Format\JSONFormatter.php(41): CodeIgniter\Format\Exceptions\FormatException::forInvalidJSON('Type is not sup...')
#1 C:\xampp\htdocs\dfpyme\system\API\ResponseTrait.php(341): CodeIgniter\Format\JSONFormatter->format(Array)
#2 C:\xampp\htdocs\dfpyme\system\API\ResponseTrait.php(99): CodeIgniter\Debug\Exceptions->format(Array)
#3 C:\xampp\htdocs\dfpyme\system\Debug\Exceptions.php(115): CodeIgniter\Debug\Exceptions->respond(Array, 500)
#4 [internal function]: CodeIgniter\Debug\Exceptions->exceptionHandler(Object(ErrorException))
#5 {main}
  thrown
#0 [internal function]: CodeIgniter\Debug\Exceptions->shutdownHandler()
#1 {main}
ERROR - 2023-03-01 15:19:01 --> ErrorException: pg_query(): Query failed: ERROR:  no existe la columna «id_iva» en la relación «producto_factura_venta»
LINE 1: ...otal&quot;, &quot;valor_ico&quot;, &quot;impuesto_al_consumo&quot;, &quot;iva&quot;, &quot;id_iva&quot;, ...
                                                             ^ in C:\xampp\htdocs\dfpyme\system\Database\Postgre\Connection.php:135
Stack trace:
#0 [internal function]: CodeIgniter\Debug\Exceptions->errorHandler(2, 'pg_query(): Que...', 'C:\\xampp\\htdocs...', 135)
#1 C:\xampp\htdocs\dfpyme\system\Database\Postgre\Connection.php(135): pg_query(Resource id #158, 'INSERT INTO "pr...')
#2 C:\xampp\htdocs\dfpyme\system\Database\BaseConnection.php(670): CodeIgniter\Database\Postgre\Connection->execute('INSERT INTO "pr...')
#3 C:\xampp\htdocs\dfpyme\system\Database\BaseConnection.php(598): CodeIgniter\Database\BaseConnection->simpleQuery('INSERT INTO "pr...')
#4 C:\xampp\htdocs\dfpyme\system\Database\BaseBuilder.php(1771): CodeIgniter\Database\BaseConnection->query('INSERT INTO "pr...', Array, false)
#5 C:\xampp\htdocs\dfpyme\system\Model.php(239): CodeIgniter\Database\BaseBuilder->insert()
#6 C:\xampp\htdocs\dfpyme\system\BaseModel.php(738): CodeIgniter\Model->doInsert(Array)
#7 C:\xampp\htdocs\dfpyme\system\Model.php(625): CodeIgniter\BaseModel->insert(Array, true)
#8 C:\xampp\htdocs\dfpyme\app\Controllers\pedido\pedidoController.php(1593): CodeIgniter\Model->insert(Array)
#9 C:\xampp\htdocs\dfpyme\app\Controllers\pedido\pedidoController.php(1464): App\Controllers\pedido\pedidoController->facturacion_sin_impuestos_credito('2023-03-01 15:1...', '7600', 0, 0, 0, '98713702', '8', '2', 0)
#10 C:\xampp\htdocs\dfpyme\system\CodeIgniter.php(832): App\Controllers\pedido\pedidoController->facturar_credito()
#11 C:\xampp\htdocs\dfpyme\system\CodeIgniter.php(419): CodeIgniter\CodeIgniter->runController(Object(App\Controllers\pedido\pedidoController))
#12 C:\xampp\htdocs\dfpyme\system\CodeIgniter.php(326): CodeIgniter\CodeIgniter->handleRequest(NULL, Object(Config\Cache), false)
#13 C:\xampp\htdocs\dfpyme\index.php(37): CodeIgniter\CodeIgniter->run()
#14 {main}
CRITICAL - 2023-03-01 15:19:01 --> pg_query(): Query failed: ERROR:  no existe la columna «id_iva» en la relación «producto_factura_venta»
LINE 1: ...otal&quot;, &quot;valor_ico&quot;, &quot;impuesto_al_consumo&quot;, &quot;iva&quot;, &quot;id_iva&quot;, ...
                                                             ^
#0 [internal function]: CodeIgniter\Debug\Exceptions->errorHandler(2, 'pg_query(): Que...', 'C:\\xampp\\htdocs...', 135)
#1 C:\xampp\htdocs\dfpyme\system\Database\Postgre\Connection.php(135): pg_query(Resource id #158, 'INSERT INTO "pr...')
#2 C:\xampp\htdocs\dfpyme\system\Database\BaseConnection.php(670): CodeIgniter\Database\Postgre\Connection->execute('INSERT INTO "pr...')
#3 C:\xampp\htdocs\dfpyme\system\Database\BaseConnection.php(598): CodeIgniter\Database\BaseConnection->simpleQuery('INSERT INTO "pr...')
#4 C:\xampp\htdocs\dfpyme\system\Database\BaseBuilder.php(1771): CodeIgniter\Database\BaseConnection->query('INSERT INTO "pr...', Array, false)
#5 C:\xampp\htdocs\dfpyme\system\Model.php(239): CodeIgniter\Database\BaseBuilder->insert()
#6 C:\xampp\htdocs\dfpyme\system\BaseModel.php(738): CodeIgniter\Model->doInsert(Array)
#7 C:\xampp\htdocs\dfpyme\system\Model.php(625): CodeIgniter\BaseModel->insert(Array, true)
#8 C:\xampp\htdocs\dfpyme\app\Controllers\pedido\pedidoController.php(1593): CodeIgniter\Model->insert(Array)
#9 C:\xampp\htdocs\dfpyme\app\Controllers\pedido\pedidoController.php(1464): App\Controllers\pedido\pedidoController->facturacion_sin_impuestos_credito('2023-03-01 15:1...', '7600', 0, 0, 0, '98713702', '8', '2', 0)
#10 C:\xampp\htdocs\dfpyme\system\CodeIgniter.php(832): App\Controllers\pedido\pedidoController->facturar_credito()
#11 C:\xampp\htdocs\dfpyme\system\CodeIgniter.php(419): CodeIgniter\CodeIgniter->runController(Object(App\Controllers\pedido\pedidoController))
#12 C:\xampp\htdocs\dfpyme\system\CodeIgniter.php(326): CodeIgniter\CodeIgniter->handleRequest(NULL, Object(Config\Cache), false)
#13 C:\xampp\htdocs\dfpyme\index.php(37): CodeIgniter\CodeIgniter->run()
#14 {main}
CRITICAL - 2023-03-01 15:19:01 --> Uncaught CodeIgniter\Format\Exceptions\FormatException: Failed to parse json string, error: "Type is not supported". in C:\xampp\htdocs\dfpyme\system\Format\JSONFormatter.php:41
Stack trace:
#0 C:\xampp\htdocs\dfpyme\system\Format\JSONFormatter.php(41): CodeIgniter\Format\Exceptions\FormatException::forInvalidJSON('Type is not sup...')
#1 C:\xampp\htdocs\dfpyme\system\API\ResponseTrait.php(341): CodeIgniter\Format\JSONFormatter->format(Array)
#2 C:\xampp\htdocs\dfpyme\system\API\ResponseTrait.php(99): CodeIgniter\Debug\Exceptions->format(Array)
#3 C:\xampp\htdocs\dfpyme\system\Debug\Exceptions.php(115): CodeIgniter\Debug\Exceptions->respond(Array, 500)
#4 [internal function]: CodeIgniter\Debug\Exceptions->exceptionHandler(Object(ErrorException))
#5 {main}
  thrown
#0 [internal function]: CodeIgniter\Debug\Exceptions->shutdownHandler()
#1 {main}
ERROR - 2023-03-01 15:19:32 --> ErrorException: pg_query(): Query failed: ERROR:  no existe la columna «id_iva» en la relación «producto_factura_venta»
LINE 1: ...otal&quot;, &quot;valor_ico&quot;, &quot;impuesto_al_consumo&quot;, &quot;iva&quot;, &quot;id_iva&quot;, ...
                                                             ^ in C:\xampp\htdocs\dfpyme\system\Database\Postgre\Connection.php:135
Stack trace:
#0 [internal function]: CodeIgniter\Debug\Exceptions->errorHandler(2, 'pg_query(): Que...', 'C:\\xampp\\htdocs...', 135)
#1 C:\xampp\htdocs\dfpyme\system\Database\Postgre\Connection.php(135): pg_query(Resource id #158, 'INSERT INTO "pr...')
#2 C:\xampp\htdocs\dfpyme\system\Database\BaseConnection.php(670): CodeIgniter\Database\Postgre\Connection->execute('INSERT INTO "pr...')
#3 C:\xampp\htdocs\dfpyme\system\Database\BaseConnection.php(598): CodeIgniter\Database\BaseConnection->simpleQuery('INSERT INTO "pr...')
#4 C:\xampp\htdocs\dfpyme\system\Database\BaseBuilder.php(1771): CodeIgniter\Database\BaseConnection->query('INSERT INTO "pr...', Array, false)
#5 C:\xampp\htdocs\dfpyme\system\Model.php(239): CodeIgniter\Database\BaseBuilder->insert()
#6 C:\xampp\htdocs\dfpyme\system\BaseModel.php(738): CodeIgniter\Model->doInsert(Array)
#7 C:\xampp\htdocs\dfpyme\system\Model.php(625): CodeIgniter\BaseModel->insert(Array, true)
#8 C:\xampp\htdocs\dfpyme\app\Controllers\pedido\pedidoController.php(1593): CodeIgniter\Model->insert(Array)
#9 C:\xampp\htdocs\dfpyme\app\Controllers\pedido\pedidoController.php(1464): App\Controllers\pedido\pedidoController->facturacion_sin_impuestos_credito('2023-03-01 15:1...', '7600', 0, 0, 0, '98713702', '8', '2', 0)
#10 C:\xampp\htdocs\dfpyme\system\CodeIgniter.php(832): App\Controllers\pedido\pedidoController->facturar_credito()
#11 C:\xampp\htdocs\dfpyme\system\CodeIgniter.php(419): CodeIgniter\CodeIgniter->runController(Object(App\Controllers\pedido\pedidoController))
#12 C:\xampp\htdocs\dfpyme\system\CodeIgniter.php(326): CodeIgniter\CodeIgniter->handleRequest(NULL, Object(Config\Cache), false)
#13 C:\xampp\htdocs\dfpyme\index.php(37): CodeIgniter\CodeIgniter->run()
#14 {main}
CRITICAL - 2023-03-01 15:19:32 --> pg_query(): Query failed: ERROR:  no existe la columna «id_iva» en la relación «producto_factura_venta»
LINE 1: ...otal&quot;, &quot;valor_ico&quot;, &quot;impuesto_al_consumo&quot;, &quot;iva&quot;, &quot;id_iva&quot;, ...
                                                             ^
#0 [internal function]: CodeIgniter\Debug\Exceptions->errorHandler(2, 'pg_query(): Que...', 'C:\\xampp\\htdocs...', 135)
#1 C:\xampp\htdocs\dfpyme\system\Database\Postgre\Connection.php(135): pg_query(Resource id #158, 'INSERT INTO "pr...')
#2 C:\xampp\htdocs\dfpyme\system\Database\BaseConnection.php(670): CodeIgniter\Database\Postgre\Connection->execute('INSERT INTO "pr...')
#3 C:\xampp\htdocs\dfpyme\system\Database\BaseConnection.php(598): CodeIgniter\Database\BaseConnection->simpleQuery('INSERT INTO "pr...')
#4 C:\xampp\htdocs\dfpyme\system\Database\BaseBuilder.php(1771): CodeIgniter\Database\BaseConnection->query('INSERT INTO "pr...', Array, false)
#5 C:\xampp\htdocs\dfpyme\system\Model.php(239): CodeIgniter\Database\BaseBuilder->insert()
#6 C:\xampp\htdocs\dfpyme\system\BaseModel.php(738): CodeIgniter\Model->doInsert(Array)
#7 C:\xampp\htdocs\dfpyme\system\Model.php(625): CodeIgniter\BaseModel->insert(Array, true)
#8 C:\xampp\htdocs\dfpyme\app\Controllers\pedido\pedidoController.php(1593): CodeIgniter\Model->insert(Array)
#9 C:\xampp\htdocs\dfpyme\app\Controllers\pedido\pedidoController.php(1464): App\Controllers\pedido\pedidoController->facturacion_sin_impuestos_credito('2023-03-01 15:1...', '7600', 0, 0, 0, '98713702', '8', '2', 0)
#10 C:\xampp\htdocs\dfpyme\system\CodeIgniter.php(832): App\Controllers\pedido\pedidoController->facturar_credito()
#11 C:\xampp\htdocs\dfpyme\system\CodeIgniter.php(419): CodeIgniter\CodeIgniter->runController(Object(App\Controllers\pedido\pedidoController))
#12 C:\xampp\htdocs\dfpyme\system\CodeIgniter.php(326): CodeIgniter\CodeIgniter->handleRequest(NULL, Object(Config\Cache), false)
#13 C:\xampp\htdocs\dfpyme\index.php(37): CodeIgniter\CodeIgniter->run()
#14 {main}
CRITICAL - 2023-03-01 15:19:32 --> Uncaught CodeIgniter\Format\Exceptions\FormatException: Failed to parse json string, error: "Type is not supported". in C:\xampp\htdocs\dfpyme\system\Format\JSONFormatter.php:41
Stack trace:
#0 C:\xampp\htdocs\dfpyme\system\Format\JSONFormatter.php(41): CodeIgniter\Format\Exceptions\FormatException::forInvalidJSON('Type is not sup...')
#1 C:\xampp\htdocs\dfpyme\system\API\ResponseTrait.php(341): CodeIgniter\Format\JSONFormatter->format(Array)
#2 C:\xampp\htdocs\dfpyme\system\API\ResponseTrait.php(99): CodeIgniter\Debug\Exceptions->format(Array)
#3 C:\xampp\htdocs\dfpyme\system\Debug\Exceptions.php(115): CodeIgniter\Debug\Exceptions->respond(Array, 500)
#4 [internal function]: CodeIgniter\Debug\Exceptions->exceptionHandler(Object(ErrorException))
#5 {main}
  thrown
#0 [internal function]: CodeIgniter\Debug\Exceptions->shutdownHandler()
#1 {main}
ERROR - 2023-03-01 15:19:45 --> ErrorException: pg_query(): Query failed: ERROR:  no existe la columna «id_iva» en la relación «producto_factura_venta»
LINE 1: ...otal&quot;, &quot;valor_ico&quot;, &quot;impuesto_al_consumo&quot;, &quot;iva&quot;, &quot;id_iva&quot;, ...
                                                             ^ in C:\xampp\htdocs\dfpyme\system\Database\Postgre\Connection.php:135
Stack trace:
#0 [internal function]: CodeIgniter\Debug\Exceptions->errorHandler(2, 'pg_query(): Que...', 'C:\\xampp\\htdocs...', 135)
#1 C:\xampp\htdocs\dfpyme\system\Database\Postgre\Connection.php(135): pg_query(Resource id #158, 'INSERT INTO "pr...')
#2 C:\xampp\htdocs\dfpyme\system\Database\BaseConnection.php(670): CodeIgniter\Database\Postgre\Connection->execute('INSERT INTO "pr...')
#3 C:\xampp\htdocs\dfpyme\system\Database\BaseConnection.php(598): CodeIgniter\Database\BaseConnection->simpleQuery('INSERT INTO "pr...')
#4 C:\xampp\htdocs\dfpyme\system\Database\BaseBuilder.php(1771): CodeIgniter\Database\BaseConnection->query('INSERT INTO "pr...', Array, false)
#5 C:\xampp\htdocs\dfpyme\system\Model.php(239): CodeIgniter\Database\BaseBuilder->insert()
#6 C:\xampp\htdocs\dfpyme\system\BaseModel.php(738): CodeIgniter\Model->doInsert(Array)
#7 C:\xampp\htdocs\dfpyme\system\Model.php(625): CodeIgniter\BaseModel->insert(Array, true)
#8 C:\xampp\htdocs\dfpyme\app\Controllers\pedido\pedidoController.php(1593): CodeIgniter\Model->insert(Array)
#9 C:\xampp\htdocs\dfpyme\app\Controllers\pedido\pedidoController.php(1464): App\Controllers\pedido\pedidoController->facturacion_sin_impuestos_credito('2023-03-01 15:1...', '7600', 0, 0, 0, '98713702', '8', '2', 0)
#10 C:\xampp\htdocs\dfpyme\system\CodeIgniter.php(832): App\Controllers\pedido\pedidoController->facturar_credito()
#11 C:\xampp\htdocs\dfpyme\system\CodeIgniter.php(419): CodeIgniter\CodeIgniter->runController(Object(App\Controllers\pedido\pedidoController))
#12 C:\xampp\htdocs\dfpyme\system\CodeIgniter.php(326): CodeIgniter\CodeIgniter->handleRequest(NULL, Object(Config\Cache), false)
#13 C:\xampp\htdocs\dfpyme\index.php(37): CodeIgniter\CodeIgniter->run()
#14 {main}
CRITICAL - 2023-03-01 15:19:45 --> pg_query(): Query failed: ERROR:  no existe la columna «id_iva» en la relación «producto_factura_venta»
LINE 1: ...otal&quot;, &quot;valor_ico&quot;, &quot;impuesto_al_consumo&quot;, &quot;iva&quot;, &quot;id_iva&quot;, ...
                                                             ^
#0 [internal function]: CodeIgniter\Debug\Exceptions->errorHandler(2, 'pg_query(): Que...', 'C:\\xampp\\htdocs...', 135)
#1 C:\xampp\htdocs\dfpyme\system\Database\Postgre\Connection.php(135): pg_query(Resource id #158, 'INSERT INTO "pr...')
#2 C:\xampp\htdocs\dfpyme\system\Database\BaseConnection.php(670): CodeIgniter\Database\Postgre\Connection->execute('INSERT INTO "pr...')
#3 C:\xampp\htdocs\dfpyme\system\Database\BaseConnection.php(598): CodeIgniter\Database\BaseConnection->simpleQuery('INSERT INTO "pr...')
#4 C:\xampp\htdocs\dfpyme\system\Database\BaseBuilder.php(1771): CodeIgniter\Database\BaseConnection->query('INSERT INTO "pr...', Array, false)
#5 C:\xampp\htdocs\dfpyme\system\Model.php(239): CodeIgniter\Database\BaseBuilder->insert()
#6 C:\xampp\htdocs\dfpyme\system\BaseModel.php(738): CodeIgniter\Model->doInsert(Array)
#7 C:\xampp\htdocs\dfpyme\system\Model.php(625): CodeIgniter\BaseModel->insert(Array, true)
#8 C:\xampp\htdocs\dfpyme\app\Controllers\pedido\pedidoController.php(1593): CodeIgniter\Model->insert(Array)
#9 C:\xampp\htdocs\dfpyme\app\Controllers\pedido\pedidoController.php(1464): App\Controllers\pedido\pedidoController->facturacion_sin_impuestos_credito('2023-03-01 15:1...', '7600', 0, 0, 0, '98713702', '8', '2', 0)
#10 C:\xampp\htdocs\dfpyme\system\CodeIgniter.php(832): App\Controllers\pedido\pedidoController->facturar_credito()
#11 C:\xampp\htdocs\dfpyme\system\CodeIgniter.php(419): CodeIgniter\CodeIgniter->runController(Object(App\Controllers\pedido\pedidoController))
#12 C:\xampp\htdocs\dfpyme\system\CodeIgniter.php(326): CodeIgniter\CodeIgniter->handleRequest(NULL, Object(Config\Cache), false)
#13 C:\xampp\htdocs\dfpyme\index.php(37): CodeIgniter\CodeIgniter->run()
#14 {main}
CRITICAL - 2023-03-01 15:19:45 --> Uncaught CodeIgniter\Format\Exceptions\FormatException: Failed to parse json string, error: "Type is not supported". in C:\xampp\htdocs\dfpyme\system\Format\JSONFormatter.php:41
Stack trace:
#0 C:\xampp\htdocs\dfpyme\system\Format\JSONFormatter.php(41): CodeIgniter\Format\Exceptions\FormatException::forInvalidJSON('Type is not sup...')
#1 C:\xampp\htdocs\dfpyme\system\API\ResponseTrait.php(341): CodeIgniter\Format\JSONFormatter->format(Array)
#2 C:\xampp\htdocs\dfpyme\system\API\ResponseTrait.php(99): CodeIgniter\Debug\Exceptions->format(Array)
#3 C:\xampp\htdocs\dfpyme\system\Debug\Exceptions.php(115): CodeIgniter\Debug\Exceptions->respond(Array, 500)
#4 [internal function]: CodeIgniter\Debug\Exceptions->exceptionHandler(Object(ErrorException))
#5 {main}
  thrown
#0 [internal function]: CodeIgniter\Debug\Exceptions->shutdownHandler()
#1 {main}
ERROR - 2023-03-01 15:20:05 --> ErrorException: pg_query(): Query failed: ERROR:  no existe la columna «id_iva» en la relación «producto_factura_venta»
LINE 1: ...otal&quot;, &quot;valor_ico&quot;, &quot;impuesto_al_consumo&quot;, &quot;iva&quot;, &quot;id_iva&quot;, ...
                                                             ^ in C:\xampp\htdocs\dfpyme\system\Database\Postgre\Connection.php:135
Stack trace:
#0 [internal function]: CodeIgniter\Debug\Exceptions->errorHandler(2, 'pg_query(): Que...', 'C:\\xampp\\htdocs...', 135)
#1 C:\xampp\htdocs\dfpyme\system\Database\Postgre\Connection.php(135): pg_query(Resource id #158, 'INSERT INTO "pr...')
#2 C:\xampp\htdocs\dfpyme\system\Database\BaseConnection.php(670): CodeIgniter\Database\Postgre\Connection->execute('INSERT INTO "pr...')
#3 C:\xampp\htdocs\dfpyme\system\Database\BaseConnection.php(598): CodeIgniter\Database\BaseConnection->simpleQuery('INSERT INTO "pr...')
#4 C:\xampp\htdocs\dfpyme\system\Database\BaseBuilder.php(1771): CodeIgniter\Database\BaseConnection->query('INSERT INTO "pr...', Array, false)
#5 C:\xampp\htdocs\dfpyme\system\Model.php(239): CodeIgniter\Database\BaseBuilder->insert()
#6 C:\xampp\htdocs\dfpyme\system\BaseModel.php(738): CodeIgniter\Model->doInsert(Array)
#7 C:\xampp\htdocs\dfpyme\system\Model.php(625): CodeIgniter\BaseModel->insert(Array, true)
#8 C:\xampp\htdocs\dfpyme\app\Controllers\pedido\pedidoController.php(1593): CodeIgniter\Model->insert(Array)
#9 C:\xampp\htdocs\dfpyme\app\Controllers\pedido\pedidoController.php(1464): App\Controllers\pedido\pedidoController->facturacion_sin_impuestos_credito('2023-03-01 15:2...', '7600', 0, 0, 0, '98713702', '8', '2', 0)
#10 C:\xampp\htdocs\dfpyme\system\CodeIgniter.php(832): App\Controllers\pedido\pedidoController->facturar_credito()
#11 C:\xampp\htdocs\dfpyme\system\CodeIgniter.php(419): CodeIgniter\CodeIgniter->runController(Object(App\Controllers\pedido\pedidoController))
#12 C:\xampp\htdocs\dfpyme\system\CodeIgniter.php(326): CodeIgniter\CodeIgniter->handleRequest(NULL, Object(Config\Cache), false)
#13 C:\xampp\htdocs\dfpyme\index.php(37): CodeIgniter\CodeIgniter->run()
#14 {main}
CRITICAL - 2023-03-01 15:20:05 --> pg_query(): Query failed: ERROR:  no existe la columna «id_iva» en la relación «producto_factura_venta»
LINE 1: ...otal&quot;, &quot;valor_ico&quot;, &quot;impuesto_al_consumo&quot;, &quot;iva&quot;, &quot;id_iva&quot;, ...
                                                             ^
#0 [internal function]: CodeIgniter\Debug\Exceptions->errorHandler(2, 'pg_query(): Que...', 'C:\\xampp\\htdocs...', 135)
#1 C:\xampp\htdocs\dfpyme\system\Database\Postgre\Connection.php(135): pg_query(Resource id #158, 'INSERT INTO "pr...')
#2 C:\xampp\htdocs\dfpyme\system\Database\BaseConnection.php(670): CodeIgniter\Database\Postgre\Connection->execute('INSERT INTO "pr...')
#3 C:\xampp\htdocs\dfpyme\system\Database\BaseConnection.php(598): CodeIgniter\Database\BaseConnection->simpleQuery('INSERT INTO "pr...')
#4 C:\xampp\htdocs\dfpyme\system\Database\BaseBuilder.php(1771): CodeIgniter\Database\BaseConnection->query('INSERT INTO "pr...', Array, false)
#5 C:\xampp\htdocs\dfpyme\system\Model.php(239): CodeIgniter\Database\BaseBuilder->insert()
#6 C:\xampp\htdocs\dfpyme\system\BaseModel.php(738): CodeIgniter\Model->doInsert(Array)
#7 C:\xampp\htdocs\dfpyme\system\Model.php(625): CodeIgniter\BaseModel->insert(Array, true)
#8 C:\xampp\htdocs\dfpyme\app\Controllers\pedido\pedidoController.php(1593): CodeIgniter\Model->insert(Array)
#9 C:\xampp\htdocs\dfpyme\app\Controllers\pedido\pedidoController.php(1464): App\Controllers\pedido\pedidoController->facturacion_sin_impuestos_credito('2023-03-01 15:2...', '7600', 0, 0, 0, '98713702', '8', '2', 0)
#10 C:\xampp\htdocs\dfpyme\system\CodeIgniter.php(832): App\Controllers\pedido\pedidoController->facturar_credito()
#11 C:\xampp\htdocs\dfpyme\system\CodeIgniter.php(419): CodeIgniter\CodeIgniter->runController(Object(App\Controllers\pedido\pedidoController))
#12 C:\xampp\htdocs\dfpyme\system\CodeIgniter.php(326): CodeIgniter\CodeIgniter->handleRequest(NULL, Object(Config\Cache), false)
#13 C:\xampp\htdocs\dfpyme\index.php(37): CodeIgniter\CodeIgniter->run()
#14 {main}
CRITICAL - 2023-03-01 15:20:05 --> Uncaught CodeIgniter\Format\Exceptions\FormatException: Failed to parse json string, error: "Type is not supported". in C:\xampp\htdocs\dfpyme\system\Format\JSONFormatter.php:41
Stack trace:
#0 C:\xampp\htdocs\dfpyme\system\Format\JSONFormatter.php(41): CodeIgniter\Format\Exceptions\FormatException::forInvalidJSON('Type is not sup...')
#1 C:\xampp\htdocs\dfpyme\system\API\ResponseTrait.php(341): CodeIgniter\Format\JSONFormatter->format(Array)
#2 C:\xampp\htdocs\dfpyme\system\API\ResponseTrait.php(99): CodeIgniter\Debug\Exceptions->format(Array)
#3 C:\xampp\htdocs\dfpyme\system\Debug\Exceptions.php(115): CodeIgniter\Debug\Exceptions->respond(Array, 500)
#4 [internal function]: CodeIgniter\Debug\Exceptions->exceptionHandler(Object(ErrorException))
#5 {main}
  thrown
#0 [internal function]: CodeIgniter\Debug\Exceptions->shutdownHandler()
#1 {main}
ERROR - 2023-03-01 17:06:39 --> ErrorException: pg_query(): Query failed: server closed the connection unexpectedly
	This probably means the server terminated abnormally
	before or while processing the request. in C:\xampp\htdocs\dfpyme\system\Database\Postgre\Connection.php:135
Stack trace:
#0 [internal function]: CodeIgniter\Debug\Exceptions->errorHandler(2, 'pg_query(): Que...', 'C:\\xampp\\htdocs...', 135)
#1 C:\xampp\htdocs\dfpyme\system\Database\Postgre\Connection.php(135): pg_query(Resource id #158, 'UPDATE "inventa...')
#2 C:\xampp\htdocs\dfpyme\system\Database\BaseConnection.php(670): CodeIgniter\Database\Postgre\Connection->execute('UPDATE "inventa...')
#3 C:\xampp\htdocs\dfpyme\system\Database\BaseConnection.php(598): CodeIgniter\Database\BaseConnection->simpleQuery('UPDATE "inventa...')
#4 C:\xampp\htdocs\dfpyme\system\Database\BaseBuilder.php(1913): CodeIgniter\Database\BaseConnection->query('UPDATE "inventa...', Array, false)
#5 C:\xampp\htdocs\dfpyme\system\Model.php(298): CodeIgniter\Database\BaseBuilder->update()
#6 C:\xampp\htdocs\dfpyme\system\BaseModel.php(865): CodeIgniter\Model->doUpdate(NULL, Array)
#7 C:\xampp\htdocs\dfpyme\system\Model.php(651): CodeIgniter\BaseModel->update(NULL, Array)
#8 C:\xampp\htdocs\dfpyme\app\Controllers\factura_pos\facturaDirectaController.php(274): CodeIgniter\Model->update()
#9 C:\xampp\htdocs\dfpyme\app\Controllers\factura_pos\facturaDirectaController.php(83): App\Controllers\factura_pos\facturaDirectaController->facturacion_sin_impuestos('2023-03-01 17:0...', 0, '0', '200', '60', 22222222, 8, 1, '70')
#10 C:\xampp\htdocs\dfpyme\system\CodeIgniter.php(832): App\Controllers\factura_pos\facturaDirectaController->facturacion()
#11 C:\xampp\htdocs\dfpyme\system\CodeIgniter.php(419): CodeIgniter\CodeIgniter->runController(Object(App\Controllers\factura_pos\facturaDirectaController))
#12 C:\xampp\htdocs\dfpyme\system\CodeIgniter.php(326): CodeIgniter\CodeIgniter->handleRequest(NULL, Object(Config\Cache), false)
#13 C:\xampp\htdocs\dfpyme\index.php(37): CodeIgniter\CodeIgniter->run()
#14 {main}
CRITICAL - 2023-03-01 17:06:39 --> pg_query(): Query failed: server closed the connection unexpectedly
	This probably means the server terminated abnormally
	before or while processing the request.
#0 [internal function]: CodeIgniter\Debug\Exceptions->errorHandler(2, 'pg_query(): Que...', 'C:\\xampp\\htdocs...', 135)
#1 C:\xampp\htdocs\dfpyme\system\Database\Postgre\Connection.php(135): pg_query(Resource id #158, 'UPDATE "inventa...')
#2 C:\xampp\htdocs\dfpyme\system\Database\BaseConnection.php(670): CodeIgniter\Database\Postgre\Connection->execute('UPDATE "inventa...')
#3 C:\xampp\htdocs\dfpyme\system\Database\BaseConnection.php(598): CodeIgniter\Database\BaseConnection->simpleQuery('UPDATE "inventa...')
#4 C:\xampp\htdocs\dfpyme\system\Database\BaseBuilder.php(1913): CodeIgniter\Database\BaseConnection->query('UPDATE "inventa...', Array, false)
#5 C:\xampp\htdocs\dfpyme\system\Model.php(298): CodeIgniter\Database\BaseBuilder->update()
#6 C:\xampp\htdocs\dfpyme\system\BaseModel.php(865): CodeIgniter\Model->doUpdate(NULL, Array)
#7 C:\xampp\htdocs\dfpyme\system\Model.php(651): CodeIgniter\BaseModel->update(NULL, Array)
#8 C:\xampp\htdocs\dfpyme\app\Controllers\factura_pos\facturaDirectaController.php(274): CodeIgniter\Model->update()
#9 C:\xampp\htdocs\dfpyme\app\Controllers\factura_pos\facturaDirectaController.php(83): App\Controllers\factura_pos\facturaDirectaController->facturacion_sin_impuestos('2023-03-01 17:0...', 0, '0', '200', '60', 22222222, 8, 1, '70')
#10 C:\xampp\htdocs\dfpyme\system\CodeIgniter.php(832): App\Controllers\factura_pos\facturaDirectaController->facturacion()
#11 C:\xampp\htdocs\dfpyme\system\CodeIgniter.php(419): CodeIgniter\CodeIgniter->runController(Object(App\Controllers\factura_pos\facturaDirectaController))
#12 C:\xampp\htdocs\dfpyme\system\CodeIgniter.php(326): CodeIgniter\CodeIgniter->handleRequest(NULL, Object(Config\Cache), false)
#13 C:\xampp\htdocs\dfpyme\index.php(37): CodeIgniter\CodeIgniter->run()
#14 {main}
CRITICAL - 2023-03-01 17:06:39 --> Uncaught CodeIgniter\Format\Exceptions\FormatException: Failed to parse json string, error: "Type is not supported". in C:\xampp\htdocs\dfpyme\system\Format\JSONFormatter.php:41
Stack trace:
#0 C:\xampp\htdocs\dfpyme\system\Format\JSONFormatter.php(41): CodeIgniter\Format\Exceptions\FormatException::forInvalidJSON('Type is not sup...')
#1 C:\xampp\htdocs\dfpyme\system\API\ResponseTrait.php(341): CodeIgniter\Format\JSONFormatter->format(Array)
#2 C:\xampp\htdocs\dfpyme\system\API\ResponseTrait.php(99): CodeIgniter\Debug\Exceptions->format(Array)
#3 C:\xampp\htdocs\dfpyme\system\Debug\Exceptions.php(115): CodeIgniter\Debug\Exceptions->respond(Array, 500)
#4 [internal function]: CodeIgniter\Debug\Exceptions->exceptionHandler(Object(ErrorException))
#5 {main}
  thrown
#0 [internal function]: CodeIgniter\Debug\Exceptions->shutdownHandler()
#1 {main}
CRITICAL - 2023-03-01 17:07:43 --> Trying to access array offset on value of type null
#0 C:\xampp\htdocs\dfpyme\app\Controllers\pedido\pedidoController.php(1431): CodeIgniter\Debug\Exceptions->errorHandler(2, 'Trying to acces...', 'C:\\xampp\\htdocs...', 1431)
#1 C:\xampp\htdocs\dfpyme\system\CodeIgniter.php(832): App\Controllers\pedido\pedidoController->forma_pago()
#2 C:\xampp\htdocs\dfpyme\system\CodeIgniter.php(419): CodeIgniter\CodeIgniter->runController(Object(App\Controllers\pedido\pedidoController))
#3 C:\xampp\htdocs\dfpyme\system\CodeIgniter.php(326): CodeIgniter\CodeIgniter->handleRequest(NULL, Object(Config\Cache), false)
#4 C:\xampp\htdocs\dfpyme\index.php(37): CodeIgniter\CodeIgniter->run()
#5 {main}
CRITICAL - 2023-03-01 17:09:39 --> Trying to access array offset on value of type null
#0 C:\xampp\htdocs\dfpyme\app\Controllers\pedido\pedidoController.php(1431): CodeIgniter\Debug\Exceptions->errorHandler(2, 'Trying to acces...', 'C:\\xampp\\htdocs...', 1431)
#1 C:\xampp\htdocs\dfpyme\system\CodeIgniter.php(832): App\Controllers\pedido\pedidoController->forma_pago()
#2 C:\xampp\htdocs\dfpyme\system\CodeIgniter.php(419): CodeIgniter\CodeIgniter->runController(Object(App\Controllers\pedido\pedidoController))
#3 C:\xampp\htdocs\dfpyme\system\CodeIgniter.php(326): CodeIgniter\CodeIgniter->handleRequest(NULL, Object(Config\Cache), false)
#4 C:\xampp\htdocs\dfpyme\index.php(37): CodeIgniter\CodeIgniter->run()
#5 {main}
CRITICAL - 2023-03-01 17:14:31 --> Undefined array key "nit_cliente"
#0 C:\xampp\htdocs\dfpyme\app\Controllers\pedido\pedidoController.php(1429): CodeIgniter\Debug\Exceptions->errorHandler(2, 'Undefined array...', 'C:\\xampp\\htdocs...', 1429)
#1 C:\xampp\htdocs\dfpyme\system\CodeIgniter.php(832): App\Controllers\pedido\pedidoController->forma_pago()
#2 C:\xampp\htdocs\dfpyme\system\CodeIgniter.php(419): CodeIgniter\CodeIgniter->runController(Object(App\Controllers\pedido\pedidoController))
#3 C:\xampp\htdocs\dfpyme\system\CodeIgniter.php(326): CodeIgniter\CodeIgniter->handleRequest(NULL, Object(Config\Cache), false)
#4 C:\xampp\htdocs\dfpyme\index.php(37): CodeIgniter\CodeIgniter->run()
#5 {main}
CRITICAL - 2023-03-01 17:16:44 --> Trying to access array offset on value of type null
#0 C:\xampp\htdocs\dfpyme\app\Controllers\pedido\pedidoController.php(1434): CodeIgniter\Debug\Exceptions->errorHandler(2, 'Trying to acces...', 'C:\\xampp\\htdocs...', 1434)
#1 C:\xampp\htdocs\dfpyme\system\CodeIgniter.php(832): App\Controllers\pedido\pedidoController->forma_pago()
#2 C:\xampp\htdocs\dfpyme\system\CodeIgniter.php(419): CodeIgniter\CodeIgniter->runController(Object(App\Controllers\pedido\pedidoController))
#3 C:\xampp\htdocs\dfpyme\system\CodeIgniter.php(326): CodeIgniter\CodeIgniter->handleRequest(NULL, Object(Config\Cache), false)
#4 C:\xampp\htdocs\dfpyme\index.php(37): CodeIgniter\CodeIgniter->run()
#5 {main}
CRITICAL - 2023-03-01 17:19:07 --> number_format(): Argument #1 ($num) must be of type float, string given
#0 C:\xampp\htdocs\dfpyme\app\Controllers\cliente\clienteController.php(109): number_format('4351542-0', 0, ',', '.')
#1 C:\xampp\htdocs\dfpyme\system\CodeIgniter.php(832): App\Controllers\cliente\ClienteController->clientes_autocompletado()
#2 C:\xampp\htdocs\dfpyme\system\CodeIgniter.php(419): CodeIgniter\CodeIgniter->runController(Object(App\Controllers\cliente\ClienteController))
#3 C:\xampp\htdocs\dfpyme\system\CodeIgniter.php(326): CodeIgniter\CodeIgniter->handleRequest(NULL, Object(Config\Cache), false)
#4 C:\xampp\htdocs\dfpyme\index.php(37): CodeIgniter\CodeIgniter->run()
#5 {main}
CRITICAL - 2023-03-01 17:19:07 --> Uncaught CodeIgniter\Format\Exceptions\FormatException: Failed to parse json string, error: "Type is not supported". in C:\xampp\htdocs\dfpyme\system\Format\JSONFormatter.php:41
Stack trace:
#0 C:\xampp\htdocs\dfpyme\system\Format\JSONFormatter.php(41): CodeIgniter\Format\Exceptions\FormatException::forInvalidJSON('Type is not sup...')
#1 C:\xampp\htdocs\dfpyme\system\API\ResponseTrait.php(341): CodeIgniter\Format\JSONFormatter->format(Array)
#2 C:\xampp\htdocs\dfpyme\system\API\ResponseTrait.php(99): CodeIgniter\Debug\Exceptions->format(Array)
#3 C:\xampp\htdocs\dfpyme\system\Debug\Exceptions.php(115): CodeIgniter\Debug\Exceptions->respond(Array, 500)
#4 [internal function]: CodeIgniter\Debug\Exceptions->exceptionHandler(Object(TypeError))
#5 {main}
  thrown
#0 [internal function]: CodeIgniter\Debug\Exceptions->shutdownHandler()
#1 {main}
ERROR - 2023-03-01 17:19:38 --> ErrorException: pg_query(): Query failed: ERROR:  no existe la columna «id_iva» en la relación «producto_factura_venta»
LINE 1: ...otal&quot;, &quot;valor_ico&quot;, &quot;impuesto_al_consumo&quot;, &quot;iva&quot;, &quot;id_iva&quot;, ...
                                                             ^ in C:\xampp\htdocs\dfpyme\system\Database\Postgre\Connection.php:135
Stack trace:
#0 [internal function]: CodeIgniter\Debug\Exceptions->errorHandler(2, 'pg_query(): Que...', 'C:\\xampp\\htdocs...', 135)
#1 C:\xampp\htdocs\dfpyme\system\Database\Postgre\Connection.php(135): pg_query(Resource id #158, 'INSERT INTO "pr...')
#2 C:\xampp\htdocs\dfpyme\system\Database\BaseConnection.php(670): CodeIgniter\Database\Postgre\Connection->execute('INSERT INTO "pr...')
#3 C:\xampp\htdocs\dfpyme\system\Database\BaseConnection.php(598): CodeIgniter\Database\BaseConnection->simpleQuery('INSERT INTO "pr...')
#4 C:\xampp\htdocs\dfpyme\system\Database\BaseBuilder.php(1771): CodeIgniter\Database\BaseConnection->query('INSERT INTO "pr...', Array, false)
#5 C:\xampp\htdocs\dfpyme\system\Model.php(239): CodeIgniter\Database\BaseBuilder->insert()
#6 C:\xampp\htdocs\dfpyme\system\BaseModel.php(738): CodeIgniter\Model->doInsert(Array)
#7 C:\xampp\htdocs\dfpyme\system\Model.php(625): CodeIgniter\BaseModel->insert(Array, true)
#8 C:\xampp\htdocs\dfpyme\app\Controllers\pedido\pedidoController.php(1593): CodeIgniter\Model->insert(Array)
#9 C:\xampp\htdocs\dfpyme\app\Controllers\pedido\pedidoController.php(1464): App\Controllers\pedido\pedidoController->facturacion_sin_impuestos_credito('2023-03-01 17:1...', '2500', 0, 0, 0, '254654541', '8', '2', 0)
#10 C:\xampp\htdocs\dfpyme\system\CodeIgniter.php(832): App\Controllers\pedido\pedidoController->facturar_credito()
#11 C:\xampp\htdocs\dfpyme\system\CodeIgniter.php(419): CodeIgniter\CodeIgniter->runController(Object(App\Controllers\pedido\pedidoController))
#12 C:\xampp\htdocs\dfpyme\system\CodeIgniter.php(326): CodeIgniter\CodeIgniter->handleRequest(NULL, Object(Config\Cache), false)
#13 C:\xampp\htdocs\dfpyme\index.php(37): CodeIgniter\CodeIgniter->run()
#14 {main}
CRITICAL - 2023-03-01 17:19:38 --> pg_query(): Query failed: ERROR:  no existe la columna «id_iva» en la relación «producto_factura_venta»
LINE 1: ...otal&quot;, &quot;valor_ico&quot;, &quot;impuesto_al_consumo&quot;, &quot;iva&quot;, &quot;id_iva&quot;, ...
                                                             ^
#0 [internal function]: CodeIgniter\Debug\Exceptions->errorHandler(2, 'pg_query(): Que...', 'C:\\xampp\\htdocs...', 135)
#1 C:\xampp\htdocs\dfpyme\system\Database\Postgre\Connection.php(135): pg_query(Resource id #158, 'INSERT INTO "pr...')
#2 C:\xampp\htdocs\dfpyme\system\Database\BaseConnection.php(670): CodeIgniter\Database\Postgre\Connection->execute('INSERT INTO "pr...')
#3 C:\xampp\htdocs\dfpyme\system\Database\BaseConnection.php(598): CodeIgniter\Database\BaseConnection->simpleQuery('INSERT INTO "pr...')
#4 C:\xampp\htdocs\dfpyme\system\Database\BaseBuilder.php(1771): CodeIgniter\Database\BaseConnection->query('INSERT INTO "pr...', Array, false)
#5 C:\xampp\htdocs\dfpyme\system\Model.php(239): CodeIgniter\Database\BaseBuilder->insert()
#6 C:\xampp\htdocs\dfpyme\system\BaseModel.php(738): CodeIgniter\Model->doInsert(Array)
#7 C:\xampp\htdocs\dfpyme\system\Model.php(625): CodeIgniter\BaseModel->insert(Array, true)
#8 C:\xampp\htdocs\dfpyme\app\Controllers\pedido\pedidoController.php(1593): CodeIgniter\Model->insert(Array)
#9 C:\xampp\htdocs\dfpyme\app\Controllers\pedido\pedidoController.php(1464): App\Controllers\pedido\pedidoController->facturacion_sin_impuestos_credito('2023-03-01 17:1...', '2500', 0, 0, 0, '254654541', '8', '2', 0)
#10 C:\xampp\htdocs\dfpyme\system\CodeIgniter.php(832): App\Controllers\pedido\pedidoController->facturar_credito()
#11 C:\xampp\htdocs\dfpyme\system\CodeIgniter.php(419): CodeIgniter\CodeIgniter->runController(Object(App\Controllers\pedido\pedidoController))
#12 C:\xampp\htdocs\dfpyme\system\CodeIgniter.php(326): CodeIgniter\CodeIgniter->handleRequest(NULL, Object(Config\Cache), false)
#13 C:\xampp\htdocs\dfpyme\index.php(37): CodeIgniter\CodeIgniter->run()
#14 {main}
CRITICAL - 2023-03-01 17:19:38 --> Uncaught CodeIgniter\Format\Exceptions\FormatException: Failed to parse json string, error: "Type is not supported". in C:\xampp\htdocs\dfpyme\system\Format\JSONFormatter.php:41
Stack trace:
#0 C:\xampp\htdocs\dfpyme\system\Format\JSONFormatter.php(41): CodeIgniter\Format\Exceptions\FormatException::forInvalidJSON('Type is not sup...')
#1 C:\xampp\htdocs\dfpyme\system\API\ResponseTrait.php(341): CodeIgniter\Format\JSONFormatter->format(Array)
#2 C:\xampp\htdocs\dfpyme\system\API\ResponseTrait.php(99): CodeIgniter\Debug\Exceptions->format(Array)
#3 C:\xampp\htdocs\dfpyme\system\Debug\Exceptions.php(115): CodeIgniter\Debug\Exceptions->respond(Array, 500)
#4 [internal function]: CodeIgniter\Debug\Exceptions->exceptionHandler(Object(ErrorException))
#5 {main}
  thrown
#0 [internal function]: CodeIgniter\Debug\Exceptions->shutdownHandler()
#1 {main}
CRITICAL - 2023-03-01 17:42:21 --> Unsupported operand types: string + string
#0 C:\xampp\htdocs\dfpyme\system\CodeIgniter.php(832): App\Controllers\producto\productoController->actualizar_entregar_producto()
#1 C:\xampp\htdocs\dfpyme\system\CodeIgniter.php(419): CodeIgniter\CodeIgniter->runController(Object(App\Controllers\producto\productoController))
#2 C:\xampp\htdocs\dfpyme\system\CodeIgniter.php(326): CodeIgniter\CodeIgniter->handleRequest(NULL, Object(Config\Cache), false)
#3 C:\xampp\htdocs\dfpyme\index.php(37): CodeIgniter\CodeIgniter->run()
#4 {main}
CRITICAL - 2023-03-01 17:42:21 --> Uncaught CodeIgniter\Format\Exceptions\FormatException: Failed to parse json string, error: "Type is not supported". in C:\xampp\htdocs\dfpyme\system\Format\JSONFormatter.php:41
Stack trace:
#0 C:\xampp\htdocs\dfpyme\system\Format\JSONFormatter.php(41): CodeIgniter\Format\Exceptions\FormatException::forInvalidJSON('Type is not sup...')
#1 C:\xampp\htdocs\dfpyme\system\API\ResponseTrait.php(341): CodeIgniter\Format\JSONFormatter->format(Array)
#2 C:\xampp\htdocs\dfpyme\system\API\ResponseTrait.php(99): CodeIgniter\Debug\Exceptions->format(Array)
#3 C:\xampp\htdocs\dfpyme\system\Debug\Exceptions.php(115): CodeIgniter\Debug\Exceptions->respond(Array, 500)
#4 [internal function]: CodeIgniter\Debug\Exceptions->exceptionHandler(Object(TypeError))
#5 {main}
  thrown
#0 [internal function]: CodeIgniter\Debug\Exceptions->shutdownHandler()
#1 {main}
CRITICAL - 2023-03-01 17:42:23 --> Unsupported operand types: string + string
#0 C:\xampp\htdocs\dfpyme\system\CodeIgniter.php(832): App\Controllers\producto\productoController->actualizar_entregar_producto()
#1 C:\xampp\htdocs\dfpyme\system\CodeIgniter.php(419): CodeIgniter\CodeIgniter->runController(Object(App\Controllers\producto\productoController))
#2 C:\xampp\htdocs\dfpyme\system\CodeIgniter.php(326): CodeIgniter\CodeIgniter->handleRequest(NULL, Object(Config\Cache), false)
#3 C:\xampp\htdocs\dfpyme\index.php(37): CodeIgniter\CodeIgniter->run()
#4 {main}
CRITICAL - 2023-03-01 17:42:23 --> Uncaught CodeIgniter\Format\Exceptions\FormatException: Failed to parse json string, error: "Type is not supported". in C:\xampp\htdocs\dfpyme\system\Format\JSONFormatter.php:41
Stack trace:
#0 C:\xampp\htdocs\dfpyme\system\Format\JSONFormatter.php(41): CodeIgniter\Format\Exceptions\FormatException::forInvalidJSON('Type is not sup...')
#1 C:\xampp\htdocs\dfpyme\system\API\ResponseTrait.php(341): CodeIgniter\Format\JSONFormatter->format(Array)
#2 C:\xampp\htdocs\dfpyme\system\API\ResponseTrait.php(99): CodeIgniter\Debug\Exceptions->format(Array)
#3 C:\xampp\htdocs\dfpyme\system\Debug\Exceptions.php(115): CodeIgniter\Debug\Exceptions->respond(Array, 500)
#4 [internal function]: CodeIgniter\Debug\Exceptions->exceptionHandler(Object(TypeError))
#5 {main}
  thrown
#0 [internal function]: CodeIgniter\Debug\Exceptions->shutdownHandler()
#1 {main}
CRITICAL - 2023-03-01 17:59:36 --> number_format(): Argument #1 ($num) must be of type float, string given
#0 C:\xampp\htdocs\dfpyme\app\Controllers\cliente\clienteController.php(109): number_format('4351542-0', 0, ',', '.')
#1 C:\xampp\htdocs\dfpyme\system\CodeIgniter.php(832): App\Controllers\cliente\ClienteController->clientes_autocompletado()
#2 C:\xampp\htdocs\dfpyme\system\CodeIgniter.php(419): CodeIgniter\CodeIgniter->runController(Object(App\Controllers\cliente\ClienteController))
#3 C:\xampp\htdocs\dfpyme\system\CodeIgniter.php(326): CodeIgniter\CodeIgniter->handleRequest(NULL, Object(Config\Cache), false)
#4 C:\xampp\htdocs\dfpyme\index.php(37): CodeIgniter\CodeIgniter->run()
#5 {main}
CRITICAL - 2023-03-01 17:59:36 --> Uncaught CodeIgniter\Format\Exceptions\FormatException: Failed to parse json string, error: "Type is not supported". in C:\xampp\htdocs\dfpyme\system\Format\JSONFormatter.php:41
Stack trace:
#0 C:\xampp\htdocs\dfpyme\system\Format\JSONFormatter.php(41): CodeIgniter\Format\Exceptions\FormatException::forInvalidJSON('Type is not sup...')
#1 C:\xampp\htdocs\dfpyme\system\API\ResponseTrait.php(341): CodeIgniter\Format\JSONFormatter->format(Array)
#2 C:\xampp\htdocs\dfpyme\system\API\ResponseTrait.php(99): CodeIgniter\Debug\Exceptions->format(Array)
#3 C:\xampp\htdocs\dfpyme\system\Debug\Exceptions.php(115): CodeIgniter\Debug\Exceptions->respond(Array, 500)
#4 [internal function]: CodeIgniter\Debug\Exceptions->exceptionHandler(Object(TypeError))
#5 {main}
  thrown
#0 [internal function]: CodeIgniter\Debug\Exceptions->shutdownHandler()
#1 {main}
CRITICAL - 2023-03-01 18:19:28 --> Undefined variable $pedido
#0 C:\xampp\htdocs\dfpyme\app\Views\productos_pedido\productos_pedido.php(106): CodeIgniter\Debug\Exceptions->errorHandler(2, 'Undefined varia...', 'C:\\xampp\\htdocs...', 106)
#1 C:\xampp\htdocs\dfpyme\system\View\View.php(210): include('C:\\xampp\\htdocs...')
#2 C:\xampp\htdocs\dfpyme\system\View\View.php(213): CodeIgniter\View\View->CodeIgniter\View\{closure}()
#3 C:\xampp\htdocs\dfpyme\system\Common.php(1089): CodeIgniter\View\View->render('productos_pedid...', Array, true)
#4 C:\xampp\htdocs\dfpyme\app\Controllers\producto\productoController.php(836): view('productos_pedid...', Array)
#5 C:\xampp\htdocs\dfpyme\system\CodeIgniter.php(832): App\Controllers\producto\productoController->actualizar_entregar_producto()
#6 C:\xampp\htdocs\dfpyme\system\CodeIgniter.php(419): CodeIgniter\CodeIgniter->runController(Object(App\Controllers\producto\productoController))
#7 C:\xampp\htdocs\dfpyme\system\CodeIgniter.php(326): CodeIgniter\CodeIgniter->handleRequest(NULL, Object(Config\Cache), false)
#8 C:\xampp\htdocs\dfpyme\index.php(37): CodeIgniter\CodeIgniter->run()
#9 {main}
CRITICAL - 2023-03-01 18:19:28 --> Uncaught CodeIgniter\Format\Exceptions\FormatException: Failed to parse json string, error: "Type is not supported". in C:\xampp\htdocs\dfpyme\system\Format\JSONFormatter.php:41
Stack trace:
#0 C:\xampp\htdocs\dfpyme\system\Format\JSONFormatter.php(41): CodeIgniter\Format\Exceptions\FormatException::forInvalidJSON('Type is not sup...')
#1 C:\xampp\htdocs\dfpyme\system\API\ResponseTrait.php(341): CodeIgniter\Format\JSONFormatter->format(Array)
#2 C:\xampp\htdocs\dfpyme\system\API\ResponseTrait.php(99): CodeIgniter\Debug\Exceptions->format(Array)
#3 C:\xampp\htdocs\dfpyme\system\Debug\Exceptions.php(115): CodeIgniter\Debug\Exceptions->respond(Array, 500)
#4 [internal function]: CodeIgniter\Debug\Exceptions->exceptionHandler(Object(ErrorException))
#5 {main}
  thrown
#0 [internal function]: CodeIgniter\Debug\Exceptions->shutdownHandler()
#1 {main}
CRITICAL - 2023-03-01 18:21:40 --> Undefined array key "id_producto_pedido"
#0 C:\xampp\htdocs\dfpyme\app\Controllers\producto\productoController.php(768): CodeIgniter\Debug\Exceptions->errorHandler(2, 'Undefined array...', 'C:\\xampp\\htdocs...', 768)
#1 C:\xampp\htdocs\dfpyme\system\CodeIgniter.php(832): App\Controllers\producto\productoController->entregar_producto()
#2 C:\xampp\htdocs\dfpyme\system\CodeIgniter.php(419): CodeIgniter\CodeIgniter->runController(Object(App\Controllers\producto\productoController))
#3 C:\xampp\htdocs\dfpyme\system\CodeIgniter.php(326): CodeIgniter\CodeIgniter->handleRequest(NULL, Object(Config\Cache), false)
#4 C:\xampp\htdocs\dfpyme\index.php(37): CodeIgniter\CodeIgniter->run()
#5 {main}
CRITICAL - 2023-03-01 18:22:07 --> Undefined array key "id_producto_pedido"
#0 C:\xampp\htdocs\dfpyme\app\Controllers\producto\productoController.php(768): CodeIgniter\Debug\Exceptions->errorHandler(2, 'Undefined array...', 'C:\\xampp\\htdocs...', 768)
#1 C:\xampp\htdocs\dfpyme\system\CodeIgniter.php(832): App\Controllers\producto\productoController->entregar_producto()
#2 C:\xampp\htdocs\dfpyme\system\CodeIgniter.php(419): CodeIgniter\CodeIgniter->runController(Object(App\Controllers\producto\productoController))
#3 C:\xampp\htdocs\dfpyme\system\CodeIgniter.php(326): CodeIgniter\CodeIgniter->handleRequest(NULL, Object(Config\Cache), false)
#4 C:\xampp\htdocs\dfpyme\index.php(37): CodeIgniter\CodeIgniter->run()
#5 {main}
CRITICAL - 2023-03-01 18:22:09 --> Undefined array key "id_producto_pedido"
#0 C:\xampp\htdocs\dfpyme\app\Controllers\producto\productoController.php(768): CodeIgniter\Debug\Exceptions->errorHandler(2, 'Undefined array...', 'C:\\xampp\\htdocs...', 768)
#1 C:\xampp\htdocs\dfpyme\system\CodeIgniter.php(832): App\Controllers\producto\productoController->entregar_producto()
#2 C:\xampp\htdocs\dfpyme\system\CodeIgniter.php(419): CodeIgniter\CodeIgniter->runController(Object(App\Controllers\producto\productoController))
#3 C:\xampp\htdocs\dfpyme\system\CodeIgniter.php(326): CodeIgniter\CodeIgniter->handleRequest(NULL, Object(Config\Cache), false)
#4 C:\xampp\htdocs\dfpyme\index.php(37): CodeIgniter\CodeIgniter->run()
#5 {main}
ERROR - 2023-03-01 18:24:37 --> ErrorException: pg_query(): Query failed: ERROR:  la sintaxis de entrada no es válida para integer: «»
LINE 3: WHERE &quot;fk_mesa&quot; = ''
                          ^ in C:\xampp\htdocs\dfpyme\system\Database\Postgre\Connection.php:135
Stack trace:
#0 [internal function]: CodeIgniter\Debug\Exceptions->errorHandler(2, 'pg_query(): Que...', 'C:\\xampp\\htdocs...', 135)
#1 C:\xampp\htdocs\dfpyme\system\Database\Postgre\Connection.php(135): pg_query(Resource id #157, 'SELECT "id"\nFRO...')
#2 C:\xampp\htdocs\dfpyme\system\Database\BaseConnection.php(670): CodeIgniter\Database\Postgre\Connection->execute('SELECT "id"\nFRO...')
#3 C:\xampp\htdocs\dfpyme\system\Database\BaseConnection.php(598): CodeIgniter\Database\BaseConnection->simpleQuery('SELECT "id"\nFRO...')
#4 C:\xampp\htdocs\dfpyme\system\Database\BaseBuilder.php(1455): CodeIgniter\Database\BaseConnection->query('SELECT "id"\nFRO...', Array, false)
#5 C:\xampp\htdocs\dfpyme\system\Model.php(210): CodeIgniter\Database\BaseBuilder->get()
#6 C:\xampp\htdocs\dfpyme\system\BaseModel.php(622): CodeIgniter\Model->doFirst()
#7 C:\xampp\htdocs\dfpyme\app\Controllers\producto\productoController.php(202): CodeIgniter\BaseModel->first()
#8 C:\xampp\htdocs\dfpyme\system\CodeIgniter.php(832): App\Controllers\producto\productoController->insertar_productos_tabla_pedido()
#9 C:\xampp\htdocs\dfpyme\system\CodeIgniter.php(419): CodeIgniter\CodeIgniter->runController(Object(App\Controllers\producto\productoController))
#10 C:\xampp\htdocs\dfpyme\system\CodeIgniter.php(326): CodeIgniter\CodeIgniter->handleRequest(NULL, Object(Config\Cache), false)
#11 C:\xampp\htdocs\dfpyme\index.php(37): CodeIgniter\CodeIgniter->run()
#12 {main}
CRITICAL - 2023-03-01 18:24:37 --> pg_query(): Query failed: ERROR:  la sintaxis de entrada no es válida para integer: «»
LINE 3: WHERE &quot;fk_mesa&quot; = ''
                          ^
#0 [internal function]: CodeIgniter\Debug\Exceptions->errorHandler(2, 'pg_query(): Que...', 'C:\\xampp\\htdocs...', 135)
#1 C:\xampp\htdocs\dfpyme\system\Database\Postgre\Connection.php(135): pg_query(Resource id #157, 'SELECT "id"\nFRO...')
#2 C:\xampp\htdocs\dfpyme\system\Database\BaseConnection.php(670): CodeIgniter\Database\Postgre\Connection->execute('SELECT "id"\nFRO...')
#3 C:\xampp\htdocs\dfpyme\system\Database\BaseConnection.php(598): CodeIgniter\Database\BaseConnection->simpleQuery('SELECT "id"\nFRO...')
#4 C:\xampp\htdocs\dfpyme\system\Database\BaseBuilder.php(1455): CodeIgniter\Database\BaseConnection->query('SELECT "id"\nFRO...', Array, false)
#5 C:\xampp\htdocs\dfpyme\system\Model.php(210): CodeIgniter\Database\BaseBuilder->get()
#6 C:\xampp\htdocs\dfpyme\system\BaseModel.php(622): CodeIgniter\Model->doFirst()
#7 C:\xampp\htdocs\dfpyme\app\Controllers\producto\productoController.php(202): CodeIgniter\BaseModel->first()
#8 C:\xampp\htdocs\dfpyme\system\CodeIgniter.php(832): App\Controllers\producto\productoController->insertar_productos_tabla_pedido()
#9 C:\xampp\htdocs\dfpyme\system\CodeIgniter.php(419): CodeIgniter\CodeIgniter->runController(Object(App\Controllers\producto\productoController))
#10 C:\xampp\htdocs\dfpyme\system\CodeIgniter.php(326): CodeIgniter\CodeIgniter->handleRequest(NULL, Object(Config\Cache), false)
#11 C:\xampp\htdocs\dfpyme\index.php(37): CodeIgniter\CodeIgniter->run()
#12 {main}
CRITICAL - 2023-03-01 18:24:37 --> Uncaught CodeIgniter\Format\Exceptions\FormatException: Failed to parse json string, error: "Type is not supported". in C:\xampp\htdocs\dfpyme\system\Format\JSONFormatter.php:41
Stack trace:
#0 C:\xampp\htdocs\dfpyme\system\Format\JSONFormatter.php(41): CodeIgniter\Format\Exceptions\FormatException::forInvalidJSON('Type is not sup...')
#1 C:\xampp\htdocs\dfpyme\system\API\ResponseTrait.php(341): CodeIgniter\Format\JSONFormatter->format(Array)
#2 C:\xampp\htdocs\dfpyme\system\API\ResponseTrait.php(99): CodeIgniter\Debug\Exceptions->format(Array)
#3 C:\xampp\htdocs\dfpyme\system\Debug\Exceptions.php(115): CodeIgniter\Debug\Exceptions->respond(Array, 500)
#4 [internal function]: CodeIgniter\Debug\Exceptions->exceptionHandler(Object(ErrorException))
#5 {main}
  thrown
#0 [internal function]: CodeIgniter\Debug\Exceptions->shutdownHandler()
#1 {main}
CRITICAL - 2023-03-01 18:28:21 --> Undefined variable $pedido
#0 C:\xampp\htdocs\dfpyme\app\Views\productos_pedido\productos_pedido.php(106): CodeIgniter\Debug\Exceptions->errorHandler(2, 'Undefined varia...', 'C:\\xampp\\htdocs...', 106)
#1 C:\xampp\htdocs\dfpyme\system\View\View.php(210): include('C:\\xampp\\htdocs...')
#2 C:\xampp\htdocs\dfpyme\system\View\View.php(213): CodeIgniter\View\View->CodeIgniter\View\{closure}()
#3 C:\xampp\htdocs\dfpyme\system\Common.php(1089): CodeIgniter\View\View->render('productos_pedid...', Array, true)
#4 C:\xampp\htdocs\dfpyme\app\Controllers\producto\productoController.php(836): view('productos_pedid...', Array)
#5 C:\xampp\htdocs\dfpyme\system\CodeIgniter.php(832): App\Controllers\producto\productoController->actualizar_entregar_producto()
#6 C:\xampp\htdocs\dfpyme\system\CodeIgniter.php(419): CodeIgniter\CodeIgniter->runController(Object(App\Controllers\producto\productoController))
#7 C:\xampp\htdocs\dfpyme\system\CodeIgniter.php(326): CodeIgniter\CodeIgniter->handleRequest(NULL, Object(Config\Cache), false)
#8 C:\xampp\htdocs\dfpyme\index.php(37): CodeIgniter\CodeIgniter->run()
#9 {main}
CRITICAL - 2023-03-01 18:28:21 --> Uncaught CodeIgniter\Format\Exceptions\FormatException: Failed to parse json string, error: "Type is not supported". in C:\xampp\htdocs\dfpyme\system\Format\JSONFormatter.php:41
Stack trace:
#0 C:\xampp\htdocs\dfpyme\system\Format\JSONFormatter.php(41): CodeIgniter\Format\Exceptions\FormatException::forInvalidJSON('Type is not sup...')
#1 C:\xampp\htdocs\dfpyme\system\API\ResponseTrait.php(341): CodeIgniter\Format\JSONFormatter->format(Array)
#2 C:\xampp\htdocs\dfpyme\system\API\ResponseTrait.php(99): CodeIgniter\Debug\Exceptions->format(Array)
#3 C:\xampp\htdocs\dfpyme\system\Debug\Exceptions.php(115): CodeIgniter\Debug\Exceptions->respond(Array, 500)
#4 [internal function]: CodeIgniter\Debug\Exceptions->exceptionHandler(Object(ErrorException))
#5 {main}
  thrown
#0 [internal function]: CodeIgniter\Debug\Exceptions->shutdownHandler()
#1 {main}
CRITICAL - 2023-03-01 18:33:46 --> Undefined variable $pedido
#0 C:\xampp\htdocs\dfpyme\app\Views\productos_pedido\productos_pedido.php(106): CodeIgniter\Debug\Exceptions->errorHandler(2, 'Undefined varia...', 'C:\\xampp\\htdocs...', 106)
#1 C:\xampp\htdocs\dfpyme\system\View\View.php(210): include('C:\\xampp\\htdocs...')
#2 C:\xampp\htdocs\dfpyme\system\View\View.php(213): CodeIgniter\View\View->CodeIgniter\View\{closure}()
#3 C:\xampp\htdocs\dfpyme\system\Common.php(1089): CodeIgniter\View\View->render('productos_pedid...', Array, true)
#4 C:\xampp\htdocs\dfpyme\app\Controllers\producto\productoController.php(837): view('productos_pedid...', Array)
#5 C:\xampp\htdocs\dfpyme\system\CodeIgniter.php(832): App\Controllers\producto\productoController->actualizar_entregar_producto()
#6 C:\xampp\htdocs\dfpyme\system\CodeIgniter.php(419): CodeIgniter\CodeIgniter->runController(Object(App\Controllers\producto\productoController))
#7 C:\xampp\htdocs\dfpyme\system\CodeIgniter.php(326): CodeIgniter\CodeIgniter->handleRequest(NULL, Object(Config\Cache), false)
#8 C:\xampp\htdocs\dfpyme\index.php(37): CodeIgniter\CodeIgniter->run()
#9 {main}
CRITICAL - 2023-03-01 18:33:46 --> Uncaught CodeIgniter\Format\Exceptions\FormatException: Failed to parse json string, error: "Type is not supported". in C:\xampp\htdocs\dfpyme\system\Format\JSONFormatter.php:41
Stack trace:
#0 C:\xampp\htdocs\dfpyme\system\Format\JSONFormatter.php(41): CodeIgniter\Format\Exceptions\FormatException::forInvalidJSON('Type is not sup...')
#1 C:\xampp\htdocs\dfpyme\system\API\ResponseTrait.php(341): CodeIgniter\Format\JSONFormatter->format(Array)
#2 C:\xampp\htdocs\dfpyme\system\API\ResponseTrait.php(99): CodeIgniter\Debug\Exceptions->format(Array)
#3 C:\xampp\htdocs\dfpyme\system\Debug\Exceptions.php(115): CodeIgniter\Debug\Exceptions->respond(Array, 500)
#4 [internal function]: CodeIgniter\Debug\Exceptions->exceptionHandler(Object(ErrorException))
#5 {main}
  thrown
#0 [internal function]: CodeIgniter\Debug\Exceptions->shutdownHandler()
#1 {main}
ERROR - 2023-03-01 18:49:44 --> ErrorException: pg_query(): Query failed: ERROR:  la sintaxis de entrada no es válida para integer: «»
LINE 3: WHERE &quot;fk_mesa&quot; = ''
                          ^ in C:\xampp\htdocs\dfpyme\system\Database\Postgre\Connection.php:135
Stack trace:
#0 [internal function]: CodeIgniter\Debug\Exceptions->errorHandler(2, 'pg_query(): Que...', 'C:\\xampp\\htdocs...', 135)
#1 C:\xampp\htdocs\dfpyme\system\Database\Postgre\Connection.php(135): pg_query(Resource id #157, 'SELECT "id"\nFRO...')
#2 C:\xampp\htdocs\dfpyme\system\Database\BaseConnection.php(670): CodeIgniter\Database\Postgre\Connection->execute('SELECT "id"\nFRO...')
#3 C:\xampp\htdocs\dfpyme\system\Database\BaseConnection.php(598): CodeIgniter\Database\BaseConnection->simpleQuery('SELECT "id"\nFRO...')
#4 C:\xampp\htdocs\dfpyme\system\Database\BaseBuilder.php(1455): CodeIgniter\Database\BaseConnection->query('SELECT "id"\nFRO...', Array, false)
#5 C:\xampp\htdocs\dfpyme\system\Model.php(210): CodeIgniter\Database\BaseBuilder->get()
#6 C:\xampp\htdocs\dfpyme\system\BaseModel.php(622): CodeIgniter\Model->doFirst()
#7 C:\xampp\htdocs\dfpyme\app\Controllers\producto\productoController.php(202): CodeIgniter\BaseModel->first()
#8 C:\xampp\htdocs\dfpyme\system\CodeIgniter.php(832): App\Controllers\producto\productoController->insertar_productos_tabla_pedido()
#9 C:\xampp\htdocs\dfpyme\system\CodeIgniter.php(419): CodeIgniter\CodeIgniter->runController(Object(App\Controllers\producto\productoController))
#10 C:\xampp\htdocs\dfpyme\system\CodeIgniter.php(326): CodeIgniter\CodeIgniter->handleRequest(NULL, Object(Config\Cache), false)
#11 C:\xampp\htdocs\dfpyme\index.php(37): CodeIgniter\CodeIgniter->run()
#12 {main}
CRITICAL - 2023-03-01 18:49:44 --> pg_query(): Query failed: ERROR:  la sintaxis de entrada no es válida para integer: «»
LINE 3: WHERE &quot;fk_mesa&quot; = ''
                          ^
#0 [internal function]: CodeIgniter\Debug\Exceptions->errorHandler(2, 'pg_query(): Que...', 'C:\\xampp\\htdocs...', 135)
#1 C:\xampp\htdocs\dfpyme\system\Database\Postgre\Connection.php(135): pg_query(Resource id #157, 'SELECT "id"\nFRO...')
#2 C:\xampp\htdocs\dfpyme\system\Database\BaseConnection.php(670): CodeIgniter\Database\Postgre\Connection->execute('SELECT "id"\nFRO...')
#3 C:\xampp\htdocs\dfpyme\system\Database\BaseConnection.php(598): CodeIgniter\Database\BaseConnection->simpleQuery('SELECT "id"\nFRO...')
#4 C:\xampp\htdocs\dfpyme\system\Database\BaseBuilder.php(1455): CodeIgniter\Database\BaseConnection->query('SELECT "id"\nFRO...', Array, false)
#5 C:\xampp\htdocs\dfpyme\system\Model.php(210): CodeIgniter\Database\BaseBuilder->get()
#6 C:\xampp\htdocs\dfpyme\system\BaseModel.php(622): CodeIgniter\Model->doFirst()
#7 C:\xampp\htdocs\dfpyme\app\Controllers\producto\productoController.php(202): CodeIgniter\BaseModel->first()
#8 C:\xampp\htdocs\dfpyme\system\CodeIgniter.php(832): App\Controllers\producto\productoController->insertar_productos_tabla_pedido()
#9 C:\xampp\htdocs\dfpyme\system\CodeIgniter.php(419): CodeIgniter\CodeIgniter->runController(Object(App\Controllers\producto\productoController))
#10 C:\xampp\htdocs\dfpyme\system\CodeIgniter.php(326): CodeIgniter\CodeIgniter->handleRequest(NULL, Object(Config\Cache), false)
#11 C:\xampp\htdocs\dfpyme\index.php(37): CodeIgniter\CodeIgniter->run()
#12 {main}
CRITICAL - 2023-03-01 18:49:44 --> Uncaught CodeIgniter\Format\Exceptions\FormatException: Failed to parse json string, error: "Type is not supported". in C:\xampp\htdocs\dfpyme\system\Format\JSONFormatter.php:41
Stack trace:
#0 C:\xampp\htdocs\dfpyme\system\Format\JSONFormatter.php(41): CodeIgniter\Format\Exceptions\FormatException::forInvalidJSON('Type is not sup...')
#1 C:\xampp\htdocs\dfpyme\system\API\ResponseTrait.php(341): CodeIgniter\Format\JSONFormatter->format(Array)
#2 C:\xampp\htdocs\dfpyme\system\API\ResponseTrait.php(99): CodeIgniter\Debug\Exceptions->format(Array)
#3 C:\xampp\htdocs\dfpyme\system\Debug\Exceptions.php(115): CodeIgniter\Debug\Exceptions->respond(Array, 500)
#4 [internal function]: CodeIgniter\Debug\Exceptions->exceptionHandler(Object(ErrorException))
#5 {main}
  thrown
#0 [internal function]: CodeIgniter\Debug\Exceptions->shutdownHandler()
#1 {main}
CRITICAL - 2023-03-01 18:54:49 --> Undefined variable $pedido
#0 C:\xampp\htdocs\dfpyme\app\Views\productos_pedido\productos_pedido.php(106): CodeIgniter\Debug\Exceptions->errorHandler(2, 'Undefined varia...', 'C:\\xampp\\htdocs...', 106)
#1 C:\xampp\htdocs\dfpyme\system\View\View.php(210): include('C:\\xampp\\htdocs...')
#2 C:\xampp\htdocs\dfpyme\system\View\View.php(213): CodeIgniter\View\View->CodeIgniter\View\{closure}()
#3 C:\xampp\htdocs\dfpyme\system\Common.php(1089): CodeIgniter\View\View->render('productos_pedid...', Array, true)
#4 C:\xampp\htdocs\dfpyme\app\Controllers\Mesa\mesaController.php(337): view('productos_pedid...', Array)
#5 C:\xampp\htdocs\dfpyme\system\CodeIgniter.php(832): App\Controllers\Mesa\mesaController->intercambio_mesa()
#6 C:\xampp\htdocs\dfpyme\system\CodeIgniter.php(419): CodeIgniter\CodeIgniter->runController(Object(App\Controllers\Mesa\mesaController))
#7 C:\xampp\htdocs\dfpyme\system\CodeIgniter.php(326): CodeIgniter\CodeIgniter->handleRequest(NULL, Object(Config\Cache), false)
#8 C:\xampp\htdocs\dfpyme\index.php(37): CodeIgniter\CodeIgniter->run()
#9 {main}
CRITICAL - 2023-03-01 18:54:51 --> Trying to access array offset on value of type null
#0 C:\xampp\htdocs\dfpyme\app\Controllers\Mesa\mesaController.php(206): CodeIgniter\Debug\Exceptions->errorHandler(2, 'Trying to acces...', 'C:\\xampp\\htdocs...', 206)
#1 C:\xampp\htdocs\dfpyme\system\CodeIgniter.php(832): App\Controllers\Mesa\mesaController->intercambio_mesa()
#2 C:\xampp\htdocs\dfpyme\system\CodeIgniter.php(419): CodeIgniter\CodeIgniter->runController(Object(App\Controllers\Mesa\mesaController))
#3 C:\xampp\htdocs\dfpyme\system\CodeIgniter.php(326): CodeIgniter\CodeIgniter->handleRequest(NULL, Object(Config\Cache), false)
#4 C:\xampp\htdocs\dfpyme\index.php(37): CodeIgniter\CodeIgniter->run()
#5 {main}
CRITICAL - 2023-03-01 18:54:52 --> Trying to access array offset on value of type null
#0 C:\xampp\htdocs\dfpyme\app\Controllers\Mesa\mesaController.php(206): CodeIgniter\Debug\Exceptions->errorHandler(2, 'Trying to acces...', 'C:\\xampp\\htdocs...', 206)
#1 C:\xampp\htdocs\dfpyme\system\CodeIgniter.php(832): App\Controllers\Mesa\mesaController->intercambio_mesa()
#2 C:\xampp\htdocs\dfpyme\system\CodeIgniter.php(419): CodeIgniter\CodeIgniter->runController(Object(App\Controllers\Mesa\mesaController))
#3 C:\xampp\htdocs\dfpyme\system\CodeIgniter.php(326): CodeIgniter\CodeIgniter->handleRequest(NULL, Object(Config\Cache), false)
#4 C:\xampp\htdocs\dfpyme\index.php(37): CodeIgniter\CodeIgniter->run()
#5 {main}
CRITICAL - 2023-03-01 18:54:52 --> Trying to access array offset on value of type null
#0 C:\xampp\htdocs\dfpyme\app\Controllers\Mesa\mesaController.php(206): CodeIgniter\Debug\Exceptions->errorHandler(2, 'Trying to acces...', 'C:\\xampp\\htdocs...', 206)
#1 C:\xampp\htdocs\dfpyme\system\CodeIgniter.php(832): App\Controllers\Mesa\mesaController->intercambio_mesa()
#2 C:\xampp\htdocs\dfpyme\system\CodeIgniter.php(419): CodeIgniter\CodeIgniter->runController(Object(App\Controllers\Mesa\mesaController))
#3 C:\xampp\htdocs\dfpyme\system\CodeIgniter.php(326): CodeIgniter\CodeIgniter->handleRequest(NULL, Object(Config\Cache), false)
#4 C:\xampp\htdocs\dfpyme\index.php(37): CodeIgniter\CodeIgniter->run()
#5 {main}
CRITICAL - 2023-03-01 18:54:52 --> Trying to access array offset on value of type null
#0 C:\xampp\htdocs\dfpyme\app\Controllers\Mesa\mesaController.php(206): CodeIgniter\Debug\Exceptions->errorHandler(2, 'Trying to acces...', 'C:\\xampp\\htdocs...', 206)
#1 C:\xampp\htdocs\dfpyme\system\CodeIgniter.php(832): App\Controllers\Mesa\mesaController->intercambio_mesa()
#2 C:\xampp\htdocs\dfpyme\system\CodeIgniter.php(419): CodeIgniter\CodeIgniter->runController(Object(App\Controllers\Mesa\mesaController))
#3 C:\xampp\htdocs\dfpyme\system\CodeIgniter.php(326): CodeIgniter\CodeIgniter->handleRequest(NULL, Object(Config\Cache), false)
#4 C:\xampp\htdocs\dfpyme\index.php(37): CodeIgniter\CodeIgniter->run()
#5 {main}
CRITICAL - 2023-03-01 18:54:52 --> Trying to access array offset on value of type null
#0 C:\xampp\htdocs\dfpyme\app\Controllers\Mesa\mesaController.php(206): CodeIgniter\Debug\Exceptions->errorHandler(2, 'Trying to acces...', 'C:\\xampp\\htdocs...', 206)
#1 C:\xampp\htdocs\dfpyme\system\CodeIgniter.php(832): App\Controllers\Mesa\mesaController->intercambio_mesa()
#2 C:\xampp\htdocs\dfpyme\system\CodeIgniter.php(419): CodeIgniter\CodeIgniter->runController(Object(App\Controllers\Mesa\mesaController))
#3 C:\xampp\htdocs\dfpyme\system\CodeIgniter.php(326): CodeIgniter\CodeIgniter->handleRequest(NULL, Object(Config\Cache), false)
#4 C:\xampp\htdocs\dfpyme\index.php(37): CodeIgniter\CodeIgniter->run()
#5 {main}
CRITICAL - 2023-03-01 18:55:29 --> Undefined variable $pedido
#0 C:\xampp\htdocs\dfpyme\app\Views\productos_pedido\productos_pedido.php(106): CodeIgniter\Debug\Exceptions->errorHandler(2, 'Undefined varia...', 'C:\\xampp\\htdocs...', 106)
#1 C:\xampp\htdocs\dfpyme\system\View\View.php(210): include('C:\\xampp\\htdocs...')
#2 C:\xampp\htdocs\dfpyme\system\View\View.php(213): CodeIgniter\View\View->CodeIgniter\View\{closure}()
#3 C:\xampp\htdocs\dfpyme\system\Common.php(1089): CodeIgniter\View\View->render('productos_pedid...', Array, true)
#4 C:\xampp\htdocs\dfpyme\app\Controllers\Mesa\mesaController.php(337): view('productos_pedid...', Array)
#5 C:\xampp\htdocs\dfpyme\system\CodeIgniter.php(832): App\Controllers\Mesa\mesaController->intercambio_mesa()
#6 C:\xampp\htdocs\dfpyme\system\CodeIgniter.php(419): CodeIgniter\CodeIgniter->runController(Object(App\Controllers\Mesa\mesaController))
#7 C:\xampp\htdocs\dfpyme\system\CodeIgniter.php(326): CodeIgniter\CodeIgniter->handleRequest(NULL, Object(Config\Cache), false)
#8 C:\xampp\htdocs\dfpyme\index.php(37): CodeIgniter\CodeIgniter->run()
#9 {main}
CRITICAL - 2023-03-01 18:58:23 --> Undefined variable $pedido
#0 C:\xampp\htdocs\dfpyme\app\Views\productos_pedido\productos_pedido.php(106): CodeIgniter\Debug\Exceptions->errorHandler(2, 'Undefined varia...', 'C:\\xampp\\htdocs...', 106)
#1 C:\xampp\htdocs\dfpyme\system\View\View.php(210): include('C:\\xampp\\htdocs...')
#2 C:\xampp\htdocs\dfpyme\system\View\View.php(213): CodeIgniter\View\View->CodeIgniter\View\{closure}()
#3 C:\xampp\htdocs\dfpyme\system\Common.php(1089): CodeIgniter\View\View->render('productos_pedid...', Array, true)
#4 C:\xampp\htdocs\dfpyme\app\Controllers\Mesa\mesaController.php(338): view('productos_pedid...', Array)
#5 C:\xampp\htdocs\dfpyme\system\CodeIgniter.php(832): App\Controllers\Mesa\mesaController->intercambio_mesa()
#6 C:\xampp\htdocs\dfpyme\system\CodeIgniter.php(419): CodeIgniter\CodeIgniter->runController(Object(App\Controllers\Mesa\mesaController))
#7 C:\xampp\htdocs\dfpyme\system\CodeIgniter.php(326): CodeIgniter\CodeIgniter->handleRequest(NULL, Object(Config\Cache), false)
#8 C:\xampp\htdocs\dfpyme\index.php(37): CodeIgniter\CodeIgniter->run()
#9 {main}
ERROR - 2023-03-01 18:59:12 --> ErrorException: pg_query(): Query failed: ERROR:  update o delete en «pedido» viola la llave foránea «fk_pedido» en la tabla «producto_pedido»
DETAIL:  La llave (id)=(30364) todavía es referida desde la tabla «producto_pedido». in C:\xampp\htdocs\dfpyme\system\Database\Postgre\Connection.php:135
Stack trace:
#0 [internal function]: CodeIgniter\Debug\Exceptions->errorHandler(2, 'pg_query(): Que...', 'C:\\xampp\\htdocs...', 135)
#1 C:\xampp\htdocs\dfpyme\system\Database\Postgre\Connection.php(135): pg_query(Resource id #157, 'DELETE FROM "pe...')
#2 C:\xampp\htdocs\dfpyme\system\Database\BaseConnection.php(670): CodeIgniter\Database\Postgre\Connection->execute('DELETE FROM "pe...')
#3 C:\xampp\htdocs\dfpyme\system\Database\BaseConnection.php(598): CodeIgniter\Database\BaseConnection->simpleQuery('DELETE FROM "pe...')
#4 C:\xampp\htdocs\dfpyme\system\Database\BaseBuilder.php(2225): CodeIgniter\Database\BaseConnection->query('DELETE FROM "pe...', Array, false)
#5 C:\xampp\htdocs\dfpyme\system\Database\Postgre\Builder.php(204): CodeIgniter\Database\BaseBuilder->delete('', NULL, true)
#6 C:\xampp\htdocs\dfpyme\system\Model.php(359): CodeIgniter\Database\Postgre\Builder->delete()
#7 C:\xampp\htdocs\dfpyme\system\BaseModel.php(963): CodeIgniter\Model->doDelete(NULL, false)
#8 C:\xampp\htdocs\dfpyme\app\Controllers\Mesa\mesaController.php(251): CodeIgniter\BaseModel->delete()
#9 C:\xampp\htdocs\dfpyme\system\CodeIgniter.php(832): App\Controllers\Mesa\mesaController->intercambio_mesa()
#10 C:\xampp\htdocs\dfpyme\system\CodeIgniter.php(419): CodeIgniter\CodeIgniter->runController(Object(App\Controllers\Mesa\mesaController))
#11 C:\xampp\htdocs\dfpyme\system\CodeIgniter.php(326): CodeIgniter\CodeIgniter->handleRequest(NULL, Object(Config\Cache), false)
#12 C:\xampp\htdocs\dfpyme\index.php(37): CodeIgniter\CodeIgniter->run()
#13 {main}
CRITICAL - 2023-03-01 18:59:12 --> pg_query(): Query failed: ERROR:  update o delete en «pedido» viola la llave foránea «fk_pedido» en la tabla «producto_pedido»
DETAIL:  La llave (id)=(30364) todavía es referida desde la tabla «producto_pedido».
#0 [internal function]: CodeIgniter\Debug\Exceptions->errorHandler(2, 'pg_query(): Que...', 'C:\\xampp\\htdocs...', 135)
#1 C:\xampp\htdocs\dfpyme\system\Database\Postgre\Connection.php(135): pg_query(Resource id #157, 'DELETE FROM "pe...')
#2 C:\xampp\htdocs\dfpyme\system\Database\BaseConnection.php(670): CodeIgniter\Database\Postgre\Connection->execute('DELETE FROM "pe...')
#3 C:\xampp\htdocs\dfpyme\system\Database\BaseConnection.php(598): CodeIgniter\Database\BaseConnection->simpleQuery('DELETE FROM "pe...')
#4 C:\xampp\htdocs\dfpyme\system\Database\BaseBuilder.php(2225): CodeIgniter\Database\BaseConnection->query('DELETE FROM "pe...', Array, false)
#5 C:\xampp\htdocs\dfpyme\system\Database\Postgre\Builder.php(204): CodeIgniter\Database\BaseBuilder->delete('', NULL, true)
#6 C:\xampp\htdocs\dfpyme\system\Model.php(359): CodeIgniter\Database\Postgre\Builder->delete()
#7 C:\xampp\htdocs\dfpyme\system\BaseModel.php(963): CodeIgniter\Model->doDelete(NULL, false)
#8 C:\xampp\htdocs\dfpyme\app\Controllers\Mesa\mesaController.php(251): CodeIgniter\BaseModel->delete()
#9 C:\xampp\htdocs\dfpyme\system\CodeIgniter.php(832): App\Controllers\Mesa\mesaController->intercambio_mesa()
#10 C:\xampp\htdocs\dfpyme\system\CodeIgniter.php(419): CodeIgniter\CodeIgniter->runController(Object(App\Controllers\Mesa\mesaController))
#11 C:\xampp\htdocs\dfpyme\system\CodeIgniter.php(326): CodeIgniter\CodeIgniter->handleRequest(NULL, Object(Config\Cache), false)
#12 C:\xampp\htdocs\dfpyme\index.php(37): CodeIgniter\CodeIgniter->run()
#13 {main}
CRITICAL - 2023-03-01 18:59:12 --> Uncaught CodeIgniter\Format\Exceptions\FormatException: Failed to parse json string, error: "Type is not supported". in C:\xampp\htdocs\dfpyme\system\Format\JSONFormatter.php:41
Stack trace:
#0 C:\xampp\htdocs\dfpyme\system\Format\JSONFormatter.php(41): CodeIgniter\Format\Exceptions\FormatException::forInvalidJSON('Type is not sup...')
#1 C:\xampp\htdocs\dfpyme\system\API\ResponseTrait.php(341): CodeIgniter\Format\JSONFormatter->format(Array)
#2 C:\xampp\htdocs\dfpyme\system\API\ResponseTrait.php(99): CodeIgniter\Debug\Exceptions->format(Array)
#3 C:\xampp\htdocs\dfpyme\system\Debug\Exceptions.php(115): CodeIgniter\Debug\Exceptions->respond(Array, 500)
#4 [internal function]: CodeIgniter\Debug\Exceptions->exceptionHandler(Object(ErrorException))
#5 {main}
  thrown
#0 [internal function]: CodeIgniter\Debug\Exceptions->shutdownHandler()
#1 {main}
CRITICAL - 2023-03-01 18:59:50 --> Undefined array key "id_mesa_origen"
#0 C:\xampp\htdocs\dfpyme\app\Controllers\Mesa\mesaController.php(197): CodeIgniter\Debug\Exceptions->errorHandler(2, 'Undefined array...', 'C:\\xampp\\htdocs...', 197)
#1 C:\xampp\htdocs\dfpyme\system\CodeIgniter.php(832): App\Controllers\Mesa\mesaController->intercambio_mesa()
#2 C:\xampp\htdocs\dfpyme\system\CodeIgniter.php(419): CodeIgniter\CodeIgniter->runController(Object(App\Controllers\Mesa\mesaController))
#3 C:\xampp\htdocs\dfpyme\system\CodeIgniter.php(326): CodeIgniter\CodeIgniter->handleRequest(NULL, Object(Config\Cache), false)
#4 C:\xampp\htdocs\dfpyme\index.php(37): CodeIgniter\CodeIgniter->run()
#5 {main}
CRITICAL - 2023-03-01 19:00:12 --> Trying to access array offset on value of type null
#0 C:\xampp\htdocs\dfpyme\app\Controllers\Mesa\mesaController.php(291): CodeIgniter\Debug\Exceptions->errorHandler(2, 'Trying to acces...', 'C:\\xampp\\htdocs...', 291)
#1 C:\xampp\htdocs\dfpyme\system\CodeIgniter.php(832): App\Controllers\Mesa\mesaController->intercambio_mesa()
#2 C:\xampp\htdocs\dfpyme\system\CodeIgniter.php(419): CodeIgniter\CodeIgniter->runController(Object(App\Controllers\Mesa\mesaController))
#3 C:\xampp\htdocs\dfpyme\system\CodeIgniter.php(326): CodeIgniter\CodeIgniter->handleRequest(NULL, Object(Config\Cache), false)
#4 C:\xampp\htdocs\dfpyme\index.php(37): CodeIgniter\CodeIgniter->run()
#5 {main}
CRITICAL - 2023-03-01 19:04:08 --> Undefined variable $pedido
#0 C:\xampp\htdocs\dfpyme\app\Views\productos_pedido\productos_pedido.php(106): CodeIgniter\Debug\Exceptions->errorHandler(2, 'Undefined varia...', 'C:\\xampp\\htdocs...', 106)
#1 C:\xampp\htdocs\dfpyme\system\View\View.php(210): include('C:\\xampp\\htdocs...')
#2 C:\xampp\htdocs\dfpyme\system\View\View.php(213): CodeIgniter\View\View->CodeIgniter\View\{closure}()
#3 C:\xampp\htdocs\dfpyme\system\Common.php(1089): CodeIgniter\View\View->render('productos_pedid...', Array, true)
#4 C:\xampp\htdocs\dfpyme\app\Controllers\Mesa\mesaController.php(336): view('productos_pedid...', Array)
#5 C:\xampp\htdocs\dfpyme\system\CodeIgniter.php(832): App\Controllers\Mesa\mesaController->intercambio_mesa()
#6 C:\xampp\htdocs\dfpyme\system\CodeIgniter.php(419): CodeIgniter\CodeIgniter->runController(Object(App\Controllers\Mesa\mesaController))
#7 C:\xampp\htdocs\dfpyme\system\CodeIgniter.php(326): CodeIgniter\CodeIgniter->handleRequest(NULL, Object(Config\Cache), false)
#8 C:\xampp\htdocs\dfpyme\index.php(37): CodeIgniter\CodeIgniter->run()
#9 {main}
CRITICAL - 2023-03-01 19:04:51 --> Trying to access array offset on value of type null
#0 C:\xampp\htdocs\dfpyme\app\Controllers\Mesa\mesaController.php(205): CodeIgniter\Debug\Exceptions->errorHandler(2, 'Trying to acces...', 'C:\\xampp\\htdocs...', 205)
#1 C:\xampp\htdocs\dfpyme\system\CodeIgniter.php(832): App\Controllers\Mesa\mesaController->intercambio_mesa()
#2 C:\xampp\htdocs\dfpyme\system\CodeIgniter.php(419): CodeIgniter\CodeIgniter->runController(Object(App\Controllers\Mesa\mesaController))
#3 C:\xampp\htdocs\dfpyme\system\CodeIgniter.php(326): CodeIgniter\CodeIgniter->handleRequest(NULL, Object(Config\Cache), false)
#4 C:\xampp\htdocs\dfpyme\index.php(37): CodeIgniter\CodeIgniter->run()
#5 {main}
