ERROR - 2024-04-20 15:39:14 --> ErrorException: pg_query(): Query failed: ERROR:  no existe la relación «usuario_sistema»
LINE 2: FROM &quot;usuario_sistema&quot;
             ^ in C:\xampp\htdocs\dfpyme\system\Database\Postgre\Connection.php:135
Stack trace:
#0 [internal function]: CodeIgniter\Debug\Exceptions->errorHandler(2, 'pg_query(): Que...', 'C:\\xampp\\htdocs...', 135)
#1 C:\xampp\htdocs\dfpyme\system\Database\Postgre\Connection.php(135): pg_query(Resource id #148, 'SELECT 1\nFROM "...')
#2 C:\xampp\htdocs\dfpyme\system\Database\BaseConnection.php(670): CodeIgniter\Database\Postgre\Connection->execute('SELECT 1\nFROM "...')
#3 C:\xampp\htdocs\dfpyme\system\Database\BaseConnection.php(598): CodeIgniter\Database\BaseConnection->simpleQuery('SELECT 1\nFROM "...')
#4 C:\xampp\htdocs\dfpyme\system\Database\BaseBuilder.php(1455): CodeIgniter\Database\BaseConnection->query('SELECT 1\nFROM "...', Array, false)
#5 C:\xampp\htdocs\dfpyme\system\Validation\Rules.php(104): CodeIgniter\Database\BaseBuilder->get()
#6 C:\xampp\htdocs\dfpyme\system\Validation\Validation.php(292): CodeIgniter\Validation\Rules->is_not_unique('8888', 'pinusuario_sist...', Array, NULL)
#7 C:\xampp\htdocs\dfpyme\system\Validation\Validation.php(157): CodeIgniter\Validation\Validation->processRules('pin', 'pin', '8888', Array, Array)
#8 C:\xampp\htdocs\dfpyme\system\Controller.php(160): CodeIgniter\Validation\Validation->run()
#9 C:\xampp\htdocs\dfpyme\app\Controllers\login\loginController.php(19): CodeIgniter\Controller->validate(Array)
#10 C:\xampp\htdocs\dfpyme\system\CodeIgniter.php(832): App\Controllers\login\loginController->login()
#11 C:\xampp\htdocs\dfpyme\system\CodeIgniter.php(419): CodeIgniter\CodeIgniter->runController(Object(App\Controllers\login\loginController))
#12 C:\xampp\htdocs\dfpyme\system\CodeIgniter.php(326): CodeIgniter\CodeIgniter->handleRequest(NULL, Object(Config\Cache), false)
#13 C:\xampp\htdocs\dfpyme\index.php(37): CodeIgniter\CodeIgniter->run()
#14 {main}
CRITICAL - 2024-04-20 15:39:14 --> pg_query(): Query failed: ERROR:  no existe la relación «usuario_sistema»
LINE 2: FROM &quot;usuario_sistema&quot;
             ^
#0 [internal function]: CodeIgniter\Debug\Exceptions->errorHandler(2, 'pg_query(): Que...', 'C:\\xampp\\htdocs...', 135)
#1 C:\xampp\htdocs\dfpyme\system\Database\Postgre\Connection.php(135): pg_query(Resource id #148, 'SELECT 1\nFROM "...')
#2 C:\xampp\htdocs\dfpyme\system\Database\BaseConnection.php(670): CodeIgniter\Database\Postgre\Connection->execute('SELECT 1\nFROM "...')
#3 C:\xampp\htdocs\dfpyme\system\Database\BaseConnection.php(598): CodeIgniter\Database\BaseConnection->simpleQuery('SELECT 1\nFROM "...')
#4 C:\xampp\htdocs\dfpyme\system\Database\BaseBuilder.php(1455): CodeIgniter\Database\BaseConnection->query('SELECT 1\nFROM "...', Array, false)
#5 C:\xampp\htdocs\dfpyme\system\Validation\Rules.php(104): CodeIgniter\Database\BaseBuilder->get()
#6 C:\xampp\htdocs\dfpyme\system\Validation\Validation.php(292): CodeIgniter\Validation\Rules->is_not_unique('8888', 'pinusuario_sist...', Array, NULL)
#7 C:\xampp\htdocs\dfpyme\system\Validation\Validation.php(157): CodeIgniter\Validation\Validation->processRules('pin', 'pin', '8888', Array, Array)
#8 C:\xampp\htdocs\dfpyme\system\Controller.php(160): CodeIgniter\Validation\Validation->run()
#9 C:\xampp\htdocs\dfpyme\app\Controllers\login\loginController.php(19): CodeIgniter\Controller->validate(Array)
#10 C:\xampp\htdocs\dfpyme\system\CodeIgniter.php(832): App\Controllers\login\loginController->login()
#11 C:\xampp\htdocs\dfpyme\system\CodeIgniter.php(419): CodeIgniter\CodeIgniter->runController(Object(App\Controllers\login\loginController))
#12 C:\xampp\htdocs\dfpyme\system\CodeIgniter.php(326): CodeIgniter\CodeIgniter->handleRequest(NULL, Object(Config\Cache), false)
#13 C:\xampp\htdocs\dfpyme\index.php(37): CodeIgniter\CodeIgniter->run()
#14 {main}
